Workbook

Sheet 3PM
A1: Sale Report 3PM
C2: Retail | H2: Attraction | K2: Retail + Attraction | N2: Retail + Attraction | Q2: LOYALTY
A3: Store Code | B3: Store Name | C3: Target | D3: Last Week | E3: This Week | F3: WOW | G3: Ach % | H3: Target | I3: This Week | J3: Ach % | K3: Target | L3: This Week | M3: Ach % | N3: LYSMD | O3: TYSMD | P3: Attach% | Q3: LOYALTY | R3: NOB | S3: Ach %
A4: THE8 | B4: AVK Delhi | C4: =Retail!M35 -> 520994.28 | D4: =SUMIFS(C37:AM37,$C$36:$AM$36,"="&$A$59) -> 114904 | E4: 162902 | F4: =E4/D4-1 -> 0.41772262 | G4: =E4/C4 -> 0.31267522 | H4: =Attraction!G35 -> 13653.531 | I4: 3600 | J4: =I4/H4 -> 0.26366806 | K4: =C4+H4 -> 534647.81 | L4: =+E4+I4 -> 166502 | M4: =L4/K4 -> 0.3114237 | N4: =VLOOKUP(T1,'LFL 2024'!A2:C33,3,0) -> #N/A | O4: =E4 -> 162902 | P4: =O4/N4 -> #N/A | S4: =Q4/R4*1 -> #DIV/0!
A5: THH2 | B5: Delhi Pacific | C5: =Retail!J35 -> 286734.48 | D5: =SUMIFS(C38:AM38,$C$36:$AM$36,"="&$A$59) -> 41009 | E5: 52379 | F5: =E5/D5-1 -> 0.27725621 | G5: =E5/C5 -> 0.18267423 | H5: =Attraction!E35 -> 18519.062 | I5: 5600 | J5: =I5/H5 -> 0.30239112 | K5: =C5+H5 -> 305253.54 | L5: =+E5+I5 -> 57979 | M5: =L5/K5 -> 0.18993719 | N5: =VLOOKUP(T1,'LFL 2024'!A2:D33,4,0) -> #N/A | O5: =E5 -> 52379 | P5: =O5/N5 -> #N/A | S5: =Q5/R5*1 -> #DIV/0!
A6: TAHY | B6: Worldmark | C6: =Retail!H35 -> 63851.172 | D6: =SUMIFS(C39:AM39,$C$36:$AM$36,"="&$A$59) -> 18465 | E6: 19710 | F6: =E6/D6-1 -> 0.067424858 | G6: =E6/C6 -> 0.30868658 | H6: =Attraction!B35 -> 100564.04 | I6: 18500 | J6: =I6/H6 -> 0.18396237 | K6: =C6+H6 -> 164415.21 | L6: =+E6+I6 -> 38210 | M6: =L6/K6 -> 0.23239942 | N6: =VLOOKUP(T1,'LFL 2024'!A2:F33,5,0) -> #N/A | O6: =E6 -> 19710 | P6: =O6/N6 -> #N/A | S6: =Q6/R6*1 -> #DIV/0!
A7: THH3 | B7: Delhi Selectcity | C7: =Retail!K35 -> 392222.7 | D7: =SUMIFS(C40:AM40,$C$36:$AM$36,"="&$A$59) -> 163003 | E7: 154462 | F7: =E7/D7-1 -> -0.052397809 | G7: =E7/C7 -> 0.39381199 | K7: =C7+H7 -> 392222.7 | L7: =+E7+I7 -> 154462 | M7: =L7/K7 -> 0.39381199 | N7: =VLOOKUP(T1,'LFL 2024'!A2:G33,6,0) -> #N/A | O7: =E7 -> 154462 | P7: =O7/N7 -> #N/A | S7: =Q7/R7*1 -> #DIV/0!
A8: TLX5 | B8: Vegas Dwarka | C8: =Retail!L35 -> 176136.03 | D8: =SUMIFS(C41:AM41,$C$36:$AM$36,"="&$A$59) -> 44345 | E8: 32486 | F8: =E8/D8-1 -> -0.26742587 | G8: =E8/C8 -> 0.18443699 | H8: =Attraction!D35 -> 11996.078 | I8: 0 | J8: =I8/H8 -> 0 | K8: =C8+H8 -> 188132.11 | L8: =+E8+I8 -> 32486 | M8: =L8/K8 -> 0.17267653 | N8: =VLOOKUP(T1,'LFL 2024'!A2:H33,7,0) -> #N/A | O8: =E8 -> 32486 | P8: =O8/N8 -> #N/A | S8: =Q8/R8*1 -> #DIV/0!
A9: THF9 | B9: Amb Gurg Delhi | C9: =Retail!B35 -> 480133.83 | D9: =SUMIFS(C42:AM42,$C$36:$AM$36,"="&$A$59) -> 146181 | E9: 97966 | F9: =E9/D9-1 -> -0.32983083 | G9: =E9/C9 -> 0.20403894 | K9: =C9+H9 -> 480133.83 | L9: =+E9+I9 -> 97966 | M9: =L9/K9 -> 0.20403894 | N9: =VLOOKUP(T1,'LFL 2024'!A2:I33,8,0) -> #N/A | O9: =E9 -> 97966 | P9: =O9/N9 -> #N/A | S9: =Q9/R9*1 -> #DIV/0!
A10: THI7 | B10: WTP Jaipur | C10: =Retail!F35 -> 190041.27 | D10: =SUMIFS(C43:AM43,$C$36:$AM$36,"="&$A$59) -> 47459 | E10: 42343 | F10: =E10/D10-1 -> -0.10779831 | G10: =E10/C10 -> 0.22280949 | K10: =C10+H10 -> 190041.27 | L10: =+E10+I10 -> 42343 | M10: =L10/K10 -> 0.22280949 | N10: =VLOOKUP(T1,'LFL 2024'!A2:J33,9,0) -> #N/A | O10: =E10 -> 42343 | P10: =O10/N10 -> #N/A | S10: =Q10/R10*1 -> #DIV/0!
A11: THM0 | B11: Ardee Mall, Gurgaon | C11: =Retail!C35 -> 174186.13 | D11: =SUMIFS(C44:AM44,$C$36:$AM$36,"="&$A$59) -> 30133 | E11: 23240 | F11: =E11/D11-1 -> -0.22875253 | G11: =E11/C11 -> 0.1334205 | K11: =C11+H11 -> 174186.13 | L11: =+E11+I11 -> 23240 | M11: =L11/K11 -> 0.1334205 | N11: =VLOOKUP(T1,'LFL 2024'!A2:K33,10,0) -> #N/A | O11: =E11 -> 23240 | P11: =O11/N11 -> #N/A | S11: =Q11/R11*1 -> #DIV/0!
A12: TJY4 | B12: Airia Mall Gurg | C12: =Retail!D35 -> 108239.76 | D12: =SUMIFS(C45:AM45,$C$36:$AM$36,"="&$A$59) -> 24148 | E12: 34048 | F12: =E12/D12-1 -> 0.40997184 | G12: =E12/C12 -> 0.31456095 | K12: =C12+H12 -> 108239.76 | L12: =+E12+I12 -> 34048 | M12: =L12/K12 -> 0.31456095 | N12: =VLOOKUP(T1,'LFL 2024'!A2:L33,11,0) -> #N/A | O12: =E12 -> 34048 | P12: =O12/N12 -> #N/A | S12: =Q12/R12*1 -> #DIV/0!
A13: TXUT | B13: Vaishali | C13: =Retail!G35 -> 93298.933 | D13: =SUMIFS(C46:AM46,$C$36:$AM$36,"="&$A$59) -> 13467 | E13: 10968 | F13: =E13/D13-1 -> -0.18556471 | G13: =E13/C13 -> 0.11755761 | K13: =C13+H13 -> 93298.933 | L13: =+E13+I13 -> 10968 | M13: =L13/K13 -> 0.11755761 | N13: =VLOOKUP(T2,'LFL 2024'!A3:L34,11,0) -> #N/A | O13: =E13 -> 10968 | P13: =O13/N13 -> #N/A | S13: =Q13/R13*1 -> #DIV/0!
A14: TXYT | B14: Good Earth | D14: =SUMIFS(C47:AM47,$C$36:$AM$36,"="&$A$59) -> 0 | F14: =E14/D14-1 -> #DIV/0! | G14: =E14/C14 -> #DIV/0! | K14: =C14+H14 -> 0 | L14: =+E14+I14 -> 0 | M14: =L14/K14 -> #DIV/0! | N14: =VLOOKUP(T3,'LFL 2024'!A4:L35,11,0) -> #N/A | O14: =E14 -> 0 | P14: =O14/N14 -> #N/A | S14: =Q14/R14*1 -> #DIV/0!
A15: TAUN | B15: Udaipur | C15: =Retail!I35 -> 75609.562 | D15: =SUMIFS(C48:AM48,$C$36:$AM$36,"="&$A$59) -> 8822 | E15: 5122 | F15: =E15/D15-1 -> -0.41940603 | G15: =E15/C15 -> 0.067742755 | H15: =Attraction!C35 -> 4391.1341 | I15: 2850 | J15: =I15/H15 -> 0.64903506 | K15: =C15+H15 -> 80000.696 | L15: =+E15+I15 -> 7972 | M15: =L15/K15 -> 0.099649133 | N15: =VLOOKUP(T4,'LFL 2024'!A5:L36,11,0) -> #N/A | O15: =E15 -> 5122 | P15: =O15/N15 -> #N/A | S15: =Q15/R15*1 -> #DIV/0!
A16: THE1 | B16: Elante Chandigarh | C16: =Retail!N35 -> 478539.4 | D16: =SUMIFS(C49:AM49,$C$36:$AM$36,"="&$A$59) -> 52891 | E16: 136590 | F16: =E16/D16-1 -> 1.582481 | G16: =E16/C16 -> 0.28543104 | H16: =Attraction!F35 -> 86995.04 | I16: =27291+3150+6400 -> 36841 | J16: =I16/H16 -> 0.42348391 | K16: =C16+H16 -> 565534.44 | L16: =+E16+I16 -> 173431 | M16: =L16/K16 -> 0.30666744 | N16: =VLOOKUP(T5,'LFL 2024'!A6:L37,11,0) -> #N/A | O16: =E16 -> 136590 | P16: =O16/N16 -> #N/A | S16: =Q16/R16*1 -> #DIV/0!
A17: TF5T | B17: Pacific D21 | C17: 0 | D17: =SUMIFS(C50:AM50,$C$36:$AM$36,"="&$A$59) -> 0 | F17: =E17/D17-1 -> #DIV/0! | G17: =E17/C17 -> #DIV/0! | K17: =C17+H17 -> 0 | L17: =+E17+I17 -> 0 | M17: =L17/K17 -> #DIV/0! | N17: =VLOOKUP(T6,'LFL 2024'!A7:L38,11,0) -> #N/A | O17: =E17 -> 0 | P17: =O17/N17 -> #N/A | S17: =Q17/R17*1 -> #DIV/0!
A18: TXPH | B18: NH-1 Ambala store | C18: =Retail!P35 -> 52418.276 | D18: =SUMIFS(C51:AM51,$C$36:$AM$36,"="&$A$59) -> 2999 | E18: 5389 | F18: =E18/D18-1 -> 0.79693231 | G18: =E18/C18 -> 0.10280765 | K18: =C18+H18 -> 52418.276 | L18: =+E18+I18 -> 5389 | M18: =L18/K18 -> 0.10280765 | N18: =VLOOKUP(T7,'LFL 2024'!A8:L39,11,0) -> #N/A | O18: =E18 -> 5389 | P18: =O18/N18 -> #N/A | S18: =Q18/R18*1 -> #DIV/0!
A19: TXR2 | B19: Zirakpur | C19: =Retail!Q35 -> 50054.432 | D19: =SUMIFS(C52:AM52,$C$36:$AM$36,"="&$A$59) -> 15303 | E19: 9925 | F19: =E19/D19-1 -> -0.35143436 | G19: =E19/C19 -> 0.19828414 | K19: =C19+H19 -> 50054.432 | L19: =+E19+I19 -> 9925 | M19: =L19/K19 -> 0.19828414 | N19: =VLOOKUP(T8,'LFL 2024'!A9:L40,11,0) -> #N/A | O19: =E19 -> 9925 | P19: =O19/N19 -> #N/A | S19: =Q19/R19*1 -> #DIV/0!
A20: T2DD | B20: CP-67 | C20: =Retail!R35 -> 173176.09 | D20: =SUMIFS(C53:AM53,$C$36:$AM$36,"="&$A$59) -> 37688 | E20: 32826 | F20: =E20/D20-1 -> -0.12900658 | G20: =E20/C20 -> 0.18955272 | H20: =Attraction!H35 -> 37671.355 | I20: 16443 | J20: =I20/H20 -> 0.4364855 | K20: =C20+H20 -> 210847.45 | L20: =+E20+I20 -> 49269 | M20: =L20/K20 -> 0.23367131 | N20: =VLOOKUP(T9,'LFL 2024'!A10:L41,11,0) -> #N/A | O20: =E20 -> 32826 | P20: =O20/N20 -> #N/A | S20: =Q20/R20*1 -> #DIV/0!
A21: TL60 | B21: Iris | C21: =Retail!S35 -> 69239.832 | D21: =SUMIFS(C54:AM54,$C$36:$AM$36,"="&$A$59) -> 28679 | E21: 10499 | F21: =E21/D21-1 -> -0.63391332 | G21: =E21/C21 -> 0.15163237 | K21: =C21+H21 -> 69239.832 | L21: =+E21+I21 -> 10499 | M21: =L21/K21 -> 0.15163237 | N21: =VLOOKUP(T10,'LFL 2024'!A11:L42,11,0) -> #N/A | O21: =E21 -> 10499 | P21: =O21/N21 -> #N/A | S21: =Q21/R21*1 -> #DIV/0!
A22: T1MH | B22: Faridabad | C22: =Retail!T35 -> 118798.39 | D22: =SUMIFS(C55:AM55,$C$36:$AM$36,"="&$A$59) -> 23145 | E22: 24439 | F22: =E22/D22-1 -> 0.055908404 | G22: =E22/C22 -> 0.20571828 | K22: =C22+H22 -> 118798.39 | L22: =+E22+I22 -> 24439 | M22: =L22/K22 -> 0.20571828 | N22: =VLOOKUP(T11,'LFL 2024'!A12:L43,11,0) -> #N/A | O22: =E22 -> 24439 | P22: =O22/N22 -> #N/A | S22: =Q22/R22*1 -> #DIV/0!
A23: TB6V | B23: Elegante | C23: =Retail!U35 -> 187326.31 | D23: =SUMIFS(C56:AM56,$C$36:$AM$36,"="&$A$59) -> 32076 | E23: 19727 | F23: =E23/D23-1 -> -0.38499189 | G23: =E23/C23 -> 0.10530822 | K23: =C23+H23 -> 187326.31 | L23: =+E23+I23 -> 19727 | M23: =L23/K23 -> 0.10530822 | N23: =VLOOKUP(T11,'LFL 2024'!A12:L43,11,0) -> #N/A | O23: =E23 -> 19727 | P23: =O23/N23 -> #N/A | S23: =Q23/R23*1 -> #DIV/0!
A24: TBDE | B24: Dlf Summit Plaza | C24: =Retail!V35 -> 157216.41 | D24: =SUMIFS(C57:AM57,$C$36:$AM$36,"="&$A$59) -> 25590 | E24: 21668 | F24: =E24/D24-1 -> -0.15326299 | G24: =E24/C24 -> 0.13782277 | K24: =C24+H24 -> 157216.41 | L24: =+E24+I24 -> 21668 | M24: =L24/K24 -> 0.13782277 | N24: =VLOOKUP(T12,'LFL 2024'!A13:L44,11,0) -> #N/A | O24: =E24 -> 21668 | P24: =O24/N24 -> #N/A | S24: =Q24/R24*1 -> #DIV/0!
A25: TD9T | B25: Jodhpur | C25: =Retail!W35 -> 138746.39 | D25: =SUMIFS(C58:AM58,$C$36:$AM$36,"="&$A$59) -> 14381 | E25: 30780 | F25: =E25/D25-1 -> 1.140324 | G25: =E25/C25 -> 0.22184361 | K25: =C25+H25 -> 138746.39 | L25: =+E25+I25 -> 30780 | M25: =L25/K25 -> 0.22184361 | O25: =E25 -> 30780
C26: =SUM(C4:C25) -> 3986963.7 | D26: =SUM(D4:D25) -> 884688 | E26: =SUM(E4:E25) -> 927469 | F26: =E26/D26-1 -> 0.048357161 | G26: =E26/C26 -> 0.23262539 | H26: =SUM(H4:H23) -> 273790.24 | I26: =SUM(I4:I24) -> 83834 | J26: =I26/H26 -> 0.30619791 | K26: =SUM(K4:K25) -> 4260753.9 | L26: =SUM(L4:L25) -> 1011303 | M26: =L26/K26 -> 0.23735306 | N26: =VLOOKUP(T13,'LFL 2024'!A14:K45,10,0) -> #N/A | O26: =E26 -> 927469 | P26: =O26/N26 -> #N/A | Q26: =SUM(Q4:Q23) -> 0 | R26: =SUM(R4:R23) -> 0 | S26: =+Q26/R26 -> #DIV/0!
C28: Target | D28: Last Week | E28: This Week | F28: WOW | G28: Ach% | H28: Target | I28: This Week | J28: Ach % | K28: Target | L28: This Week | M28: Ach % | N28: NOB | O28: Loyalty | P28: Attach% | Q28: Loyalty | R28: NOB | S28: Ach % | AG28: =+K33-K26 -> 0
B29: Ajay | C29: =+C4+C20+C10+C13+C15+C25 -> 1191866.5 | D29: =+D4+D20+D10+D13+D15+D25 -> 236721 | E29: =+E4+E20+E10+E13+E15+E25 -> 284941 | F29: =E29/D29-1 -> 0.20369971 | G29: =+E29/C29 -> 0.23907123 | H29: =+H4+H20+H10+H13+H15 -> 55716.02 | I29: =+I4+I20+I10+I13+I15 -> 22893 | J29: =I29/H29 -> 0.41088721 | K29: =+K4+K20+K10+K13+K15+K25 -> 1247582.6 | L29: =+L4+L20+L10+L13+L15+L25 -> 307834 | M29: =L29/K29 -> 0.24674439 | N29: =+N4+N20 -> #N/A | O29: =+O4+O20+O10+O13+O15 -> 254161 | P29: =O29/N29 -> #N/A | Q29: =+Q4+Q20 -> 0 | R29: =+R4+R20 -> 0 | S29: =Q29/R29*1 -> #DIV/0!
B30: Shashank | C30: 0 | D30: 0 | E30: 0 | F30: =E30/D30-1 -> #DIV/0! | G30: =+E30/C30 -> #DIV/0! | H30: 0 | I30: 0 | J30: =I30/H30 -> #DIV/0! | K30: 0 | M30: =L30/K30 -> #DIV/0! | N30: =+N10+N13+N15 -> #N/A | O30: 0 | P30: =O30/N30 -> #N/A | Q30: =+Q10+Q13+Q15 -> 0 | R30: =+R10+R13+R15 -> 0 | S30: =Q30/R30*1 -> #DIV/0!
B31: Param | C31: =+C11+C9+C12+C6+C14+C21+C22+C24 -> 1171665.5 | D31: =+D11+D9+D12+D6+D14+D21+D22+D24 -> 296341 | E31: =+E11+E9+E12+E6+E14+E21+E22+E24 -> 231570 | F31: =E31/D31-1 -> -0.21856915 | G31: =+E31/C31 -> 0.19764173 | H31: =H11+H9+H12+H6+H14+H21+H24+H22 -> 100564.04 | I31: =I11+I9+I12+I6+I14+I21+I22+I24 -> 18500 | J31: =I31/H31 -> 0.18396237 | K31: =K11+K9+K12+K6+K14+K21+K22+K24 -> 1272229.6 | L31: =+L11+L9+L12+L6+L14+L22+L24+L21 -> 250070 | M31: =L31/K31 -> 0.19656044 | N31: =+N11+N9+N12+N6+N14+N21 -> #N/A | O31: =+O11+O9+O12+O6+O14+O21+O22+O24 -> 231570 | P31: =O31/N31 -> #N/A | Q31: =+Q11+Q9+Q12+Q6+Q14+Q21+Q22+Q24 -> 0 | R31: =+R11+R9+R12+R6+R14+R21+R22+R24 -> 0 | S31: =Q31/R31*1 -> #DIV/0!
B32: Harsh | C32: =+C5+C7+C8+C19+C18+C16+C23 -> 1623431.6 | D32: =+D5+D7+D8+D19+D18+D17+D16+D23 -> 351626 | E32: =+E5+E7+E8+E19+E18+E17+E16+E23 -> 410958 | F32: =E32/D32-1 -> 0.1687361 | G32: =+E32/C32 -> 0.25314155 | H32: =+H5+H7+H8+H19+H18+H17+H16+H23 -> 117510.18 | I32: =+I5+I7+I8+I19+I18+I17+I16+I23 -> 42441 | J32: =I32/H32 -> 0.36116871 | K32: =+K5+K7+K8+K19+K18+K16+K23 -> 1740941.8 | L32: =+L5+L7+L8+L16+L18+L19+L23 -> 453399 | M32: =L32/K32 -> 0.26043317 | N32: =+N5+N7+N8+N19+N18+N17+N16+N23 -> #N/A | O32: =+O5+O7+O8+O19+O18+O17+O16+O23 -> 410958 | P32: =O32/N32 -> #N/A | Q32: =+Q5+Q7+Q8+Q19+Q18+Q17+Q16+Q23 -> 0 | R32: =+R5+R7+R8+R19+R18+R17+R16+R23 -> 0 | S32: =Q32/R32*1 -> #DIV/0!
C33: =SUM(C29:C32) -> 3986963.7 | D33: =SUM(D29:D32) -> 884688 | E33: =SUM(E29:E32) -> 927469 | F33: =E33/D33-1 -> 0.048357161 | G33: =+E33/C33 -> 0.23262539 | H33: =SUM(H29:H32) -> 273790.24 | I33: =SUM(I29:I32) -> 83834 | J33: =I33/H33 -> 0.30619791 | K33: =SUM(K29:K32) -> 4260753.9 | L33: =SUM(L29:L32) -> 1011303 | M33: =L33/K33 -> 0.23735306 | N33: =SUM(N29:N32) -> #N/A | O33: =SUM(O29:O32) -> 896689 | P33: =O33/N33 -> #N/A | Q33: =SUM(Q29:Q32) -> 0 | R33: =SUM(R29:R32) -> 0 | S33: =+Q33/R33 -> #DIV/0!
A36: Store Code | B36: Store Name | C36: 46259 | D36: =C36+1 -> 46260 | E36: =D36+1 -> 46261 | F36: =E36+1 -> 46262 | G36: =F36+1 -> 46263 | H36: =G36+1 -> 46264 | I36: =H36+1 -> 46265 | J36: =I36+1 -> 46266 | K36: =J36+1 -> 46267 | ... AP36: =AO36+1 -> 46298
A37: THE8 | B37: AVK Delhi | C37: 31588 | D37: 118825 | E37: 116238 | F37: 100930 | G37: 98700 | H37: 220702 | I37: 67392 | J37: 51407 | K37: 32321 | L37: 74333 | N37: 88263 | P37: 30749 | Q37: 32633 | R37: 37364 | S37: 50265 | T37: 125191 | U37: 79924 | V37: 164684 | W37: 60602 | X37: 86306 | Y37: 50141 | Z37: 31872 | AA37: 139474 | AB37: 114904 | AC37: 202002 | AD37: 49606 | AE37: 42467 | AF37: 61565 | AG37: 81471 | AH37: 85522 | AI37: 162902
A38: THH2 | B38: Delhi Pacific | C38: 21800 | D38: 49510 | E38: 53259 | F38: 66251 | G38: 28974 | H38: 0 | I38: 0 | J38: 29938 | K38: 22611 | L38: 22947 | N38: 22676 | P38: 6500 | Q38: 11108 | R38: 19670 | S38: 0 | T38: 7767 | U38: 32195 | V38: 61409 | W38: 9978 | X38: 8495 | Y38: 21988 | Z38: 13027 | AA38: 23547 | AB38: 41009 | AC38: 55131 | AD38: 5680 | AE38: 12089 | AF38: 7754 | AG38: 12588 | AH38: 27984 | AI38: 52379
A39: TAHY | B39: Worldmark | C39: 17637 | D39: 1298 | E39: 799 | F39: 14470 | G39: 6819 | H39: 24094 | I39: 7187 | J39: 3347 | K39: 1670 | L39: 0 | N39: 6163 | P39: 3897 | Q39: 999 | R39: 1997 | S39: 4543 | T39: 549 | U39: 4396 | V39: 6233 | W39: 198 | X39: 0 | Y39: 2698 | Z39: 7497 | AA39: 6399 | AB39: 18465 | AC39: 30027 | AD39: 0 | AE39: 0 | AF39: 5904 | AG39: 5456 | AH39: 5260 | AI39: 19710
A40: THH3 | B40: Delhi Selectcity | C40: 65104 | D40: 96091 | E40: 71392 | F40: 184843 | G40: 92967 | H40: 133975 | I40: 59008 | J40: 36983 | K40: 23603 | L40: 39262 | N40: 60440 | P40: 9937 | Q40: 40149 | R40: 40588 | S40: 77405 | T40: 44777 | U40: 36107 | V40: 75711 | W40: 59531 | X40: 26849 | Y40: 57103 | Z40: 44550 | AA40: 14261 | AB40: 163003 | AC40: 135109 | AD40: 32881 | AE40: 44653 | AF40: 49663 | AG40: 53073 | AH40: 88935 | AI40: 154462
A41: TLX5 | B41: Vegas Dwarka | C41: 28668 | D41: 65095 | E41: 51522 | F41: 57740 | G41: 28721 | H41: 28865 | I41: 4387 | J41: 18423 | K41: 40288 | L41: 18327 | N41: 4597 | P41: 1699 | Q41: 7603 | R41: 52097 | S41: 5696 | T41: 27711 | U41: 55737 | V41: 39401 | W41: 19470 | X41: 16024 | Y41: 9816 | Z41: 18870 | AA41: 15314 | AB41: 44345 | AC41: 55006 | AD41: 23857 | AE41: 39715 | AF41: 12748 | AG41: 28327 | AH41: 23057 | AI41: 32486
A42: THF9 | B42: Amb Gurg Delhi | C42: 101463 | D42: 139935 | E42: 167343 | F42: 159730 | G42: 146272 | H42: 384000 | I42: 29546 | J42: 41971 | K42: 48343 | L42: 81857 | P42: 45953 | Q42: 31756 | R42: 37138 | S42: 24930 | T42: 57932 | U42: 130130 | V42: 111551 | W42: 60003 | X42: 18284 | Y42: 89447 | Z42: 34965 | AA42: 109040 | AB42: 146181 | AC42: 112161 | AD42: 49948 | AE42: 51540 | AF42: 71542 | AG42: 56021 | AH42: 61771 | AI42: 97966
A43: THI7 | B43: WTP Jaipur | C43: 22031 | D43: 33990 | E43: 63064 | F43: 36570 | G43: 46256 | H43: 30256 | I43: 10324 | J43: 12719 | K43: 16032 | L43: 8234 | N43: 15059 | P43: 31867 | Q43: 12600 | R43: 20490 | S43: 29680 | T43: 16220 | U43: 14028 | V43: 15365 | W43: 7605 | X43: 13587 | Y43: 9154 | Z43: 17364 | AA43: 5198 | AB43: 47459 | AC43: 48641 | AD43: 20154 | AE43: 6966 | AF43: 33294 | AG43: 12214 | AH43: 14128 | AI43: 42343
...

Sheet 5PM
A1: 5PM
C2: Retail | H2: Attraction | K2: Retail + Attraction | N2: s | Q2: LOYALTY
A3: Store Code | B3: Store Name | C3: Target | D3: Last Week | E3: This Week | F3: WOW Sale | G3: Ach % | H3: Target | I3: This Week | J3: Ach % | K3: Target | L3: This Week | M3: Ach % | N3: LYSMD | O3: TYSMD | P3: Attach% | Q3: LOYALTY | R3: NOB | S3: Ach %
A4: THE8 | B4: AVK Delhi | C4: =Retail!M35 -> 520994.28 | D4: =SUMIFS(C37:AM37,$C$36:$AM$36,"="&$A$59) -> 215948 | E4: 282604 | F4: =E4/D4-1 -> 0.3086669 | G4: =E4/C4 -> 0.54243206 | H4: =Attraction!G35 -> 13653.531 | I4: 7800 | J4: =I4/H4 -> 0.5712808 | K4: =C4+H4 -> 534647.81 | L4: =+E4+I4 -> 290404 | M4: =L4/K4 -> 0.54316878 | N4: =VLOOKUP(T1,'LFL 2024'!A2:C33,3,0) -> #N/A | O4: =Z37 -> 100583 | P4: =O4/N4 -> #N/A | Q4: 12 | R4: 70 | S4: =Q4/R4*1 -> 0.17142857
A5: THH2 | B5: Delhi Pacific | C5: =Retail!J35 -> 286734.48 | D5: =SUMIFS(C38:AM38,$C$36:$AM$36,"="&$A$59) -> 55406 | E5: 89519 | F5: =E5/D5-1 -> 0.61569144 | G5: =E5/C5 -> 0.31220173 | H5: =Attraction!E35 -> 18519.062 | I5: 8200 | J5: =I5/H5 -> 0.442787 | K5: =C5+H5 -> 305253.54 | L5: =+E5+I5 -> 97719 | M5: =L5/K5 -> 0.32012405 | N5: =VLOOKUP(T1,'LFL 2024'!A2:D33,4,0) -> #N/A | O5: =Z38 -> 49455 | P5: =O5/N5 -> #N/A | Q5: 6 | R5: 36 | S5: =Q5/R5*1 -> 0.16666667
A6: TAHY | B6: Worldmark | C6: =Retail!H35 -> 63851.172 | D6: =SUMIFS(C39:AM39,$C$36:$AM$36,"="&$A$59) -> 20821 | E6: 34140 | F6: =E6/D6-1 -> 0.6396907 | G6: =E6/C6 -> 0.53468087 | H6: =Attraction!B35 -> 100564.04 | I6: 29500 | J6: =I6/H6 -> 0.29334541 | K6: =C6+H6 -> 164415.21 | L6: =+E6+I6 -> 63640 | M6: =L6/K6 -> 0.3870688 | N6: =VLOOKUP(T1,'LFL 2024'!A2:F33,5,0) -> #N/A | O6: =Z39 -> 10195 | P6: =O6/N6 -> #N/A | S6: =Q6/R6*1 -> #DIV/0!
A7: THH3 | B7: Delhi Selectcity | C7: =Retail!K35 -> 392222.7 | D7: =SUMIFS(C40:AM40,$C$36:$AM$36,"="&$A$59) -> 244035 | E7: 221767 | F7: =E7/D7-1 -> -0.091249206 | G7: =E7/C7 -> 0.56541093 | J7: =I7/H7 -> #DIV/0! | K7: =C7+H7 -> 392222.7 | L7: =+E7+I7 -> 221767 | M7: =L7/K7 -> 0.56541093 | N7: =VLOOKUP(T1,'LFL 2024'!A2:G33,6,0) -> #N/A | O7: =Z40 -> 76164 | P7: =O7/N7 -> #N/A | Q7: 12 | R7: 65 | S7: =Q7/R7*1 -> 0.18461538
A8: TLX5 | B8: Vegas Dwarka | C8: =Retail!L35 -> 176136.03 | D8: =SUMIFS(C41:AM41,$C$36:$AM$36,"="&$A$59) -> 93862 | E8: 76215 | F8: =E8/D8-1 -> -0.18801006 | G8: =E8/C8 -> 0.43270533 | H8: =Attraction!D35 -> 11996.078 | I8: 4250 | J8: =I8/H8 -> 0.35428246 | K8: =C8+H8 -> 188132.11 | L8: =+E8+I8 -> 80465 | M8: =L8/K8 -> 0.42770477 | N8: =VLOOKUP(T1,'LFL 2024'!A2:H33,7,0) -> #N/A | O8: =Z41 -> 31667 | P8: =O8/N8 -> #N/A | Q8: 5 | R8: 39 | S8: =Q8/R8*1 -> 0.12820513
A9: THF9 | B9: Amb Gurg Delhi | C9: =Retail!B35 -> 480133.83 | D9: =SUMIFS(C42:AM42,$C$36:$AM$36,"="&$A$59) -> 290337 | E9: 165757 | F9: =E9/D9-1 -> -0.42908758 | G9: =E9/C9 -> 0.34523083 | J9: =I9/H9 -> #DIV/0! | K9: =C9+H9 -> 480133.83 | L9: =+E9+I9 -> 165757 | M9: =L9/K9 -> 0.34523083 | N9: =VLOOKUP(T1,'LFL 2024'!A2:I33,8,0) -> #N/A | O9: =Z42 -> 71976 | P9: =O9/N9 -> #N/A | Q9: 20 | R9: 74 | S9: =Q9/R9*1 -> 0.27027027
A10: THI7 | B10: WTP Jaipur | C10: =Retail!F35 -> 190041.27 | D10: =SUMIFS(C43:AM43,$C$36:$AM$36,"="&$A$59) -> 84325 | E10: 56762 | F10: =E10/D10-1 -> -0.32686629 | G10: =E10/C10 -> 0.29868248 | J10: =I10/H10 -> #DIV/0! | K10: =C10+H10 -> 190041.27 | L10: =+E10+I10 -> 56762 | M10: =L10/K10 -> 0.29868248 | N10: =VLOOKUP(T1,'LFL 2024'!A2:J33,9,0) -> #N/A | O10: =Z43 -> 23548 | P10: =O10/N10 -> #N/A | Q10: 4 | R10: 29 | S10: =Q10/R10*1 -> 0.13793103
A11: THM0 | B11: Ardee Mall, Gurgaon | C11: =Retail!C35 -> 174186.13 | D11: =SUMIFS(C44:AM44,$C$36:$AM$36,"="&$A$59) -> 52628 | E11: 60455 | F11: =E11/D11-1 -> 0.14872311 | G11: =E11/C11 -> 0.34707127 | J11: =I11/H11 -> #DIV/0! | K11: =C11+H11 -> 174186.13 | L11: =+E11+I11 -> 60455 | M11: =L11/K11 -> 0.34707127 | N11: =VLOOKUP(T1,'LFL 2024'!A2:K33,10,0) -> #N/A | O11: =Z44 -> 9526 | P11: =O11/N11 -> #N/A | Q11: 4 | R11: 22 | S11: =Q11/R11*1 -> 0.18181818
A12: TJY4 | B12: Airia Mall Gurg | C12: =Retail!D35 -> 108239.76 | D12: =SUMIFS(C45:AM45,$C$36:$AM$36,"="&$A$59) -> 48671 | E12: 65881 | F12: =E12/D12-1 -> 0.35359865 | G12: =E12/C12 -> 0.60865806 | J12: =I12/H12 -> #DIV/0! | K12: =C12+H12 -> 108239.76 | L12: =+E12+I12 -> 65881 | M12: =L12/K12 -> 0.60865806 | N12: =VLOOKUP(T1,'LFL 2024'!A2:L33,11,0) -> #N/A | O12: =Z45 -> 5562 | P12: =O12/N12 -> #N/A | Q12: 1 | R12: 37 | S12: =Q12/R12*1 -> 0.027027027
A13: TXUT | B13: Vaishali | C13: =Retail!G35 -> 93298.933 | D13: =SUMIFS(C46:AM46,$C$36:$AM$36,"="&$A$59) -> 26042 | E13: 40669 | F13: =E13/D13-1 -> 0.56166961 | G13: =E13/C13 -> 0.43589995 | J13: =I13/H13 -> #DIV/0! | K13: =C13+H13 -> 93298.933 | L13: =+E13+I13 -> 40669 | M13: =L13/K13 -> 0.43589995 | N13: =VLOOKUP(T2,'LFL 2024'!A3:L34,11,0) -> #N/A | O13: =Z46 -> 23310 | P13: =O13/N13 -> #N/A | Q13: 0 | R13: 7 | S13: =Q13/R13*1 -> 0
A14: TXYT | B14: Good Earth | F14: =E14/D14-1 -> #DIV/0! | G14: =E14/C14 -> #DIV/0! | J14: =I14/H14 -> #DIV/0! | K14: =C14+H14 -> 0 | L14: =+E14+I14 -> 0 | M14: =L14/K14 -> #DIV/0! | N14: =VLOOKUP(T3,'LFL 2024'!A4:L35,11,0) -> #N/A | O14: =Z47 -> 0 | P14: =O14/N14 -> #N/A | S14: =Q14/R14*1 -> #DIV/0!
A15: TAUN | B15: Udaipur | C15: =Retail!I35 -> 75609.562 | D15: =SUMIFS(C48:AM48,$C$36:$AM$36,"="&$A$59) -> 20000 | E15: 9354 | F15: =E15/D15-1 -> -0.5323 | G15: =E15/C15 -> 0.12371451 | H15: =Attraction!C35 -> 4391.1341 | I15: 2850 | J15: =I15/H15 -> 0.64903506 | K15: =C15+H15 -> 80000.696 | L15: =+E15+I15 -> 12204 | M15: =L15/K15 -> 0.15254867 | N15: =VLOOKUP(T4,'LFL 2024'!A5:L36,11,0) -> #N/A | O15: =Z48 -> 4195 | P15: =O15/N15 -> #N/A | Q15: 2 | R15: 9 | S15: =Q15/R15*1 -> 0.22222222
A16: THE1 | B16: Elante Chandigarh | C16: =Retail!N35 -> 478539.4 | D16: =SUMIFS(C49:AM49,$C$36:$AM$36,"="&$A$59) -> 187202 | E16: 243281 | F16: =E16/D16-1 -> 0.29956411 | G16: =E16/C16 -> 0.50838238 | H16: =Attraction!F35 -> 86995.04 | I16: =4500+12681+53076 -> 70257 | J16: =I16/H16 -> 0.80759777 | K16: =C16+H16 -> 565534.44 | L16: =+E16+I16 -> 313538 | M16: =L16/K16 -> 0.55441009 | N16: =VLOOKUP(T5,'LFL 2024'!A6:L37,11,0) -> #N/A | O16: =Z49 -> 118788 | P16: =O16/N16 -> #N/A | Q16: 22 | R16: 113 | S16: =Q16/R16*1 -> 0.19469027
A17: TF5T | B17: Pacific D21 | C17: 0 | D17: 0 | F17: =E17/D17-1 -> #DIV/0! | G17: =E17/C17 -> #DIV/0! | J17: =I17/H17 -> #DIV/0! | K17: =C17+H17 -> 0 | L17: =+E17+I17 -> 0 | M17: =L17/K17 -> #DIV/0! | N17: =VLOOKUP(T6,'LFL 2024'!A7:L38,11,0) -> #N/A | O17: =Z50 -> 0 | P17: =O17/N17 -> #N/A | Q17: 0 | S17: =Q17/R17*1 -> #DIV/0!
A18: TXPH | B18: NH-1 Ambala store | C18: =Retail!P35 -> 52418.276 | D18: =SUMIFS(C51:AM51,$C$36:$AM$36,"="&$A$59) -> 12072 | E18: 20028 | F18: =E18/D18-1 -> 0.65904573 | G18: =E18/C18 -> 0.38208048 | J18: =I18/H18 -> #DIV/0! | K18: =C18+H18 -> 52418.276 | L18: =+E18+I18 -> 20028 | M18: =L18/K18 -> 0.38208048 | N18: =VLOOKUP(T7,'LFL 2024'!A8:L39,11,0) -> #N/A | O18: =Z51 -> 10004 | P18: =O18/N18 -> #N/A | Q18: 2 | R18: 6 | S18: =Q18/R18*1 -> 0.33333333
A19: TXR2 | B19: Zirakpur | C19: =Retail!Q35 -> 50054.432 | D19: =SUMIFS(C52:AM52,$C$36:$AM$36,"="&$A$59) -> 24076 | E19: 9925 | F19: =E19/D19-1 -> -0.58776375 | G19: =E19/C19 -> 0.19828414 | J19: =I19/H19 -> #DIV/0! | K19: =C19+H19 -> 50054.432 | L19: =+E19+I19 -> 9925 | M19: =L19/K19 -> 0.19828414 | N19: =VLOOKUP(T8,'LFL 2024'!A9:L40,11,0) -> #N/A | O19: =Z52 -> 10022 | P19: =O19/N19 -> #N/A | Q19: 1 | R19: 10 | S19: =Q19/R19*1 -> 0.1
A20: T2DD | B20: CP-67 | C20: =Retail!R35 -> 173176.09 | D20: =SUMIFS(C53:AM53,$C$36:$AM$36,"="&$A$59) -> 83413 | E20: 76520 | F20: =E20/D20-1 -> -0.082636999 | G20: =E20/C20 -> 0.44186238 | H20: 24039 | I20: 27592 | J20: =I20/H20 -> 1.1478015 | K20: =C20+H20 -> 197215.09 | L20: =+E20+I20 -> 104112 | M20: =L20/K20 -> 0.52791091 | N20: =VLOOKUP(T9,'LFL 2024'!A10:L41,11,0) -> #N/A | O20: =Z53 -> 35746 | P20: =O20/N20 -> #N/A | Q20: 15 | R20: 49 | S20: =Q20/R20*1 -> 0.30612245
A21: TL60 | B21: Iris | C21: =Retail!S35 -> 69239.832 | D21: =SUMIFS(C54:AM54,$C$36:$AM$36,"="&$A$59) -> 40092 | E21: 11576 | F21: =E21/D21-1 -> -0.71126409 | G21: =E21/C21 -> 0.167187 | J21: =I21/H21 -> #DIV/0! | K21: =C21+H21 -> 69239.832 | L21: =+E21+I21 -> 11576 | M21: =L21/K21 -> 0.167187 | N21: =VLOOKUP(T10,'LFL 2024'!A11:L42,11,0) -> #N/A | O21: =Z54 -> 13410 | P21: =O21/N21 -> #N/A | Q21: 1 | R21: 12 | S21: =Q21/R21*1 -> 0.083333333
A22: TM1H | B22: Faridabad | C22: =Retail!T35 -> 118798.39 | D22: =SUMIFS(C55:AM55,$C$36:$AM$36,"="&$A$59) -> 36461 | E22: 42688 | F22: =E22/D22-1 -> 0.17078522 | G22: =E22/C22 -> 0.35933147 | J22: =I22/H22 -> #DIV/0! | K22: =C22+H22 -> 118798.39 | L22: =+E22+I22 -> 42688 | M22: =L22/K22 -> 0.35933147 | N22: =VLOOKUP(T11,'LFL 2024'!A12:L43,11,0) -> #N/A | O22: =Z55 -> 8150 | P22: =O22/N22 -> #N/A | S22: =Q22/R22*1 -> #DIV/0!
A23: TB6V | B23: Elegante | C23: =Retail!U35 -> 187326.31 | D23: =SUMIFS(C56:AM56,$C$36:$AM$36,"="&$A$59) -> 74941 | E23: 33309 | F23: =E23/D23-1 -> -0.55553035 | G23: =E23/C23 -> 0.17781271 | J23: =I23/H23 -> #DIV/0! | K23: =C23+H23 -> 187326.31 | L23: =+E23+I23 -> 33309 | M23: =L23/K23 -> 0.17781271 | N23: =VLOOKUP(T11,'LFL 2024'!A12:L43,11,0) -> #N/A | O23: =Z56 -> 28213 | P23: =O23/N23 -> #N/A | Q23: 3 | R23: 27 | S23: =Q23/R23*1 -> 0.11111111
A24: TBDE | B24: Dlf Summit Plaza | C24: =Retail!V35 -> 157216.41 | D24: =SUMIFS(C57:AM57,$C$36:$AM$36,"="&$A$59) -> 31412 | E24: 52123 | F24: =E24/D24-1 -> 0.65933401 | G24: =E24/C24 -> 0.33153665 | J24: =I24/H24 -> #DIV/0! | K24: =C24+H24 -> 157216.41 | L24: =+E24+I24 -> 52123 | M24: =L24/K24 -> 0.33153665
A25: TD9T | B25: Jodhpur | C25: =Retail!W35 -> 138746.39 | D25: =SUMIFS(C58:AM58,$C$36:$AM$36,"="&$A$59) -> 14381 | E25: 38180 | F25: =E25/D25-1 -> 1.6548919 | G25: =E25/C25 -> 0.27517833 | J25: =I25/H25 -> #DIV/0! | K25: =C25+H25 -> 138746.39 | L25: =+E25+I25 -> 38180 | M25: =L25/K25 -> 0.27517833
C26: =SUM(C4:C25) -> 3986963.7 | D26: =SUM(D4:D24) -> 1641744 | E26: =SUM(E3:E25) -> 1630753 | F26: =E26/D26-1 -> -0.00669471 | G26: =E26/C26 -> 0.40902128 | H26: =SUM(H4:H24) -> 260157.89 | I26: =SUM(I3:I24) -> 150449 | J26: =I26/H26 -> 0.57829882 | K26: =SUM(K4:K25) -> 4247121.6 | L26: =SUM(L4:L25) -> 1781202 | M26: =L26/K26 -> 0.4193904 | N26: =VLOOKUP(T12,'LFL 2024'!A13:K44,10,0) -> #N/A | O26: =E26 -> 1630753 | P26: =O26/N26 -> #N/A | Q26: =SUM(Q3:Q23) -> 110 | R26: =SUM(R3:R23) -> 605 | S26: =+Q26/R26 -> 0.18181818
C28: Target | D28: Last Week | E28: This Week | F28: WOW | G28: Ach% | H28: Target | I28: This Week | J28: Ach % | K28: Target | L28: This Week | M28: Ach % | N28: NOB | O28: Loyalty | P28: Attach% | Q28: Loyalty | R28: NOB | S28: Ach %
B29: Ajay | C29: =+C4+C20+C10+C13+C15+C25 -> 1191866.5 | D29: =+D4+D20+D10+D13+D15 -> 429728 | E29: =+E4+E20+E10+E13+E15+E25 -> 504089 | F29: =E29/D29-1 -> 0.17304202 | G29: =+E29/C29 -> 0.42294081 | H29: =+H4+H20+H10+H13+H15 -> 42083.665 | I29: =+I4+I20+I10+I13+I15 -> 38242 | J29: =I29/H29 -> 0.90871363 | K29: =+K4+K20+K10+K13+K15+K25 -> 1233950.2 | L29: =+L4+L20+L10+L13+L15+L25 -> 542331 | M29: =L29/K29 -> 0.43950801 | N29: =+N4+N20 -> #N/A | O29: =+O4+O20+O10+O13+O15 -> 187382 | P29: =O29/N29-1 -> #N/A | Q29: =+Q4+Q20+Q10+Q13+Q15 -> 33 | R29: =+R4+R20+R10+R13+R15 -> 164 | S29: =Q29/R29*1 -> 0.20121951
B30: Shashank | C30: 0 | D30: 0 | F30: =E30/D30-1 -> #DIV/0! | G30: =+E30/C30 -> #DIV/0! | H30: 0 | I30: 0 | J30: =I30/H30 -> #DIV/0! | K30: 0 | L30: 0 | M30: =L30/K30 -> #DIV/0! | N30: =+N10+N13+N15 -> #N/A | O30: 0 | P30: =O30/N30-1 -> #N/A | Q30: =+Q9+Q12+Q14 -> 21 | R30: =+R9+R12+R14 -> 111 | S30: =Q30/R30*1 -> 0.18918919
B31: Param | C31: =+C11+C9+C12+C6+C14+C21+C22+C24 -> 1171665.5 | D31: =+D11+D9+D12+D6+D14+D21+D22+D24 -> 520422 | E31: =+E6+E9+E11+E14+E21+E22+E12+E24 -> 432620 | F31: =E31/D31-1 -> -0.16871308 | G31: =+E31/C31 -> 0.36923507 | H31: =H11+H9+H12+H6+H14+H21+H22+H24 -> 100564.04 | I31: =I11+I9+I12+I6+I14+I21+I22+I24 -> 29500 | J31: =I31/H31 -> 0.29334541 | K31: =K11+K9+K12+K6+K14+K21+K22+K24 -> 1272229.6 | L31: =L11+L9+L12+L6+L14+L21+L22+L24 -> 462120 | M31: =L31/K31 -> 0.36323633 | N31: =+N11+N9+N12+N6+N14+N21 -> #N/A | O31: =+O11+O9+O12+O6+O14+O21 -> 110669 | P31: =O31/N31-1 -> #N/A | Q31: =+Q10+Q8+Q11+Q5+Q13+Q20 -> 34 | R31: =+R10+R8+R11+R5+R13+R20 -> 182 | S31: =Q31/R31*1 -> 0.18681319
B32: Harsh | C32: =+C5+C7+C8+C19+C18+C16+C23 -> 1623431.6 | D32: =+D5+D7+D8+D19+D18+D16+D23 -> 691594 | E32: =+E5+E7+E8+E16+E17+E18+E19+E23 -> 694044 | F32: =E32/D32-1 -> 0.0035425409 | G32: =+E32/C32 -> 0.42751662 | H32: =+H5+H7+H8+H19+H18+H17+H16+H23 -> 117510.18 | I32: =+I5+I7+I8+I19+I18+I17+I16+I23 -> 82707 | J32: =I32/H32 -> 0.70382838 | K32: =+K5+K7+K8+K19+K18+K17+K16+K23 -> 1740941.8 | L32: =+L5+L7+L8+L19+L18+L17+L16+L23 -> 776751 | M32: =L32/K32 -> 0.44616712 | N32: =+N5+N7+N8+N19+N18+N17+N16+N23 -> #N/A | O32: =+O5+O7+O8+O19+O18+O17+O16+O23 -> 324313 | P32: =O32/N32-1 -> #N/A | Q32: =+Q4+Q6+Q7+Q18+Q17+Q16+Q15+Q22 -> 50 | R32: =+R4+R6+R7+R18+R17+R16+R15+R22 -> 263 | S32: =Q32/R32*1 -> 0.19011407
C33: =SUM(C29:C32) -> 3986963.7 | D33: =SUM(D29:D32) -> 1641744 | E33: =SUM(E29:E32) -> 1630753 | F33: =E33/D33-1 -> -0.00669471 | G33: =+E33/C33 -> 0.40902128 | H33: =SUM(H29:H32) -> 260157.89 | I33: =SUM(I29:I32) -> 150449 | J33: =I33/H33 -> 0.57829882 | K33: =SUM(K29:K32) -> 4247121.6 | L33: =SUM(L29:L32) -> 1781202 | M33: =L33/K33 -> 0.4193904 | N33: =SUM(N4:N23) -> #N/A | O33: =SUM(O29:O32) -> 622364 | P33: =SUM(P4:P23) -> #N/A | Q33: =SUM(Q29:Q32) -> 138 | R33: =SUM(R29:R32) -> 720 | S33: =+Q33/R33 -> 0.19166667
A36: Store Code | B36: Store Name | C36: 46259 | D36: =C36+1 -> 46260 | E36: =D36+1 -> 46261 | F36: =E36+1 -> 46262 | G36: =F36+1 -> 46263 | H36: =G36+1 -> 46264 | I36: =H36+1 -> 46265 | J36: =I36+1 -> 46266 | K36: =J36+1 -> 46267 | ... AP36: =AO36+1 -> 46298
A37: THE8 | B37: AVK Delhi | C37: 137270 | D37: 189419 | E37: 212559 | F37: 198820 | G37: 276544 | H37: 326183 | I37: 128034 | J37: 94857 | K37: 71171 | L37: 133567 | M37: 134103 | N37: 209901 | P37: 57731 | Q37: 65166 | R37: 122525 | S37: 116126 | T37: 152761 | U37: 233248 | V37: 224781 | W37: 149831 | X37: 102569 | Y37: 102569 | Z37: 100583 | AA37: 294381 | AB37: 215948 | AC37: 296414 | AD37: 107605 | AE37: 79076 | AF37: 97344 | AG37: 144787 | AH37: 108402 | AI37: 282604
A38: THH2 | B38: Delhi Pacific | C38: 39699 | D38: 125114 | E38: 111226 | F38: 83127 | G38: 62006 | H38: 72310 | I38: 24717 | J38: 73926 | K38: 43484 | L38: 36303 | N38: 48586 | P38: 43789 | Q38: 23415 | R38: 32683 | S38: 14029 | U38: 46905 | V38: 123720 | W38: 47374 | X38: 33134 | Y38: 33134 | Z38: 49455 | AA38: 35366 | AB38: 55406 | AC38: 78901 | AD38: 54880 | AE38: 66459 | AF38: 38070 | AG38: 18172 | AH38: 57101 | AI38: 89519
A39: TAHY | B39: Worldmark | C39: 15499 | D39: 9976 | E39: 40984 | F39: 27410 | G39: 11813 | H39: 43713 | I39: 8086 | J39: 9645 | K39: 3269 | L39: 999 | M39: 23435 | N39: 30119 | P39: 3897 | Q39: 999 | R39: 3507 | S39: 4642 | T39: 2682 | U39: 10040 | V39: 14500 | W39: 7346 | X39: 6996 | Y39: 6996 | Z39: 10195 | AA39: 7897 | AB39: 20821 | AC39: 38071 | AD39: 0 | AE39: 0 | AF39: 5904 | AG39: 11851 | AH39: 7251 | AI39: 34140
A40: THH3 | B40: Delhi Selectcity | C40: 105679 | D40: 230329 | E40: 193769 | F40: 210589 | G40: 240659 | H40: 279799 | I40: 99587 | J40: 53479 | K40: 34523 | L40: 77393 | M40: 95400 | N40: 299840 | Q40: 58238 | R40: 76021 | S40: 119379 | T40: 86564 | U40: 95240 | V40: 158899 | W40: 97087 | X40: 114372 | Y40: 114372 | Z40: 76164 | AA40: 50939 | AB40: 244035 | AC40: 209321 | AE40: 82091 | AF40: 97917 | AG40: 88237 | AH40: 125978 | AI40: 221767
A41: TLX5 | B41: Vegas Dwarka | C41: 39658 | D41: 81361 | E41: 77409 | F41: 83854 | G41: 48031 | H41: 59704 | I41: 10864 | K41: 48953 | L41: 31197 | M41: 8597 | N41: 90557 | P41: 7075 | Q41: 12336 | R41: 53293 | S41: 26507 | T41: 60102 | U41: 157930 | V41: 71664 | W41: 22114 | X41: 28601 | Y41: 28601 | Z41: 31667 | AA41: 25234 | AB41: 93862 | AC41: 99460 | AD41: 25745 | AE41: 59283 | AF41: 38475 | AG41: 50523 | AH41: 39799 | AI41: 76215
A42: THF9 | B42: Amb Gurg Delhi | C42: 101463 | D42: 236449 | E42: 275663 | F42: 245777 | G42: 360195 | H42: 594692 | I42: 65667 | J42: 41971 | K42: 64361 | L42: 103370 | M42: 126887 | N42: 153987 | P42: 57998 | Q42: 64057 | R42: 56438 | S42: 24930 | T42: 98630 | U42: 195835 | V42: 199286 | W42: 85938 | X42: 112826 | Z42: 71976 | AA42: 149226 | AB42: 290337 | AC42: 211367 | AD42: 71186 | AE42: 107304 | AF42: 143804 | AG42: 122824 | AH42: 122672 | AI42: 165757
A43: THI7 | B43: WTP Jaipur | C43: 69785 | D43: 71578 | E43: 121190 | F43: 78328 | G43: 112339 | H43: 61112 | I43: 25698 | J43: 16683 | K43: 48322 | L43: 32686 | N43: 59471 | P43: 44658 | Q43: 19345 | R43: 41358 | S43: 41437 | T43: 36352 | U43: 63241 | V43: 39010 | W43: 15243 | X43: 13223 | Y43: 13223 | Z43: 23548 | AA43: 5198 | AB43: 84325 | AC43: 95542 | AD43: 30590 | AE43: 23687 | AF43: 37450 | AG43: 29322 | AH43: 17836 | AI43: 56762
...

Sheet 7PM
A1: Sale Report 7PM
H2: Attraction | K2: Retail + Attraction | N2: LOYALTY | Q2: LOYALTY
A3: Store Code | B3: Store Name | C3: Target | D3: Last Week | E3: This week | F3: WOW Sale | G3: Ach % | H3: Target | I3: This Week | J3: Ach % | K3: Target | L3: This Week | M3: Ach % | N3: LYSMD | O3: TYSMD | P3: Attach% | Q3: Loyalty | R3: NOB | S3: Ach % | SE3: 46058
A4: THE8 | B4: AVK Delhi | C4: =Retail!M35 -> 520994.28 | D4: =SUMIFS(C37:AM37,$C$36:$AM$36,"="&$A$59) -> 333960 | E4: 450292 | F4: =E4/D4-1 -> 0.34834112 | G4: =E4/C4 -> 0.86429355 | H4: =Attraction!G35 -> 13653.531 | I4: 8401 | J4: =I4/H4 -> 0.61529872 | K4: =C4+H4 -> 534647.81 | L4: =+E4+I4 -> 458693 | M4: =L4/K4 -> 0.85793487 | N4: =VLOOKUP(T1,'LFL 2024'!A2:C33,3,0) -> #N/A | O4: =AJ37 -> 0 | P4: =O4/N4-1 -> #N/A | S4: =Q4/R4*1 -> #DIV/0!
A5: THH2 | B5: Delhi Pacific | C5: =Retail!J35 -> 286734.48 | D5: =SUMIFS(C38:AM38,$C$36:$AM$36,"="&$A$59) -> 84133 | E5: 140976 | F5: =E5/D5-1 -> 0.67563263 | G5: =E5/C5 -> 0.49166044 | H5: =Attraction!E35 -> 18519.062 | I5: 14000 | J5: =I5/H5 -> 0.7559778 | K5: =C5+H5 -> 305253.54 | L5: =+E5+I5 -> 154976 | M5: =L5/K5 -> 0.507696 | N5: =VLOOKUP(T1,'LFL 2024'!A2:D33,4,0) -> #N/A | O5: =AJ38 -> 0 | P5: =O5/N5-1 -> #N/A | Q5: 13 | R5: 54 | S5: =Q5/R5*1 -> 0.24074074
A6: TAHY | B6: Worldmark | C6: =Retail!H35 -> 63851.172 | D6: =SUMIFS(C39:AM39,$C$36:$AM$36,"="&$A$59) -> 22020 | F6: =E6/D6-1 -> -1 | G6: =E6/C6 -> 0 | H6: =Attraction!B35 -> 100564.04 | J6: =I6/H6 -> 0 | K6: =C6+H6 -> 164415.21 | L6: =+E6+I6 -> 0 | M6: =L6/K6 -> 0 | N6: =VLOOKUP(T1,'LFL 2024'!A2:F33,5,0) -> #N/A | O6: =AJ39 -> 0 | P6: =O6/N6-1 -> #N/A | Q6: 3 | R6: 21 | S6: =Q6/R6*1 -> 0.14285714
A7: THH3 | B7: Delhi Selectcity | C7: =Retail!K35 -> 392222.7 | D7: =SUMIFS(C40:AM40,$C$36:$AM$36,"="&$A$59) -> 368242 | E7: 315959 | F7: =E7/D7-1 -> -0.14198 | G7: =E7/C7 -> 0.80556021 | K7: =C7+H7 -> 392222.7 | L7: =+E7+I7 -> 315959 | M7: =L7/K7 -> 0.80556021 | N7: =VLOOKUP(T1,'LFL 2024'!A2:G33,6,0) -> #N/A | O7: =AJ40 -> 0 | P7: =O7/N7-1 -> #N/A | Q7: 18 | R7: 100 | S7: =Q7/R7*1 -> 0.18
A8: TLX5 | B8: Vegas Dwarka | C8: =Retail!L35 -> 176136.03 | D8: =SUMIFS(C41:AM41,$C$36:$AM$36,"="&$A$59) -> 129904 | E8: 361821 | F8: =E8/D8-1 -> 1.7852953 | G8: =E8/C8 -> 2.0542134 | H8: =Attraction!D35 -> 11996.078 | I8: 6650 | J8: =I8/H8 -> 0.55434784 | K8: =C8+H8 -> 188132.11 | L8: =+E8+I8 -> 368471 | M8: =L8/K8 -> 1.9585758 | N8: =VLOOKUP(T1,'LFL 2024'!A2:H33,7,0) -> #N/A | O8: =AJ41 -> 0 | P8: =O8/N8-1 -> #N/A | Q8: 12 | R8: 66 | S8: =Q8/R8*1 -> 0.18181818
A9: THF9 | B9: Amb Gurg Delhi | C9: =Retail!B35 -> 480133.83 | D9: =SUMIFS(C42:AM42,$C$36:$AM$36,"="&$A$59) -> 449241 | E9: 300542 | F9: =E9/D9-1 -> -0.33100051 | G9: =E9/C9 -> 0.62595464 | K9: =C9+H9 -> 480133.83 | L9: =+E9+I9 -> 300542 | M9: =L9/K9 -> 0.62595464 | N9: =VLOOKUP(T1,'LFL 2024'!A2:I33,8,0) -> #N/A | O9: =AJ42 -> 0 | P9: =O9/N9-1 -> #N/A | Q9: 26 | R9: 109 | S9: =Q9/R9*1 -> 0.23853211
A10: THI7 | B10: WTP Jaipur | C10: =Retail!F35 -> 190041.27 | D10: =SUMIFS(C43:AM43,$C$36:$AM$36,"="&$A$59) -> 114385 | E10: 84865 | F10: =E10/D10-1 -> -0.2580758 | G10: =E10/C10 -> 0.44656089 | K10: =C10+H10 -> 190041.27 | L10: =+E10+I10 -> 84865 | M10: =L10/K10 -> 0.44656089 | N10: =VLOOKUP(T1,'LFL 2024'!A2:J33,9,0) -> #N/A | O10: =AJ43 -> 0 | P10: =O10/N10-1 -> #N/A | Q10: 4 | R10: 42 | S10: =Q10/R10*1 -> 0.095238095
A11: THM0 | B11: Ardee Mall, Gurgaon | C11: =Retail!C35 -> 174186.13 | D11: =SUMIFS(C44:AM44,$C$36:$AM$36,"="&$A$59) -> 110564 | E11: 102367 | F11: =E11/D11-1 -> -0.074138056 | G11: =E11/C11 -> 0.58768745 | K11: =C11+H11 -> 174186.13 | L11: =+E11+I11 -> 102367 | M11: =L11/K11 -> 0.58768745 | N11: =VLOOKUP(T1,'LFL 2024'!A2:K33,10,0) -> #N/A | O11: =AJ44 -> 0 | P11: =O11/N11-1 -> #N/A | Q11: 5 | R11: 37 | S11: =Q11/R11*1 -> 0.13513514
A12: TJY4 | B12: Airia Mall Gurg | C12: =Retail!D35 -> 108239.76 | D12: =SUMIFS(C45:AM45,$C$36:$AM$36,"="&$A$59) -> 63636 | E12: 91779 | F12: =E12/D12-1 -> 0.44224967 | G12: =E12/C12 -> 0.8479232 | K12: =C12+H12 -> 108239.76 | L12: =+E12+I12 -> 91779 | M12: =L12/K12 -> 0.8479232 | N12: =VLOOKUP(T1,'LFL 2024'!A2:L33,11,0) -> #N/A | O12: =AJ45 -> 0 | P12: =O12/N12-1 -> #N/A | Q12: 1 | R12: 54 | S12: =Q12/R12*1 -> 0.018518519
A13: TXUT | B13: Vaishali | C13: =Retail!G35 -> 93298.933 | D13: =SUMIFS(C46:AM46,$C$36:$AM$36,"="&$A$59) -> 28684 | E13: 55011 | F13: =E13/D13-1 -> 0.91782875 | G13: =E13/C13 -> 0.58962089 | K13: =C13+H13 -> 93298.933 | L13: =+E13+I13 -> 55011 | M13: =L13/K13 -> 0.58962089 | N13: =VLOOKUP(T1,'LFL 2024'!A2:M33,12,0) -> #N/A | O13: =AJ46 -> 0 | P13: =O13/N13-1 -> #N/A | Q13: 0 | R13: 10 | S13: =Q13/R13*1 -> 0
A14: TXYT | B14: Good Earth | D14: =SUMIFS(C47:AM47,$C$36:$AM$36,"="&$A$59) -> 0 | F14: =E14/D14-1 -> #DIV/0! | G14: =E14/C14 -> #DIV/0! | K14: =C14+H14 -> 0 | L14: =+E14+I14 -> 0 | M14: =L14/K14 -> #DIV/0! | N14: =VLOOKUP(T1,'LFL 2024'!A2:N33,13,0) -> #N/A | O14: =AJ47 -> 0 | P14: =O14/N14-1 -> #N/A | S14: =Q14/R14*1 -> #DIV/0!
A15: TAUN | B15: Udaipur | C15: =Retail!I35 -> 75609.562 | D15: =SUMIFS(C48:AM48,$C$36:$AM$36,"="&$A$59) -> 30864 | F15: =E15/D15-1 -> -1 | G15: =E15/C15 -> 0 | H15: =Attraction!C35 -> 4391.1341 | J15: =I15/H15 -> 0 | K15: =C15+H15 -> 80000.696 | L15: =+E15+I15 -> 0 | M15: =L15/K15 -> 0 | N15: =VLOOKUP(T1,'LFL 2024'!A2:O33,14,0) -> #N/A | O15: =AJ48 -> 0 | P15: =O15/N15-1 -> #N/A | Q15: 3 | R15: 22 | S15: =Q15/R15*1 -> 0.13636364
A16: THE1 | B16: Elante Chandigarh | C16: =Retail!N35 -> 478539.4 | D16: =SUMIFS(C49:AM49,$C$36:$AM$36,"="&$A$59) -> 266450 | E16: 350784 | F16: =E16/D16-1 -> 0.31650966 | G16: =E16/C16 -> 0.73303055 | H16: =Attraction!F35 -> 86995.04 | I16: =70368+15081+6000 -> 91449 | J16: =I16/H16 -> 1.0511979 | K16: =C16+H16 -> 565534.44 | L16: =+E16+I16 -> 442233 | M16: =L16/K16 -> 0.7819736 | N16: =VLOOKUP(T1,'LFL 2024'!A2:P33,15,0) -> #N/A | O16: =AJ49 -> 0 | P16: =O16/N16-1 -> #N/A | Q16: 26 | R16: 166 | S16: =Q16/R16*1 -> 0.15662651
A17: TF5T | B17: Pacific D21 | C17: 0 | D17: =SUMIFS(C50:AM50,$C$36:$AM$36,"="&$A$59) -> 0 | F17: =E17/D17-1 -> #DIV/0! | G17: =E17/C17 -> #DIV/0! | K17: =C17+H17 -> 0 | L17: =+E17+I17 -> 0 | M17: =L17/K17 -> #DIV/0! | N17: =VLOOKUP(T1,'LFL 2024'!A2:Q33,16,0) -> #N/A | O17: =AJ50 -> 0 | P17: =O17/N17-1 -> #N/A | S17: =Q17/R17*1 -> #DIV/0!
A18: TXPH | B18: NH-1 Ambala store | C18: =Retail!P35 -> 52418.276 | D18: =SUMIFS(C51:AM51,$C$36:$AM$36,"="&$A$59) -> 22326 | E18: 29221 | F18: =E18/D18-1 -> 0.30883275 | G18: =E18/C18 -> 0.55745824 | K18: =C18+H18 -> 52418.276 | L18: =+E18+I18 -> 29221 | M18: =L18/K18 -> 0.55745824 | N18: =VLOOKUP(T1,'LFL 2024'!A2:R33,17,0) -> #N/A | O18: =AJ51 -> 0 | P18: =O18/N18-1 -> #N/A | Q18: 4 | R18: 12 | S18: =Q18/R18*1 -> 0.33333333
A19: TXR2 | B19: Zirakpur | C19: =Retail!Q35 -> 50054.432 | D19: =SUMIFS(C52:AM52,$C$36:$AM$36,"="&$A$59) -> 24076 | E19: 12251 | F19: =E19/D19-1 -> -0.49115302 | G19: =E19/C19 -> 0.24475355 | K19: =C19+H19 -> 50054.432 | L19: =+E19+I19 -> 12251 | M19: =L19/K19 -> 0.24475355 | N19: =VLOOKUP(T1,'LFL 2024'!A2:S33,18,0) -> #N/A | O19: =AJ52 -> 0 | P19: =O19/N19-1 -> #N/A | Q19: 2 | R19: 17 | S19: =Q19/R19*1 -> 0.11764706
A20: T2DD | B20: CP-67 | C20: =Retail!R35 -> 173176.09 | D20: =SUMIFS(C53:AM53,$C$36:$AM$36,"="&$A$59) -> 117745 | E20: 119707 | F20: =E20/D20-1 -> 0.016663128 | G20: =E20/C20 -> 0.69124437 | H20: =Attraction!H35 -> 37671.355 | I20: 41236 | J20: =I20/H20 -> 1.0946248 | K20: =C20+H20 -> 210847.45 | L20: =+E20+I20 -> 160943 | M20: =L20/K20 -> 0.76331491 | N20: =VLOOKUP(T1,'LFL 2024'!A2:T33,19,0) -> #N/A | O20: =AJ53 -> 0 | P20: =O20/N20-1 -> #N/A | Q20: 20 | R20: 71 | S20: =Q20/R20*1 -> 0.28169014
A21: TL60 | B21: Iris | C21: =Retail!S35 -> 69239.832 | D21: =SUMIFS(C54:AM54,$C$36:$AM$36,"="&$A$59) -> 41929 | E21: 32405 | F21: =E21/D21-1 -> -0.22714589 | G21: =E21/C21 -> 0.46801096 | K21: =C21+H21 -> 69239.832 | L21: =+E21+I21 -> 32405 | M21: =L21/K21 -> 0.46801096 | N21: =VLOOKUP(T1,'LFL 2024'!A2:U33,20,0) -> #N/A | O21: =AJ54 -> 0 | P21: =O21/N21-1 -> #N/A | Q21: 3 | R21: 19 | S21: =Q21/R21*1 -> 0.15789474
A22: T1MH | B22: Faridabad | C22: =Retail!T35 -> 118798.39 | D22: =SUMIFS(C55:AM55,$C$36:$AM$36,"="&$A$59) -> 57676 | F22: =E22/D22-1 -> -1 | G22: =E22/C22 -> 0 | K22: =C22+H22 -> 118798.39 | L22: =+E22+I22 -> 0 | M22: =L22/K22 -> 0 | N22: =VLOOKUP(T2,'LFL 2024'!A3:U34,20,0) -> #N/A | O22: =AJ55 -> 0 | P22: =O22/N22-1 -> #N/A | Q22: 9 | R22: 39 | S22: =Q22/R22*1 -> 0.23076923
A23: TB6V | B23: Elegante | C23: =Retail!U35 -> 187326.31 | D23: =SUMIFS(C56:AM56,$C$36:$AM$36,"="&$A$59) -> 121960 | F23: =E23/D23-1 -> -1 | G23: =E23/C23 -> 0 | K23: =C23+H23 -> 187326.31 | L23: =+E23+I23 -> 0 | M23: =L23/K23 -> 0 | N23: =VLOOKUP(T1,'LFL 2024'!A2:V33,21,0) -> #N/A | O23: =AJ56 -> 0 | P23: =O23/N23-1 -> #N/A | Q23: 7 | R23: 55 | S23: =Q23/R23*1 -> 0.12727273
A24: TBDE | B24: Dlf Summit Plaza | C24: =Retail!V35 -> 157216.41 | D24: =SUMIFS(C57:AM57,$C$36:$AM$36,"="&$A$59) -> 38706 | E24: 90146 | F24: =E24/D24-1 -> 1.3289929 | G24: =E24/C24 -> 0.57338799 | K24: =C24+H24 -> 157216.41 | L24: =+E24+I24 -> 90146 | M24: =L24/K24 -> 0.57338799
A25: TD9T | B25: Jodhpur | C25: =Retail!W35 -> 138746.39 | D25: =SUMIFS(C58:AM58,$C$36:$AM$36,"="&$A$59) -> 26434 | E25: 47557 | F25: =E25/D25-1 -> 0.79908451 | G25: =E25/C25 -> 0.34276207 | K25: =C25+H25 -> 138746.39 | L25: =+E25+I25 -> 47557 | M25: =L25/K25 -> 0.34276207
C26: =SUM(C4:C25) -> 3986963.7 | D26: =SUM(D4:D25) -> 2452935 | E26: =SUM(E4:E25) -> 2585683 | F26: =E26/D26-1 -> 0.054118026 | G26: =E26/C26 -> 0.64853438 | H26: =SUM(H4:H24) -> 273790.24 | I26: =SUM(I4:I24) -> 161736 | J26: =I26/H26 -> 0.5907296 | K26: =SUM(K4:K25) -> 4260753.9 | L26: =SUM(L4:L25) -> 2747419 | M26: =L26/K26 -> 0.64481992 | N26: =SUM(N4:N23) -> #N/A | O26: =SUM(O4:O23) -> 0 | P26: =O26/N26-1 -> #N/A | Q26: =SUM(Q4:Q23) -> 156 | R26: =SUM(R4:R23) -> 894 | S26: =Q26/R26*1 -> 0.17449664
C28: Target | D28: Last Week | E28: This Week | F28: WOW | G28: Ach% | H28: Target | I28: This Week | J28: Ach % | K28: Target | L28: This Week | M28: Ach % | N28: NOB | O28: Loyalty | P28: Attach% | Q28: Loyalty | R28: Red Card | S28: Ach %
B29: Ajay | C29: =+C4+C20+C10+C13+C15+C25 -> 1191866.5 | D29: =+D4+D20+D10+D13+D15+D25 -> 652072 | E29: =+E4+E20+E10+E13+E15+E25 -> 757432 | F29: =E29/D29-1 -> 0.16157725 | G29: =+E29/C29 -> 0.63550068 | H29: =+H4+H20+H15 -> 55716.02 | I29: =+I4+I20+I10+I13+I15 -> 49637 | J29: =I29/H29 -> 0.89089279 | K29: =+K4+K20+K10+K13+K15+K25 -> 1247582.6 | L29: =+L4+L20+L10+L13+L15+L25 -> 807069 | M29: =L29/K29 -> 0.64690629 | N29: =+N4+N20 -> #N/A | O29: =+O4+O20 -> 0 | P29: =O29/N29 -> #N/A | Q29: =+Q4+Q20 -> 20 | R29: =+R4+R20 -> 71 | S29: =Q29/R29*1 -> 0.28169014
B30: Shashank | C30: 0 | D30: 0 | E30: 0 | F30: =E30/D30-1 -> #DIV/0! | G30: =+E30/C30 -> #DIV/0! | H30: =+H10+H13 -> 0 | I30: 0 | J30: =I30/H30 -> #DIV/0! | K30: 0 | L30: 0 | M30: =L30/K30 -> #DIV/0! | N30: =+N10+N13+N15 -> #N/A | O30: =+O10+O13+O15 -> 0 | P30: =O30/N30 -> #N/A | Q30: =+Q5+Q21 -> 16 | R30: =+R5+R21 -> 73 | S30: =Q30/R30*1 -> 0.21917808
B31: Param | C31: =+C11+C9+C12+C6+C14+C21+C22+C24 -> 1171665.5 | D31: =+D11+D9+D12+D6+D14+D21+D22+D24 -> 783772 | E31: =+E11+E9+E12+E6+E14+E21+E22+E24 -> 617239 | F31: =E31/D31-1 -> -0.21247633 | G31: =+E31/C31 -> 0.52680479 | H31: =H11+H9+H12+H6+H14+H21+H22+H24 -> 100564.04 | I31: =I11+I9+I12+I6+I14+I21+I22+I24 -> 0 | J31: =I31/H31 -> 0 | K31: =K11+K9+K12+K6+K14+K21+K22+K24 -> 1272229.6 | L31: =L11+L9+L12+L6+L14+L21+L22+L24 -> 617239 | M31: =L31/K31 -> 0.48516323 | N31: =+N11+N9+N12+N6+N14+N21 -> #N/A | O31: =+O11+O9+O12+O6+O14+O21 -> 0 | P31: =O31/N31 -> #N/A | Q31: =+Q6+Q22 -> 12 | R31: =+R6+R22 -> 60 | S31: =Q31/R31*1 -> 0.2
B32: Harsh | C32: =+C5+C7+C8+C19+C17+C18+C16+C23 -> 1623431.6 | D32: =+D5+D7+D8+D19+D17+D18+D16+D23 -> 1017091 | E32: =+E5+E7+E8+E19+E17+E18+E16+E23 -> 1211012 | F32: =E32/D32-1 -> 0.19066239 | G32: =+E32/C32 -> 0.74595812 | H32: =+H5+H8+H16 -> 117510.18 | I32: =+I5+I7+I8+I19+I18+I17+I16+I23 -> 112099 | J32: =I32/H32 -> 0.95395139 | K32: =+K5+K7+K8+K19+K18+K17+K16+K23 -> 1740941.8 | L32: =+L5+L7+L8+L19+L18+L17+L16+L23 -> 1323111 | M32: =L32/K32 -> 0.75999726 | N32: =+N5+N7+N8+N19+N18+N17+N16+N23 -> #N/A | O32: =+O5+O7+O8+O19+O18+O17+O16+O23 -> 0 | P32: =O32/N32 -> #N/A | Q32: =+Q7+Q23 -> 25 | R32: =+R7+R23 -> 155 | S32: =Q32/R32*1 -> 0.16129032
C33: =SUM(C29:C32) -> 3986963.7 | D33: =SUM(D29:D32) -> 2452935 | E33: =SUM(E29:E32) -> 2585683 | F33: =E33/D33-1 -> 0.054118026 | G33: =+E33/C33 -> 0.64853438 | H33: =SUM(H29:H32) -> 273790.24 | I33: =SUM(I29:I32) -> 161736 | J33: =I33/H33 -> 0.5907296 | K33: =SUM(K29:K32) -> 4260753.9 | L33: =SUM(L29:L32) -> 2747419 | M33: =L33/K33 -> 0.64481992 | N33: =SUM(N29:N32) -> #N/A | O33: =SUM(O29:O32) -> 0 | P33: =O33/N33 -> #N/A | Q33: =SUM(Q29:Q32) -> 73 | R33: =SUM(R29:R32) -> 359 | S33: =+Q33/R33 -> 0.20334262
A36: Store Code | B36: Store Name | C36: 46259 | D36: =C36+1 -> 46260 | E36: =D36+1 -> 46261 | F36: =E36+1 -> 46262 | G36: =F36+1 -> 46263 | H36: =G36+1 -> 46264 | I36: =H36+1 -> 46265 | J36: =I36+1 -> 46266 | K36: =J36+1 -> 46267 | ... AP36: =AO36+1 -> 46298
A37: THE8 | B37: AVK Delhi | C37: 226258 | D37: 277580 | E37: 371875 | F37: 350510 | G37: 386304 | H37: 439607 | I37: 128034 | J37: 154783 | K37: 149426 | L37: 261489 | M37: 146170 | N37: 344085 | P37: 110994 | Q37: 65166 | R37: 180568 | S37: 171261 | T37: 205049 | U37: 467207 | V37: 385764 | W37: 169342 | X37: 217460 | Y37: 150861 | Z37: 180950 | AA37: 425028 | AB37: 333960 | AC37: 423099 | AE37: 108229 | AF37: 133290 | AG37: 203028
A38: THH2 | B38: Delhi Pacific | C38: 57799 | D38: 191145 | E38: 202912 | F38: 99132 | G38: 132109 | H38: 127364 | I38: 44440 | J38: 108143 | K38: 75563 | L38: 83397 | M38: 42672 | N38: 48586 | P38: 55320 | Q38: 27029 | R38: 68438 | S38: 15252 | T38: 46829 | U38: 90571 | V38: 148378 | X38: 31226 | Y38: 46255 | Z38: 83721 | AA38: 53113 | AB38: 84133 | AC38: 154462 | AE38: 85236 | AF38: 55442 | AG38: 57764
A39: TAHY | B39: Worldmark | C39: 28279 | D39: 22998 | E39: 50869 | F39: 30607 | G39: 24354 | H39: 54258 | I39: 8086 | J39: 9645 | K39: 5168 | L39: 6065 | M39: 24734 | N39: 35389 | P39: 8496 | Q39: 1048 | R39: 9104 | S39: 5741 | T39: 5480 | U39: 11538 | V39: 22720 | W39: 14172 | X39: 32446 | Y39: 9770 | Z39: 12194 | AA39: 16440 | AB39: 22020 | AC39: 48373 | AE39: 0 | AF39: 11501 | AG39: 16697
A40: THH3 | B40: Delhi Selectcity | C40: 182288 | D40: 369370 | E40: 248272 | F40: 296224 | G40: 359084 | H40: 326193 | I40: 99587 | J40: 83960 | K40: 50302 | L40: 133153 | M40: 130505 | N40: 349780 | P40: 68545 | Q40: 72224 | R40: 101521 | S40: 167561 | T40: 122689 | U40: 142796 | V40: 256995 | W40: 123928 | X40: 76172 | Y40: 156157 | Z40: 112758 | AA40: 77313 | AB40: 368242 | AC40: 304668 | AE40: 181529 | AF40: 143928 | AG40: 134378
A41: TLX5 | B41: Vegas Dwarka | C41: 56777 | D41: 116197 | E41: 103763 | F41: 110567 | G41: 71367 | H41: 114535 | I41: 25953 | J41: 55961 | K41: 54990 | L41: 40785 | M41: 37036 | N41: 142167 | P41: 37125 | Q41: 18978 | R41: 65287 | S41: 42025 | T41: 96100 | U41: 189720 | V41: 147124 | W41: 31102 | X41: 45001 | Y41: 29730 | Z41: 37034 | AA41: 56327 | AB41: 129904 | AC41: 149083 | AE41: 76420 | AF41: 55230 | AG41: 90464
A42: THF9 | B42: Amb Gurg Delhi | C42: 250112 | D42: 236449 | E42: 401066 | F42: 336916 | G42: 480207 | H42: 727037 | I42: 110233 | J42: 167844 | K42: 64361 | L42: 123050 | M42: 134504 | N42: 202285 | P42: 97567 | Q42: 81864 | R42: 56438 | S42: 95536 | T42: 144387 | U42: 315444 | V42: 245907 | W42: 126752 | X42: 84790 | Y42: 149803 | Z42: 109582 | AA42: 245352 | AB42: 449241 | AC42: 312288 | AE42: 147184 | AF42: 166607 | AG42: 182095
A43: THI7 | B43: WTP Jaipur | C43: 81379 | D43: 134351 | E43: 179844 | F43: 122753 | G43: 156042 | H43: 120980 | I43: 32302 | J43: 19680 | K43: 55141 | L43: 45561 | M43: 41570 | N43: 59471 | P43: 58031 | Q43: 19345 | R43: 54890 | S43: 50780 | T43: 57324 | U43: 72034 | V43: 51590 | X43: 50790 | Y43: 16324 | Z43: 31420 | AA43: 21714 | AB43: 114385 | AC43: 117511 | AE43: 26577 | AF43: 54998 | AG43: 58885
...

Sheet 9PM
A1: Sale Report 9PM | T1: =TODAY() -> 46291
H2: Attraction | K2: Retail + Attraction
A3: Store Code | B3: Store Name | C3: Target | D3: Last Week | E3: This week | F3: WOW Sale | G3: Ach % | H3: Target | I3: This Week | J3: Ach % | K3: Target | L3: This Week | M3: Ach % | N3: LYSMD | O3: TYSMD | P3: Attach% | Q3: 10K Bills | R3: Trolley
A4: THE8 | B4: AVK Delhi | C4: =Retail!M35 -> 520994.28 | D4: =SUMIFS(C34:AM34,$C$33:$AM$33,"="&$A$53) -> 0 | F4: =E4/D4-1 -> #DIV/0! | G4: =E4/C4 -> 0 | H4: =Attraction!G35 -> 13653.531 | J4: =I4/H4 -> 0 | K4: =C4+H4 -> 534647.81 | L4: =E4+I4 -> 0 | M4: =L4/K4 -> 0 | N4: =VLOOKUP(T1,'LFL 2024'!A2:C33,3,0) -> #N/A | O4: =E4 -> 0 | P4: =O4/N4-1 -> #N/A
A5: THH2 | B5: Delhi Pacific | C5: =Retail!J35 -> 286734.48 | D5: =SUMIFS(C35:AM35,$C$33:$AM$33,"="&$A$53) -> 0 | F5: =E5/D5-1 -> #DIV/0! | G5: =E5/C5 -> 0 | H5: =Attraction!E35 -> 18519.062 | J5: =I5/H5 -> 0 | K5: =C5+H5 -> 305253.54 | L5: =E5+I5 -> 0 | M5: =L5/K5 -> 0 | N5: =VLOOKUP(T1,'LFL 2024'!A2:D33,4,0) -> #N/A | O5: =E5 -> 0 | P5: =O5/N5-1 -> #N/A
A6: TAHY | B6: Worldmark | C6: =Retail!H35 -> 63851.172 | D6: =SUMIFS(C36:AM36,$C$33:$AM$33,"="&$A$53) -> 0 | F6: =E6/D6-1 -> #DIV/0! | G6: =E6/C6 -> 0 | H6: =Attraction!B35 -> 100564.04 | J6: =I6/H6 -> 0 | K6: =C6+H6 -> 164415.21 | L6: =E6+I6 -> 0 | M6: =L6/K6 -> 0 | N6: =VLOOKUP(T1,'LFL 2024'!A2:F33,5,0) -> #N/A | O6: =E6 -> 0 | P6: =O6/N6-1 -> #N/A
A7: THH3 | B7: Delhi Selectcity | C7: =Retail!K35 -> 392222.7 | D7: =SUMIFS(C37:AM37,$C$33:$AM$33,"="&$A$53) -> 0 | F7: =E7/D7-1 -> #DIV/0! | G7: =E7/C7 -> 0 | K7: =C7+H7 -> 392222.7 | L7: =E7+I7 -> 0 | M7: =L7/K7 -> 0 | N7: =VLOOKUP(T1,'LFL 2024'!A2:G33,6,0) -> #N/A | O7: =E7 -> 0 | P7: =O7/N7-1 -> #N/A
A8: TLX5 | B8: Vegas Dwarka | C8: =Retail!L35 -> 176136.03 | D8: =SUMIFS(C38:AM38,$C$33:$AM$33,"="&$A$53) -> 0 | F8: =E8/D8-1 -> #DIV/0! | G8: =E8/C8 -> 0 | H8: =Attraction!D35 -> 11996.078 | J8: =I8/H8 -> 0 | K8: =C8+H8 -> 188132.11 | L8: =E8+I8 -> 0 | M8: =L8/K8 -> 0 | N8: =VLOOKUP(T1,'LFL 2024'!A2:H33,7,0) -> #N/A | O8: =E8 -> 0 | P8: =O8/N8-1 -> #N/A
A9: THF9 | B9: Amb Gurg Delhi | C9: =Retail!B35 -> 480133.83 | D9: =SUMIFS(C39:AM39,$C$33:$AM$33,"="&$A$53) -> 0 | F9: =E9/D9-1 -> #DIV/0! | G9: =E9/C9 -> 0 | K9: =C9+H9 -> 480133.83 | L9: =E9+I9 -> 0 | M9: =L9/K9 -> 0 | N9: =VLOOKUP(T1,'LFL 2024'!A2:I33,8,0) -> #N/A | O9: =E9 -> 0 | P9: =O9/N9-1 -> #N/A
A10: THI7 | B10: WTP Jaipur | C10: =Retail!F35 -> 190041.27 | D10: =SUMIFS(C40:AM40,$C$33:$AM$33,"="&$A$53) -> 0 | F10: =E10/D10-1 -> #DIV/0! | G10: =E10/C10 -> 0 | K10: =C10+H10 -> 190041.27 | L10: =E10+I10 -> 0 | M10: =L10/K10 -> 0 | N10: =VLOOKUP(T1,'LFL 2024'!A2:J33,9,0) -> #N/A | O10: =E10 -> 0 | P10: =O10/N10-1 -> #N/A
A11: THM0 | B11: Ardee Mall, Gurgaon | C11: =Retail!C35 -> 174186.13 | D11: =SUMIFS(C41:AM41,$C$33:$AM$33,"="&$A$53) -> 0 | F11: =E11/D11-1 -> #DIV/0! | G11: =E11/C11 -> 0 | K11: =C11+H11 -> 174186.13 | L11: =E11+I11 -> 0 | M11: =L11/K11 -> 0 | N11: =VLOOKUP(T1,'LFL 2024'!A2:K33,10,0) -> #N/A | O11: =E11 -> 0 | P11: =O11/N11-1 -> #N/A
A12: TJY4 | B12: Airia Mall Gurg | C12: =Retail!D35 -> 108239.76 | D12: =SUMIFS(C42:AM42,$C$33:$AM$33,"="&$A$53) -> 0 | F12: =E12/D12-1 -> #DIV/0! | G12: =E12/C12 -> 0 | K12: =C12+H12 -> 108239.76 | L12: =E12+I12 -> 0 | M12: =L12/K12 -> 0 | N12: =VLOOKUP(T1,'LFL 2024'!A2:L33,11,0) -> #N/A | O12: =E12 -> 0 | P12: =O12/N12-1 -> #N/A
A13: TXUT | B13: Vaishali | C13: =Retail!G35 -> 93298.933 | D13: =SUMIFS(C43:AM43,$C$33:$AM$33,"="&$A$53) -> 0 | F13: =E13/D13-1 -> #DIV/0! | G13: =E13/C13 -> 0 | K13: =C13+H13 -> 93298.933 | L13: =E13+I13 -> 0 | M13: =L13/K13 -> 0 | N13: =VLOOKUP(T1,'LFL 2024'!A2:M33,12,0) -> #N/A | O13: =E13 -> 0 | P13: =O13/N13-1 -> #N/A
A14: TXYT | B14: Good Earth | C14: =Retail!E35 -> 0 | D14: =SUMIFS(C44:AM44,$C$33:$AM$33,"="&$A$53) -> 0 | F14: =E14/D14-1 -> #DIV/0! | G14: =E14/C14 -> #DIV/0! | K14: =C14+H14 -> 0 | L14: =E14+I14 -> 0 | M14: =L14/K14 -> #DIV/0! | N14: =VLOOKUP(T1,'LFL 2024'!A2:N33,13,0) -> #N/A | O14: =E14 -> 0 | P14: =O14/N14-1 -> #N/A
A15: TAUN | B15: Udaipur | C15: =Retail!I35 -> 75609.562 | D15: =SUMIFS(C45:AM45,$C$33:$AM$33,"="&$A$53) -> 0 | F15: =E15/D15-1 -> #DIV/0! | G15: =E15/C15 -> 0 | H15: =Attraction!C35 -> 4391.1341 | J15: =I15/H15 -> 0 | K15: =C15+H15 -> 80000.696 | L15: =E15+I15 -> 0 | M15: =L15/K15 -> 0 | N15: =VLOOKUP(T1,'LFL 2024'!A2:O33,14,0) -> #N/A | O15: =E15 -> 0 | P15: =O15/N15-1 -> #N/A
A16: THE1 | B16: Elante Chandigarh | C16: =Retail!N35 -> 478539.4 | D16: =SUMIFS(C46:AM46,$C$33:$AM$33,"="&$A$53) -> 0 | F16: =E16/D16-1 -> #DIV/0! | G16: =E16/C16 -> 0 | H16: =Attraction!F35 -> 86995.04 | J16: =I16/H16 -> 0 | K16: =C16+H16 -> 565534.44 | L16: =E16+I16 -> 0 | M16: =L16/K16 -> 0 | N16: =VLOOKUP(T1,'LFL 2024'!A2:P33,15,0) -> #N/A | O16: =E16 -> 0 | P16: =O16/N16-1 -> #N/A
A17: TF5T | B17: Pacific D21 | C17: =Retail!O35 -> 0 | D17: =SUMIFS(C47:AM47,$C$33:$AM$33,"="&$A$53) -> 0 | F17: =E17/D17-1 -> #DIV/0! | G17: =E17/C17 -> #DIV/0! | K17: =C17+H17 -> 0 | L17: =E17+I17 -> 0 | M17: =L17/K17 -> #DIV/0! | N17: =VLOOKUP(T1,'LFL 2024'!A2:Q33,16,0) -> #N/A | O17: =E17 -> 0 | P17: =O17/N17-1 -> #N/A
A18: TXPH | B18: NH-1 Ambala store | C18: =Retail!P35 -> 52418.276 | D18: =SUMIFS(C48:AM48,$C$33:$AM$33,"="&$A$53) -> 0 | F18: =E18/D18-1 -> #DIV/0! | G18: =E18/C18 -> 0 | K18: =C18+H18 -> 52418.276 | L18: =E18+I18 -> 0 | M18: =L18/K18 -> 0 | N18: =VLOOKUP(T1,'LFL 2024'!A2:R33,17,0) -> #N/A | O18: =E18 -> 0 | P18: =O18/N18-1 -> #N/A
A19: TXR2 | B19: Zirakpur | C19: =Retail!Q35 -> 50054.432 | D19: =SUMIFS(C49:AM49,$C$33:$AM$33,"="&$A$53) -> 0 | F19: =E19/D19-1 -> #DIV/0! | G19: =E19/C19 -> 0 | K19: =C19+H19 -> 50054.432 | L19: =E19+I19 -> 0 | M19: =L19/K19 -> 0 | N19: =VLOOKUP(T1,'LFL 2024'!A2:S33,18,0) -> #N/A | O19: =E19 -> 0 | P19: =O19/N19-1 -> #N/A
A20: T2DD | B20: CP-67 | C20: =Retail!R35 -> 173176.09 | D20: =SUMIFS(C50:AM50,$C$33:$AM$33,"="&$A$53) -> 0 | F20: =E20/D20-1 -> #DIV/0! | G20: =E20/C20 -> 0 | H20: =Attraction!H35 -> 37671.355 | J20: =I20/H20 -> 0 | K20: =C20+H20 -> 210847.45 | L20: =E20+I20 -> 0 | M20: =L20/K20 -> 0 | N20: =VLOOKUP(T1,'LFL 2024'!A2:T33,19,0) -> #N/A | O20: =E20 -> 0 | P20: =O20/N20-1 -> #N/A
A21: TL60 | B21: Iris | C21: =Retail!S35 -> 69239.832 | D21: =SUMIFS(C51:AM51,$C$33:$AM$33,"="&$A$53) -> 0 | F21: =E21/D21-1 -> #DIV/0! | G21: =E21/C21 -> 0 | K21: =C21+H21 -> 69239.832 | L21: =E21+I21 -> 0 | M21: =L21/K21 -> 0 | N21: =VLOOKUP(T1,'LFL 2024'!A2:U33,20,0) -> #N/A | O21: =E21 -> 0 | P21: =O21/N21-1 -> #N/A
A22: TB6V | B22: Elegante | C22: =Retail!T35 -> 118798.39 | D22: =SUMIFS(C52:AM52,$C$33:$AM$33,"="&$A$53) -> 0 | F22: =E22/D22-1 -> #DIV/0! | G22: =E22/C22 -> 0 | K22: =C22+H22 -> 118798.39 | L22: =E22+I22 -> 0 | M22: =L22/K22 -> 0 | N22: =VLOOKUP(T1,'LFL 2024'!A2:V33,21,0) -> #N/A | O22: =E22 -> 0 | P22: =O22/N22-1 -> #N/A
C23: =SUM(C4:C22) -> 3503674.6 | D23: =SUM(D4:D22) -> 0 | E23: =SUM(E4:E22) -> 0 | F23: =E23/D23-1 -> #DIV/0! | G23: =E23/C23 -> 0 | H23: =SUM(H4:H22) -> 273790.24 | I23: =SUM(I4:I22) -> 0 | J23: =I23/H23 -> 0 | K23: =SUM(K4:K22) -> 3777464.8 | L23: =SUM(L4:L22) -> 0 | M23: =L23/K23 -> 0 | N23: =SUM(N4:N22) -> #N/A | O23: =SUM(O4:O22) -> 0 | P23: =O23/N23-1 -> #N/A | Q23: =SUM(Q4:Q22) -> 0 | R23: =SUM(R4:R22) -> 0
C25: Target | D25: Last Week | E25: This Week | F25: WOW | G25: Ach% | H25: Target | I25: This Week | J25: Ach % | K25: Target | L25: This Week | M25: Ach % | N25: NOB | O25: Loyalty | P25: Attach% | Q25: 10K Bills | R25: Trolley
B26: Ajay | C26: =+C4+C20 -> 694170.38 | D26: =+D4+D20 -> 0 | E26: =+E4+E20 -> 0 | F26: =E26/D26-1 -> #DIV/0! | G26: =+E26/C26 -> 0 | H26: =+H4+H20 -> 51324.885 | I26: =+I4+I20 -> 0 | J26: =I26/H26 -> 0 | K26: =+K4+K20 -> 745495.26 | L26: =+L4+L20 -> 0 | M26: =L26/K26 -> 0 | N26: =+N4+N20 -> #N/A | O26: =+O4+O20 -> 0 | P26: =O26/N26 -> #N/A | Q26: =+Q4+Q20 -> 0 | R26: =+R4+R20 -> 0
B27: Shashank | C27: =C10+C13+C15 -> 358949.77 | D27: =+D10+D13+D15 -> 0 | E27: =+E10+E13+E15 -> 0 | F27: =E27/D27-1 -> #DIV/0! | G27: =+E27/C27 -> 0 | H27: =+H10+H13+H15 -> 4391.1341 | I27: =I10+I13+I15 -> 0 | J27: =I27/H27 -> 0 | K27: =K10+K13+K15 -> 363340.9 | L27: =L10+L13+L15 -> 0 | M27: =L27/K27 -> 0 | N27: =+N10+N13+N15 -> #N/A | O27: =+O10+O13+O15 -> 0 | P27: =O27/N27 -> #N/A | Q27: =+Q10+Q13+Q15 -> 0 | R27: =+R10+R13+R15 -> 0
B28: Param | C28: =+C11+C9+C12+C6+C14+C21 -> 895650.72 | D28: =+D11+D9+D12+D6+D14+D21 -> 0 | E28: =+E11+E9+E12+E6+E14+E21 -> 0 | F28: =E28/D28-1 -> #DIV/0! | G28: =+E28/C28 -> 0 | H28: =H11+H9+H12+H6+H14+H21 -> 100564.04 | I28: =I11+I9+I12+I6+I14+I21 -> 0 | J28: =I28/H28 -> 0 | K28: =K11+K9+K12+K6+K14+K21 -> 996214.76 | L28: =L11+L9+L12+L6+L14+L21 -> 0 | M28: =L28/K28 -> 0 | N28: =+N11+N9+N12+N6+N14+N21 -> #N/A | O28: =+O11+O9+O12+O6+O14+O21 -> 0 | P28: =O28/N28 -> #N/A | Q28: =+Q11+Q9+Q12+Q6+Q14+Q21 -> 0 | R28: =+R11+R9+R12+R6+R14+R21 -> 0
B29: Harsh | C29: =+C5+C7+C8+C19+C18+C17+C16+C22 -> 1554903.7 | D29: =+D5+D7+D8+D19+D18+D17+D16+D22 -> 0 | E29: =+E5+E7+E8+E19+E18+E17+E16+E22 -> 0 | F29: =E29/D29-1 -> #DIV/0! | G29: =+E29/C29 -> 0 | H29: =+H5+H7+H8+H19+H18+H17+H16+H22 -> 117510.18 | I29: =+I5+I7+I8+I19+I18+I17+I16+I22 -> 0 | J29: =I29/H29 -> 0 | K29: =+K5+K7+K8+K19+K18+K17+K16+K22 -> 1672413.9 | L29: =+L5+L7+L8+L19+L18+L17+L16+L22 -> 0 | M29: =L29/K29 -> 0 | N29: =+N5+N7+N8+N19+N18+N17+N16+N22 -> #N/A | O29: =+O5+O7+O8+O19+O18+O17+O16+O22 -> 0 | P29: =O29/N29 -> #N/A | Q29: =+Q5+Q7+Q8+Q19+Q18+Q17+Q16+Q22 -> 0 | R29: =+R5+R7+R8+R19+R18+R17+R16+R22 -> 0
C30: =SUM(C26:C29) -> 3503674.6 | D30: =SUM(D26:D29) -> 0 | E30: =SUM(E26:E29) -> 0 | F30: =E30/D30-1 -> #DIV/0! | G30: =+E30/C30 -> 0 | H30: =SUM(H26:H29) -> 273790.24 | I30: =SUM(I26:I29) -> 0 | J30: =I30/H30 -> 0 | K30: =SUM(K26:K29) -> 3777464.8 | L30: =SUM(L26:L29) -> 0 | M30: =L30/K30 -> 0 | N30: =SUM(N26:N29) -> #N/A | O30: =SUM(O26:O29) -> 0 | P30: =O30/N30 -> #N/A | Q30: =SUM(Q26:Q29) -> 0 | R30: =SUM(R26:R29) -> 0
A33: Store Code | B33: Store Name | C33: 45985 | D33: =C33+1 -> 45986 | E33: =D33+1 -> 45987 | F33: =E33+1 -> 45988 | G33: =F33+1 -> 45989 | H33: =G33+1 -> 45990 | I33: =H33+1 -> 45991 | J33: =I33+1 -> 45992 | K33: =J33+1 -> 45993 | ... AP33: =AO33+1 -> 46024
A34: THE8 | B34: AVK Delhi
A35: THH2 | B35: Delhi Pacific
A36: TAHY | B36: Worldmark
A37: THH3 | B37: Delhi Selectcity
A38: TLX5 | B38: Vegas Dwarka
A39: THF9 | B39: Amb Gurg Delhi
A40: THI7 | B40: WTP Jaipur
A41: THM0 | B41: Ardee Mall, Gurgaon
A42: TJY4 | B42: Airia Mall Gurg
A43: TXUT | B43: Vaishali
...

Sheet Retail
B1: AGU Delhi | C1: ARDEE | D1: AIRIA | E1: Good Earth | F1: JAIPUR | G1: Vaishali | H1: WMG | I1: Udaipur | J1: Pacifc | K1: SELECT | L1: VEGAS | M1: AVK | N1: ELANTE | O1: D21 | P1: AMBALA | Q1: Zirakpur | R1: CP-67 | S1: Iris | T1: Faridabd | U1: Elegante | V1: Dlf Summit Plaza | W1: Jodhpur
