Workbook

Sheet FINAL
B1: 46266
A2: Hours | B2: Store Name | C2: ROM | D2: SD | E2: Date | F2: Day | G2: Time Slot | H2: Staff Present | I2: NOB/Hour | J2: NOB Tgt | K2: NOB Ach | L2: FF | M2: Conv
A3: 11 | B3: Hamleys Vegas | C3: Ajay Gill | D3: Harsh | E3: 46266 | F3: Wed | G3: 11 to 12 | H3: 3 | I3: 1.5 | J3: 4.5 | K3: 0 | L3: 4 | M3: 0
A4: 12 | B4: Hamleys Vegas | C4: Ajay Gill | D4: Harsh | E4: 46266 | F4: Wed | G4: 12 to 1 | H4: 3 | I4: 1.5 | J4: 4.5 | K4: 1 | L4: 8 | M4: 0.125
A5: 13 | B5: Hamleys Vegas | C5: Ajay Gill | D5: Harsh | E5: 46266 | F5: Wed | G5: 1 to 2 | H5: 7 | I5: 1.5 | J5: 10.5 | K5: 3 | L5: 17 | M5: 0.17647059
A6: 14 | B6: Hamleys Vegas | C6: Ajay Gill | D6: Harsh | E6: 46266 | F6: Wed | G6: 2 to 3 | H6: 7 | I6: 1.5 | J6: 10.5 | K6: 1 | L6: 14 | M6: 0.071428571
A7: 15 | B7: Hamleys Vegas | C7: Ajay Gill | D7: Harsh | E7: 46266 | F7: Wed | G7: 3 to 4 | H7: 7 | I7: 1.5 | J7: 10.5 | K7: 1 | L7: 12 | M7: 0.083333333
A8: 16 | B8: Hamleys Vegas | C8: Ajay Gill | D8: Harsh | E8: 46266 | F8: Wed | G8: 4 to 5 | H8: 7 | I8: 1.5 | J8: 10.5 | K8: 4 | L8: 24 | M8: 0.16666667
A9: 17 | B9: Hamleys Vegas | C9: Ajay Gill | D9: Harsh | E9: 46266 | F9: Wed | G9: 5 to 6 | H9: 7 | I9: 1.5 | J9: 10.5 | K9: 6 | L9: 33 | M9: 0.18181818
A10: 18 | B10: Hamleys Vegas | C10: Ajay Gill | D10: Harsh | E10: 46266 | F10: Wed | G10: 6 to 7 | H10: 7 | I10: 1.5 | J10: 10.5 | K10: 4 | L10: 19 | M10: 0.21052632
A11: 19 | B11: Hamleys Vegas | C11: Ajay Gill | D11: Harsh | E11: 46266 | F11: Wed | G11: 7 to 8 | H11: 4 | I11: 1.5 | J11: 6 | K11: 4 | L11: 28 | M11: 0.14285714
A12: 20 | B12: Hamleys Vegas | C12: Ajay Gill | D12: Harsh | E12: 46266 | F12: Wed | G12: 8 to 9 | H12: 4 | I12: 1.5 | J12: 6 | K12: 2 | L12: 17 | M12: 0.11764706
A13: 21 | B13: Hamleys Vegas | C13: Ajay Gill | D13: Harsh | E13: 46266 | F13: Wed | G13: 9 to 10 | H13: 4 | I13: 1.5 | J13: 6 | K13: 1 | L13: 10 | M13: 0.1
B16: 46267
A17: Hours | B17: Store Name | C17: ROM | D17: SD | E17: Date | F17: Day | G17: Time Slot | H17: Staff Present | I17: NOB/Hour | J17: NOB Tgt | K17: NOB Ach | L17: FF | M17: Conv
A18: 11 | B18: Hamleys Vegas | C18: Ajay Gill | D18: Harsh | E18: 46267 | F18: Wed | G18: 11 to 12 | H18: 3 | I18: 1.5 | J18: 4.5 | K18: 1 | L18: 7 | M18: 0.14285714
A19: 12 | B19: Hamleys Vegas | C19: Ajay Gill | D19: Harsh | E19: 46267 | F19: Wed | G19: 12 to 1 | H19: 3 | I19: 1.5 | J19: 4.5 | K19: 1 | L19: 6 | M19: 0.16666667
A20: 13 | B20: Hamleys Vegas | C20: Ajay Gill | D20: Harsh | E20: 46267 | F20: Wed | G20: 1 to 2 | H20: 7 | I20: 1.5 | J20: 10.5 | K20: 2 | L20: 11 | M20: 0.18181818
A21: 14 | B21: Hamleys Vegas | C21: Ajay Gill | D21: Harsh | E21: 46267 | F21: Wed | G21: 2 to 3 | H21: 7 | I21: 1.5 | J21: 10.5 | K21: 4 | L21: 19 | M21: 0.21052632
A22: 15 | B22: Hamleys Vegas | C22: Ajay Gill | D22: Harsh | E22: 46267 | F22: Wed | G22: 3 to 4 | H22: 7 | I22: 1.5 | J22: 10.5 | K22: 3 | L22: 24 | M22: 0.125
A23: 16 | B23: Hamleys Vegas | C23: Ajay Gill | D23: Harsh | E23: 46267 | F23: Wed | G23: 4 to 5 | H23: 7 | I23: 1.5 | J23: 10.5 | K23: 2 | L23: 21 | M23: 0.095238095
A24: 17 | B24: Hamleys Vegas | C24: Ajay Gill | D24: Harsh | E24: 46267 | F24: Wed | G24: 5 to 6 | H24: 7 | I24: 1.5 | J24: 10.5 | K24: 2 | L24: 16 | M24: 0.125
A25: 18 | B25: Hamleys Vegas | C25: Ajay Gill | D25: Harsh | E25: 46267 | F25: Wed | G25: 6 to 7 | H25: 7 | I25: 1.5 | J25: 10.5 | K25: 3 | L25: 27 | M25: 0.11111111
A26: 19 | B26: Hamleys Vegas | C26: Ajay Gill | D26: Harsh | E26: 46267 | F26: Wed | G26: 7 to 8 | H26: 4 | I26: 1.5 | J26: 6 | K26: 3 | L26: 17 | M26: 0.17647059
A27: 20 | B27: Hamleys Vegas | C27: Ajay Gill | D27: Harsh | E27: 46267 | F27: Wed | G27: 8 to 9 | H27: 4 | I27: 1.5 | J27: 6 | K27: 4 | L27: 25 | M27: 0.16
A28: 21 | B28: Hamleys Vegas | C28: Ajay Gill | D28: Harsh | E28: 46267 | F28: Wed | G28: 9 to 10 | H28: 4 | I28: 1.5 | J28: 6 | K28: 4 | L28: 33 | M28: 0.12121212
B31: 46268
A32: Hours | B32: Store Name | C32: ROM | D32: SD | E32: Date | F32: Day | G32: Time Slot | H32: Staff Present | I32: NOB/Hour | J32: NOB Tgt | K32: NOB Ach | L32: FF | M32: Conv
A33: 11 | B33: Hamleys Vegas | C33: Ajay Gill | D33: Harsh | E33: 46268 | F33: Wed | G33: 11 to 12 | H33: 3 | I33: 1.5 | J33: 4.5 | K33: 0 | L33: 2 | M33: 0
A34: 12 | B34: Hamleys Vegas | C34: Ajay Gill | D34: Harsh | E34: 46268 | F34: Wed | G34: 12 to 1 | H34: 3 | I34: 1.5 | J34: 4.5 | K34: 2 | L34: 12 | M34: 0.16666667
A35: 13 | B35: Hamleys Vegas | C35: Ajay Gill | D35: Harsh | E35: 46268 | F35: Wed | G35: 1 to 2 | H35: 7 | I35: 1.5 | J35: 10.5 | K35: 1 | L35: 10 | M35: 0.1
A36: 14 | B36: Hamleys Vegas | C36: Ajay Gill | D36: Harsh | E36: 46268 | F36: Wed | G36: 2 to 3 | H36: 7 | I36: 1.5 | J36: 10.5 | K36: 3 | L36: 25 | M36: 0.12
A37: 15 | B37: Hamleys Vegas | C37: Ajay Gill | D37: Harsh | E37: 46268 | F37: Wed | G37: 3 to 4 | H37: 7 | I37: 1.5 | J37: 10.5 | K37: 3 | L37: 31 | M37: 0.096774194
A38: 16 | B38: Hamleys Vegas | C38: Ajay Gill | D38: Harsh | E38: 46268 | F38: Wed | G38: 4 to 5 | H38: 7 | I38: 1.5 | J38: 10.5 | K38: 1 | L38: 16 | M38: 0.0625
A39: 17 | B39: Hamleys Vegas | C39: Ajay Gill | D39: Harsh | E39: 46268 | F39: Wed | G39: 5 to 6 | H39: 7 | I39: 1.5 | J39: 10.5 | K39: 5 | L39: 22 | M39: 0.22727273
A40: 18 | B40: Hamleys Vegas | C40: Ajay Gill | D40: Harsh | E40: 46268 | F40: Wed | G40: 6 to 7 | H40: 7 | I40: 1.5 | J40: 10.5 | K40: 7 | L40: 30 | M40: 0.23333333
A41: 19 | B41: Hamleys Vegas | C41: Ajay Gill | D41: Harsh | E41: 46268 | F41: Wed | G41: 7 to 8 | H41: 4 | I41: 1.5 | J41: 6 | K41: 6 | L41: 33 | M41: 0.18181818
A42: 20 | B42: Hamleys Vegas | C42: Ajay Gill | D42: Harsh | E42: 46268 | F42: Wed | G42: 8 to 9 | H42: 4 | I42: 1.5 | J42: 6 | K42: 8 | L42: 41 | M42: 0.19512195
A43: 21 | B43: Hamleys Vegas | C43: Ajay Gill | D43: Harsh | E43: 46268 | F43: Wed | G43: 9 to 10 | H43: 4 | I43: 1.5 | J43: 6 | K43: 1 | L43: 9 | M43: 0.11111111
B46: 46269
...

Sheet Master
B2: =TODAY() -> 46291
A3: Hours | B3: Store Name | C3: ROM | D3: SD | E3: Date | F3: Day | G3: Time Slot | H3: Staff Present | I3: NOB/Hour | J3: NOB Tgt | K3: NOB Ach | L3: FF | M3: Conv
A4: 11 | B4: Hamleys Vegas | C4: Ajay Gill | D4: Harsh | E4: =$B$2 -> 46291 | F4: TUE | G4: 11 to 12 | H4: 3 | I4: 1.5 | J4: =I4*H4 -> 4.5 | K4: =IFERROR(VLOOKUP(A4,PIVOT!A:B,2,0),0) -> 2 | L4: 16 | M4: =K4/L4 -> 0.125
A5: 12 | B5: Hamleys Vegas | C5: Ajay Gill | D5: Harsh | E5: =$B$2 -> 46291 | F5: TUE | G5: 12 to 1 | H5: 3 | I5: 1.5 | J5: =I5*H5 -> 4.5 | K5: =IFERROR(VLOOKUP(A5,PIVOT!A:B,2,0),0) -> 4 | L5: 27 | M5: =K5/L5 -> 0.14814815
A6: 13 | B6: Hamleys Vegas | C6: Ajay Gill | D6: Harsh | E6: =$B$2 -> 46291 | F6: TUE | G6: 1 to 2 | H6: 7 | I6: 1.5 | J6: =I6*H6 -> 10.5 | K6: =IFERROR(VLOOKUP(A6,PIVOT!A:B,2,0),0) -> 7 | L6: 41 | M6: =K6/L6 -> 0.17073171
A7: 14 | B7: Hamleys Vegas | C7: Ajay Gill | D7: Harsh | E7: =$B$2 -> 46291 | F7: TUE | G7: 2 to 3 | H7: 7 | I7: 1.5 | J7: =I7*H7 -> 10.5 | K7: =IFERROR(VLOOKUP(A7,PIVOT!A:B,2,0),0) -> 8 | L7: 55 | M7: =K7/L7 -> 0.14545455
A8: 15 | B8: Hamleys Vegas | C8: Ajay Gill | D8: Harsh | E8: =$B$2 -> 46291 | F8: TUE | G8: 3 to 4 | H8: 7 | I8: 1.5 | J8: =I8*H8 -> 10.5 | K8: =IFERROR(VLOOKUP(A8,PIVOT!A:B,2,0),0) -> 10 | L8: 71 | M8: =K8/L8 -> 0.14084507
A9: 16 | B9: Hamleys Vegas | C9: Ajay Gill | D9: Harsh | E9: =$B$2 -> 46291 | F9: TUE | G9: 4 to 5 | H9: 7 | I9: 1.5 | J9: =I9*H9 -> 10.5 | K9: =IFERROR(VLOOKUP(A9,PIVOT!A:B,2,0),0) -> 12 | L9: 62 | M9: =K9/L9 -> 0.19354839
A10: 17 | B10: Hamleys Vegas | C10: Ajay Gill | D10: Harsh | E10: =$B$2 -> 46291 | F10: TUE | G10: 5 to 6 | H10: 7 | I10: 1.5 | J10: =I10*H10 -> 10.5 | K10: =IFERROR(VLOOKUP(A10,PIVOT!A:B,2,0),0) -> 16 | L10: 76 | M10: =K10/L10 -> 0.21052632
A11: 18 | B11: Hamleys Vegas | C11: Ajay Gill | D11: Harsh | E11: =$B$2 -> 46291 | F11: TUE | G11: 6 to 7 | H11: 7 | I11: 1.5 | J11: =I11*H11 -> 10.5 | K11: =IFERROR(VLOOKUP(A11,PIVOT!A:B,2,0),0) -> 11 | L11: 52 | M11: =K11/L11 -> 0.21153846
A12: 19 | B12: Hamleys Vegas | C12: Ajay Gill | D12: Harsh | E12: =$B$2 -> 46291 | F12: TUE | G12: 7 to 8 | H12: 4 | I12: 1.5 | J12: =I12*H12 -> 6 | K12: =IFERROR(VLOOKUP(A12,PIVOT!A:B,2,0),0) -> 0 | M12: =K12/L12 -> #DIV/0!
A13: 20 | B13: Hamleys Vegas | C13: Ajay Gill | D13: Harsh | E13: =$B$2 -> 46291 | F13: TUE | G13: 8 to 9 | H13: 4 | I13: 1.5 | J13: =I13*H13 -> 6 | K13: =IFERROR(VLOOKUP(A13,PIVOT!A:B,2,0),0) -> 0 | M13: =K13/L13 -> #DIV/0!
A14: 21 | B14: Hamleys Vegas | C14: Ajay Gill | D14: Harsh | E14: =$B$2 -> 46291 | F14: TUE | G14: 9 to 10 | H14: 4 | I14: 1.5 | J14: =I14*H14 -> 6 | K14: =IFERROR(VLOOKUP(A14,PIVOT!A:B,2,0),0) -> 0 | M14: =K14/L14 -> #DIV/0!
H415: call is busy

Sheet PIVOT
A3: Row Labels | B3: Sum of Bills
A4: 0 | B4: 1
A5: 11 | B5: 2
A6: 12 | B6: 4
A7: 13 | B7: 7
A8: 16 | B8: 12
A9: 17 | B9: 16
A10: 18 | B10: 11
A11: 14 | B11: 8
A12: 15 | B12: 10
A13: Grand Total | B13: 71

Sheet sale.
A1: TXNID | B1: STORENO | C1: TRANSACTIONTYPE | D1: RECEIPTNO | E1: TRANSDATE | F1: ARTICLESINRECEIPT | G1: BARCODE | H1: QTY | I1: RECEIPTPRICE | J1: PROMOTION | K1: DISCOUNT | L1: TOTALDISCOUNT | M1: NET | N1: TAX | O1: Tax% | P1: ARTICLEDESC | Q1: CASHIER | R1: STATUS | S1: SALESMANCODE | T1: Order_Type | U1: PRODUCT_TYPE | V1: 0 | W1: Hour | X1: Bills
A2: 1 | B2: TLX5 | C2: SALE | D2: TLX5102000126092026 | E2: 46291.467 | F2: 3 | G2: 8904391805119 | H2: 1 | I2: 699 | J2: 0 | K2: 0 | L2: 0 | M2: 699 | N2: 33.28 | O2: 5 | P2: NE MIR 24CM STANDING | Q2: 50170981 | R2: COMPLETED | S2: 50188930 | U2: GnG | V2: 0 | W2: =HOUR(E2) -> 11 | X2: =IF(D2=D1,0,1) -> 1
A3: 1 | B3: TLX5 | C3: SALE | D3: TLX5104000126092026 | E3: 46291.481 | F3: 3 | G3: 8904391805201 | H3: 1 | I3: 999 | J3: 0 | K3: 0 | L3: 0 | M3: 999 | N3: 47.58 | O3: 5 | P3: NE CB 35CM TENDERHEA | Q3: 50157523 | R3: COMPLETED | S3: 50188930 | U3: GnG | V3: 0 | W3: =HOUR(E3) -> 11 | X3: =IF(D3=D2,0,1) -> 1
A4: 5 | B4: TLX5 | C4: SALE | D4: TLX5102000526092026 | E4: 46291.512 | F4: 3 | G4: 194735220809 | H4: 1 | I4: 279 | J4: -69.85 | K4: 0 | L4: -69.85 | M4: 209.15 | N4: 9.96 | O4: 5 | P4: NE UNO SHOW EM NO ME | Q4: 50170981 | R4: COMPLETED | S4: 50188930 | U4: GnG | V4: 0 | W4: =HOUR(E4) -> 12 | X4: =IF(D4=D3,0,1) -> 1
A5: 5 | B5: TLX5 | C5: SALE | D5: TLX5102000526092026 | E5: 46291.512 | F5: 3 | G5: 8909409261154 | H5: 1 | I5: 799 | J5: -200.05 | K5: 0 | L5: -200.05 | M5: 598.95 | N5: 28.52 | O5: 5 | P5: NE 300PC PUZZLECASTL | Q5: 50170981 | R5: COMPLETED | S5: 50188930 | U5: GnG | V5: 0 | W5: =HOUR(E5) -> 12 | X5: =IF(D5=D4,0,1) -> 0
A6: 5 | B6: TLX5 | C6: SALE | D6: TLX5102000526092026 | E6: 46291.512 | F6: 3 | G6: 630509888900 | H6: 1 | I6: 899 | J6: -225.09 | K6: 0 | L6: -225.09 | M6: 673.91 | N6: 32.1 | O6: 5 | P6: HASBRO GMNG MONOPOLY | Q6: 50170981 | R6: COMPLETED | S6: 50188930 | U6: GnG | V6: 0 | W6: =HOUR(E6) -> 12 | X6: =IF(D6=D5,0,1) -> 0
A7: 6 | B7: TLX5 | C7: SALE | D7: TLX5102000626092026 | E7: 46291.515 | F7: 3 | G7: 5010996295545 | H7: 1 | I7: 999 | J7: 0 | K7: 0 | L7: 0 | M7: 999 | N7: 47.58 | O7: 5 | P7: NE TRA GEN PROJECT S | Q7: 50170981 | R7: COMPLETED | S7: 50188930 | U7: GnG | V7: 0 | W7: =HOUR(E7) -> 12 | X7: =IF(D7=D6,0,1) -> 1
A8: 7 | B8: TLX5 | C8: SALE | D8: TLX5102000726092026 | E8: 46291.527 | F8: 3 | G8: 887961751062 | H8: 1 | I8: 185 | J8: 0 | K8: 0 | L8: 0 | M8: 185 | N8: 8.8 | O8: 5 | P8: NE UNO FLIP SIDE | Q8: 50170981 | R8: COMPLETED | S8: 50188930 | U8: GnG | V8: 0 | W8: =HOUR(E8) -> 12 | X8: =IF(D8=D7,0,1) -> 1
A9: 7 | B9: TLX5 | C9: SALE | D9: TLX5102000726092026 | E9: 46291.527 | F9: 3 | G9: 5010994106966 | H9: 1 | I9: 399 | J9: 0 | K9: 0 | L9: 0 | M9: 399 | N9: 19 | O9: 5 | P9: NE NER ELITE 2.0 ACE | Q9: 50170981 | R9: COMPLETED | S9: 50188930 | U9: GnG | V9: 0 | W9: =HOUR(E9) -> 12 | X9: =IF(D9=D8,0,1) -> 0
A10: 8 | B10: TLX5 | C10: SALE | D10: TLX5102000826092026 | E10: 46291.534 | F10: 3 | G10: 195166219387 | H10: 1 | I10: 460 | J10: 0 | K10: 0 | L10: 0 | M10: 460 | N10: 21.9 | O10: 5 | P10: NE NER ELITE 2 0 SLY | Q10: 50170981 | R10: COMPLETED | S10: 50188930 | U10: GnG | V10: 0 | W10: =HOUR(E10) -> 12 | X10: =IF(D10=D9,0,1) -> 1
A11: 9 | B11: TLX5 | C11: SALE | D11: TLX5102000926092026 | E11: 46291.545 | F11: 3 | G11: 8906169660944 | H11: 1 | I11: 1499 | J11: 0 | K11: 0 | L11: 0 | M11: 1499 | N11: 71.38 | O11: 5 | P11: NE BLM DIY UNICORN U | Q11: 50170981 | R11: COMPLETED | S11: 50188930 | U11: GnG | V11: 0 | W11: =HOUR(E11) -> 13 | X11: =IF(D11=D10,0,1) -> 1
A12: 10 | B12: TLX5 | C12: SALE | D12: TLX5102001026092026 | E12: 46291.55 | F12: 3 | G12: 3467452077290 | H12: 1 | I12: 699 | J12: -139.8 | K12: 0 | L12: -139.8 | M12: 559.2 | N12: 26.62 | O12: 5 | P12: NE MJTFARM TRAILER 4 | Q12: 50170981 | R12: COMPLETED | S12: 50000001 | U12: GnG | V12: 0 | W12: =HOUR(E12) -> 13 | X12: =IF(D12=D11,0,1) -> 1
A13: 10 | B13: TLX5 | C13: SALE | D13: TLX5102001026092026 | E13: 46291.55 | F13: 3 | G13: 74299018060 | H13: 1 | I13: 899 | J13: -179.8 | K13: 0 | L13: -179.8 | M13: 719.2 | N13: 34.24 | O13: 5 | P13: HW FIVECAR GIFT PACK | Q13: 50170981 | R13: COMPLETED | S13: 50000001 | U13: GnG | V13: 0 | W13: =HOUR(E13) -> 13 | X13: =IF(D13=D12,0,1) -> 0
A14: 11 | B14: TLX5 | C14: SALE | D14: TLX5102001126092026 | E14: 46291.554 | F14: 3 | G14: 27084120134 | H14: 1 | I14: 179 | J14: 0 | K14: 0 | L14: 0 | M14: 179 | N14: 8.52 | O14: 5 | P14: NE HW BASIC CAR ASST | Q14: 50170981 | R14: COMPLETED | U14: GnG | V14: 0 | W14: =HOUR(E14) -> 13 | X14: =IF(D14=D13,0,1) -> 1
A15: 11 | B15: TLX5 | C15: SALE | D15: TLX5102001126092026 | E15: 46291.554 | F15: 3 | G15: 3467452077368 | H15: 1 | I15: 399 | J15: 0 | K15: 0 | L15: 0 | M15: 399 | N15: 19 | O15: 5 | P15: NE MJT RACING PRM CA | Q15: 50170981 | R15: COMPLETED | S15: 50170981 | U15: GnG | V15: 0 | W15: =HOUR(E15) -> 13 | X15: =IF(D15=D14,0,1) -> 0
A16: 12 | B16: TLX5 | C16: SALE | D16: TLX5102001226092026 | E16: 46291.556 | F16: 3 | G16: 5702018063323 | H16: 1 | I16: 5499 | J16: 0 | K16: 0 | L16: 0 | M16: 5499 | N16: 261.86 | O16: 5 | P16: NE LEGO 76349 SPIDER | Q16: 50170981 | R16: COMPLETED | S16: 50188930 | U16: GnG | V16: 0 | W16: =HOUR(E16) -> 13 | X16: =IF(D16=D15,0,1) -> 1
A17: 13 | B17: TLX5 | C17: SALE | D17: TLX5102001326092026 | E17: 46291.563 | F17: 3 | G17: 194735277582 | H17: 1 | I17: 1099 | J17: 0 | K17: 0 | L17: 0 | M17: 1099 | N17: 52.34 | O17: 5 | P17: NE BARBIE POP STAR D | Q17: 50170981 | R17: COMPLETED | S17: 50195439 | U17: GnG | V17: 0 | W17: =HOUR(E17) -> 13 | X17: =IF(D17=D16,0,1) -> 1
A18: 13 | B18: TLX5 | C18: SALE | D18: TLX5102001326092026 | E18: 46291.563 | F18: 3 | G18: 194735363353 | H18: 1 | I18: 399 | J18: -88.59 | K18: 0 | L18: -88.59 | M18: 310.41 | N18: 14.78 | O18: 5 | P18: NE BRB ENTRY PNK DRE | Q18: 50170981 | R18: COMPLETED | S18: 50195439 | U18: GnG | V18: 0 | W18: =HOUR(E18) -> 13 | X18: =IF(D18=D17,0,1) -> 0
A19: 13 | B19: TLX5 | C19: SALE | D19: TLX5102001326092026 | E19: 46291.563 | F19: 3 | G19: 194735234561 | H19: 1 | I19: 599 | J19: -133 | K19: 0 | L19: -133 | M19: 466 | N19: 22.2 | O19: 5 | P19: NE BARBIE CHELSEA AS | Q19: 50170981 | R19: COMPLETED | U19: GnG | V19: 0 | W19: =HOUR(E19) -> 13 | X19: =IF(D19=D18,0,1) -> 0
A20: 13 | B20: TLX5 | C20: SALE | D20: TLX5102001326092026 | E20: 46291.563 | F20: 3 | G20: 194735339754 | H20: 1 | I20: 799 | J20: -177.41 | K20: 0 | L20: -177.41 | M20: 621.59 | N20: 29.6 | O20: 5 | P20: NE BRB FSHNSTA S1 | Q20: 50170981 | R20: COMPLETED | S20: 50195439 | U20: GnG | V20: 0 | W20: =HOUR(E20) -> 13 | X20: =IF(D20=D19,0,1) -> 0
A21: 14 | B21: TLX5 | C21: SALE | D21: TLX5102001426092026 | E21: 46291.582 | F21: 3 | G21: 8904279514409 | H21: 1 | I21: 1499 | J21: 0 | K21: 0 | L21: 0 | M21: 1499 | N21: 71.38 | O21: 5 | P21: NE CLASSIC MAGIC KIT | Q21: 50170981 | R21: COMPLETED | S21: 50195439 | U21: GnG | V21: 0 | W21: =HOUR(E21) -> 13 | X21: =IF(D21=D20,0,1) -> 1
A22: 15 | B22: TLX5 | C22: SALE | D22: TLX5102001526092026 | E22: 46291.583 | F22: 3 | G22: 194735284931 | H22: 1 | I22: 449 | J22: 0 | K22: 0 | L22: 0 | M22: 449 | N22: 21.38 | O22: 5 | P22: NE MT MBX SKYBUSTERS | Q22: 50170981 | R22: COMPLETED | S22: 50170981 | U22: GnG | V22: 0 | W22: =HOUR(E22) -> 13 | X22: =IF(D22=D21,0,1) -> 1
A23: 15 | B23: TLX5 | C23: SALE | D23: TLX5102001526092026 | E23: 46291.583 | F23: 3 | G23: 8906134711299 | H23: 1 | I23: 499 | J23: -299.4 | K23: 0 | L23: -299.4 | M23: 199.6 | N23: 9.5 | O23: 5 | P23: NE MIGHTY MACHINES B | Q23: 50170981 | R23: COMPLETED | S23: 50170981 | U23: GnG | V23: 0 | W23: =HOUR(E23) -> 13 | X23: =IF(D23=D22,0,1) -> 0
A24: 17 | B24: TLX5 | C24: SALE | D24: TLX5102001726092026 | E24: 46291.586 | F24: 3 | G24: 8905672078727 | H24: 1 | I24: 1099 | J24: 0 | K24: 0 | L24: 0 | M24: 1099 | N24: 52.34 | O24: 5 | P24: NE SL 53CM LYING UNI | Q24: 50170981 | R24: COMPLETED | U24: GnG | V24: 0 | W24: =HOUR(E24) -> 14 | X24: =IF(D24=D23,0,1) -> 1
A25: 17 | B25: TLX5 | C25: SALE | D25: TLX5102001726092026 | E25: 46291.586 | F25: 3 | G25: 8904432220918 | H25: 1 | I25: 599 | J25: 0 | K25: 0 | L25: 0 | M25: 599 | N25: 28.52 | O25: 5 | P25: NE BIG EYE GIRAFFE 2 | Q25: 50170981 | R25: COMPLETED | S25: 50188930 | U25: GnG | V25: 0 | W25: =HOUR(E25) -> 14 | X25: =IF(D25=D24,0,1) -> 0
A26: 3 | B26: TLX5 | C26: SALE | D26: TLX5104000326092026 | E26: 46291.59 | F26: 3 | G26: 8905450027411 | H26: 1 | I26: 1599 | J26: -799.5 | K26: 0 | L26: -799.5 | M26: 799.5 | N26: 38.08 | O26: 5 | P26: NE YK KNOWLEDGE JACK | Q26: 50157523 | R26: COMPLETED | S26: 50195907 | U26: GnG | V26: 0 | W26: =HOUR(E26) -> 14 | X26: =IF(D26=D25,0,1) -> 1
A27: 3 | B27: TLX5 | C27: SALE | D27: TLX5104000326092026 | E27: 46291.59 | F27: 3 | G27: 8905450027398 | H27: 1 | I27: 1799 | J27: -899.5 | K27: 0 | L27: -899.5 | M27: 899.5 | N27: 42.84 | O27: 5 | P27: NE YK EXPLORE SPACE | Q27: 50157523 | R27: COMPLETED | U27: GnG | V27: 0 | W27: =HOUR(E27) -> 14 | X27: =IF(D27=D26,0,1) -> 0
A28: 18 | B28: TLX5 | C28: SALE | D28: TLX5102001826092026 | E28: 46291.594 | F28: 3 | G28: 8905672075528 | H28: 1 | I28: 2499 | J28: 0 | K28: 0 | L28: 0 | M28: 2499 | N28: 119 | O28: 5 | P28: NE ROLEPLAYMILITARYS | Q28: 50170981 | R28: COMPLETED | U28: GnG | V28: 0 | W28: =HOUR(E28) -> 14 | X28: =IF(D28=D27,0,1) -> 1
A29: 19 | B29: TLX5 | C29: SALE | D29: TLX5102001926092026 | E29: 46291.599 | F29: 3 | G29: 194735284931 | H29: 1 | I29: 449 | J29: 0 | K29: 0 | L29: 0 | M29: 449 | N29: 21.38 | O29: 5 | P29: NE MT MBX SKYBUSTERS | Q29: 50170981 | R29: COMPLETED | S29: 50151682 | U29: GnG | V29: 0 | W29: =HOUR(E29) -> 14 | X29: =IF(D29=D28,0,1) -> 1
A30: 21 | B30: TLX5 | C30: SALE | D30: TLX5102002126092026 | E30: 46291.602 | F30: 3 | G30: 8905450074064 | H30: 1 | I30: 79 | J30: 0 | K30: 0 | L30: 0 | M30: 79 | N30: 3.76 | O30: 5 | P30: NE BUBBLE WAND | Q30: 50170981 | R30: COMPLETED | U30: GnG | V30: 0 | W30: =HOUR(E30) -> 14 | X30: =IF(D30=D29,0,1) -> 1
A31: 22 | B31: TLX5 | C31: SALE | D31: TLX5102002226092026 | E31: 46291.604 | F31: 3 | G31: 778988661222 | H31: 1 | I31: 1499 | J31: -299.8 | K31: 0 | L31: -299.8 | M31: 1199.2 | N31: 182.92 | O31: 18 | P31: E WINMAGIC WOBBLY WO | Q31: 50170981 | R31: COMPLETED | U31: GnG | V31: 0 | W31: =HOUR(E31) -> 14 | X31: =IF(D31=D30,0,1) -> 1
A32: 23 | B32: TLX5 | C32: SALE | D32: TLX5102002326092026 | E32: 46291.609 | F32: 3 | G32: 8904027127288 | H32: 1 | I32: 1499 | J32: 0 | K32: 0 | L32: 0 | M32: 1499 | N32: 228.66 | O32: 18 | P32: E KOP 27PCS KITCHEN | Q32: 50170981 | R32: COMPLETED | S32: 50188930 | U32: GnG | V32: 0 | W32: =HOUR(E32) -> 14 | X32: =IF(D32=D31,0,1) -> 1
A33: 4 | B33: TLX5 | C33: SALE | D33: TLX5104000426092026 | E33: 46291.611 | F33: 3 | G33: 4501517003455 | H33: 1 | I33: 499 | J33: 0 | K33: 0 | L33: 0 | M33: 499 | N33: 23.76 | O33: 5 | P33: NE PLAYSHIFU AQUATIC | Q33: 50157523 | R33: COMPLETED | S33: 50000003 | U33: GnG | V33: 0 | W33: =HOUR(E33) -> 14 | X33: =IF(D33=D32,0,1) -> 1
A34: 4 | B34: TLX5 | C34: SALE | D34: TLX5104000426092026 | E34: 46291.611 | F34: 3 | G34: 8908013692385 | H34: 1 | I34: 499 | J34: 0 | K34: 0 | L34: 0 | M34: 499 | N34: 23.76 | O34: 5 | P34: NE PLAYSHIFU SOLAR S | Q34: 50157523 | R34: COMPLETED | S34: 50000003 | U34: GnG | V34: 0 | W34: =HOUR(E34) -> 14 | X34: =IF(D34=D33,0,1) -> 0
A35: 4 | B35: TLX5 | C35: SALE | D35: TLX5104000426092026 | E35: 46291.611 | F35: 3 | G35: 8909409286041 | H35: 1 | I35: 799 | J35: 0 | K35: 0 | L35: 0 | M35: 799 | N35: 121.88 | O35: 18 | P35: E HOVER FOOTBALL GRE | Q35: 50157523 | R35: COMPLETED | S35: 50000003 | U35: GnG | V35: 0 | W35: =HOUR(E35) -> 14 | X35: =IF(D35=D34,0,1) -> 0
A36: 4 | B36: TLX5 | C36: SALE | D36: TLX5104000426092026 | E36: 46291.611 | F36: 3 | G36: 8906169660821 | H36: 1 | I36: 799 | J36: 0 | K36: 0 | L36: 0 | M36: 799 | N36: 38.04 | O36: 5 | P36: NE DABBLE ABC WITH A | Q36: 50157523 | R36: COMPLETED | S36: 50000003 | U36: GnG | V36: 0 | W36: =HOUR(E36) -> 14 | X36: =IF(D36=D35,0,1) -> 0
A37: 5 | B37: TLX5 | C37: SALE | D37: TLX5104000526092026 | E37: 46291.626 | F37: 3 | G37: 194735358878 | H37: 1 | I37: 299 | J37: 0 | K37: 0 | L37: 0 | M37: 299 | N37: 14.24 | O37: 5 | P37: NE HW AUTOMOTIVE ASS | Q37: 50157523 | R37: COMPLETED | S37: 50157523 | U37: GnG | V37: 0 | W37: =HOUR(E37) -> 15 | X37: =IF(D37=D36,0,1) -> 1
A38: 5 | B38: TLX5 | C38: SALE | D38: TLX5104000526092026 | E38: 46291.626 | F38: 3 | G38: 887961672039 | H38: 1 | I38: 399 | J38: 0 | K38: 0 | L38: 0 | M38: 399 | N38: 19 | O38: 5 | P38: NE MATCHBOX BASIC CA | Q38: 50157523 | R38: COMPLETED | S38: 50157523 | U38: GnG | V38: 0 | W38: =HOUR(E38) -> 15 | X38: =IF(D38=D37,0,1) -> 0
A39: 26 | B39: TLX5 | C39: SALE | D39: TLX5102002626092026 | E39: 46291.632 | F39: 3 | G39: 8907653097178 | H39: 1 | I39: 295 | J39: 0 | K39: 0 | L39: 0 | M39: 295 | N39: 14.04 | O39: 5 | Q39: 50170981 | R39: COMPLETED | U39: GnG | V39: 0 | W39: =HOUR(E39) -> 15 | X39: =IF(D39=D38,0,1) -> 1
A40: 26 | B40: TLX5 | C40: SALE | D40: TLX5102002626092026 | E40: 46291.632 | F40: 3 | G40: 8904279514874 | H40: 1 | I40: 599 | J40: 0 | K40: 0 | L40: 0 | M40: 599 | N40: 28.52 | O40: 5 | P40: NE SKM SNIP SNIP DIS | Q40: 50170981 | R40: COMPLETED | S40: 50000002 | U40: GnG | V40: 0 | W40: =HOUR(E40) -> 15 | X40: =IF(D40=D39,0,1) -> 0
...

Sheet Sheet1
A1: Store | B1: VEGAS
A2: Date- | B2: =TODAY()-1 -> 46290
A3: MONTH TRGT - | B3: =[1]DSR!D54 -> 3029539.7
A4: TARGET- | B4: =VLOOKUP(B2,[1]DSR!C8:D52,2,0) -> 96074.199
A5: SALE- | B5: =IFERROR(VLOOKUP(B2,[1]DSR!C9:E54,3,0),0) -> 96738
A6: FF- | B6: =VLOOKUP(B2,[1]DSR!C8:S52,17,0) -> 265
A7: BILL- | B7: =VLOOKUP(B2,[1]DSR!C8:R52,16,0) -> 48
A8: UNIT- | B8: =IFERROR(VLOOKUP(B2,[1]DSR!C9:Q54,15,0),0) -> 100
A9: UPT- | B9: =VLOOKUP(B2,[1]DSR!C9:AA52,25,0) -> 2.0833333
A10: ATV- | B10: =VLOOKUP(B2,[1]DSR!C9:Z52,24,0) -> 2015.375
A11: AUV- | B11: =VLOOKUP(B2,[1]DSR!C9:Y52,23,0) -> 967.38
A12: CONV%- | B12: =VLOOKUP('[1]MSG '!B2,[1]DSR!C9:AB52,26,0)
A14: MTD TGT- | B14: =VLOOKUP(B2,[1]DSR!C9:K52,9,0) -> 2449892.1
A15: MTD SALE- | B15: =[1]DSR!E54 -> 2404186
A16: MTD SALE%- | B16: =B15/B14 -> 0.98134364
A17: MTD FF- | B17: =[1]DSR!S54 -> 6418
A18: MTD BILL- | B18: =[1]DSR!R54 -> 1021
A19: MTD QTY- | B19: =[1]DSR!Q54 -> 2292
A20: MTD UPT- | B20: =[1]DSR!AA54 -> 2.244858
A21: MTD ATV- | B21: =[1]DSR!Z54 -> 2354.7365
A22: MTD AUV- | B22: =[1]DSR!Y54 -> 1048.9468
A23: MTD CONV%- | B23: =[1]DSR!AB54 -> 0.15908383
A25: ATVD SALE- | B25: =VLOOKUP(B2,[1]DSR!C9:AH52,32,0) -> 0
A26: ATVD QTY- | B26: =VLOOKUP(B2,[1]DSR!C9:U52,19,0) -> 0
A27: ATVD CONTRI%- | B27: =VLOOKUP(B2,[1]DSR!C9:AI52,33,0) -> 0
A28: MTD ATVD CONTRI%- | B28: =[1]DSR!AI54 -> 0.0065564811
A30: HOT SPOT SALE- | B30: =VLOOKUP(B2,[1]DSR!C9:AS52,43,0) -> 1799
A31: HOT SPOT %- | B31: =VLOOKUP(B2,[1]DSR!C9:AT52,44,0) -> 0.018596622
A32: MTD HOTSPOT %- | B32: =[1]DSR!AT54 -> 0.040668234
A34: SELF DEMO SALE- | B34: =VLOOKUP(B2,[1]DSR!C9:AP52,40,0) -> 5309
A35: SELF DEMO %- | B35: =VLOOKUP(B2,[1]DSR!C9:AQ52,41,0) -> 0.054880192
A36: MTD SELF DEMO %- | B36: =[1]DSR!AQ54 -> 0.036314578
A38: CORE- | B38: =VLOOKUP(B2,[1]DSR!C9:AM52,37,0) -> 1860
A39: CORE %- | B39: =VLOOKUP(B2,[1]DSR!C9:AN52,38,0) -> 0.019227191
A40: MTD CORE SALE- | B40: =[1]DSR!AM54 -> 102517
A41: MTD CORE DEMO%- | B41: =[1]DSR!AN54 -> 0.042641044
A43: MII SALE - | B43: =VLOOKUP(B2,[1]DSR!C9:AV52,46,0) -> 8581
A44: MII SALE %- | B44: =VLOOKUP(B2,[1]DSR!C9:AW52,47,0) -> 0.088703508
A45: MTD MII SALE- | B45: =[1]DSR!AV54 -> 219214
A46: MTD MII SALE %- | B46: =[1]DSR!AW54 -> 0.091180133
...
