Workbook

Sheet Netplay
A1: Attraction DSR OF JUNE 26 | N1: =TODAY()-1 -> 46290 | O1: =TODAY() -> 46291
A2: DATE | C2: DAY | D2: Net Play | P2: MTD ACH
D3: Target | E3: Actual Sale | F3: Ach% | G3: Bills target | H3: Bills | I3: Ach % | J3: MTD TARGET | K3: MTD ACH | L3: MTD ACH % | M3: Qty | Q3: Target | R3: Actual Sale | S3: Ach%
A4: 46266 | B4: 1 | C4: TUE | D4: 4597.4185 | E4: 0 | F4: =E4/D4 -> 0 | G4: =D4/250 -> 18.389674 | H4: 0 | I4: =H4/G4 -> 0 | J4: =+D4 -> 4597.4185 | K4: =+E4 -> 0 | L4: =+K4/J4 -> 0 | M4: 0 | P4: Today | Q4: =+VLOOKUP(O1,A4:D34,4,0) -> 11996.078 | R4: =+VLOOKUP(O1,A4:E34,5,0) -> 0 | S4: =R4/Q4 -> 0
A5: =+A4+1 -> 46267 | B5: 2 | C5: WED | D5: 4760.6694 | E5: 0 | F5: =E5/D5 -> 0 | G5: =D5/250 -> 19.042677 | H5: 0 | I5: =H5/G5 -> 0 | J5: =+D5+J4 -> 9358.0879 | K5: =+E5+K4 -> 0 | L5: =+K5/J5 -> 0 | M5: 0 | P5: MTD | Q5: =+VLOOKUP(O1,A4:J35,10,0) -> 181800.24 | R5: =+VLOOKUP(O1,A4:K35,11,0) -> 47200 | S5: =R5/Q5 -> 0.25962562
A6: =+A5+1 -> 46268 | B6: 3 | C6: THU | D6: 5336.5905 | E6: 2000 | F6: =E6/D6 -> 0.37477112 | G6: =D6/250 -> 21.346362 | H6: 5 | I6: =H6/G6 -> 0.23423195 | J6: =+D6+J5 -> 14694.678 | K6: =+E6+K5 -> 2000 | L6: =+K6/J6 -> 0.13610369 | M6: 8
A7: =+A6+1 -> 46269 | B7: 4 | C7: FRI | D7: 8061.591 | E7: 3000 | F7: =E7/D7 -> 0.37213498 | G7: =D7/250 -> 32.246364 | H7: 9 | I7: =H7/G7 -> 0.27910124 | J7: =+D7+J6 -> 22756.269 | K7: =+E7+K6 -> 5000 | L7: =+K7/J7 -> 0.21971967 | M7: 12
A8: =+A7+1 -> 46270 | B8: 5 | C8: SAT | D8: 10551.494 | E8: 2750 | F8: =E8/D8 -> 0.2606266 | G8: =D8/250 -> 42.205976 | H8: 10 | I8: =H8/G8 -> 0.23693327 | J8: =+D8+J7 -> 33307.763 | K8: =+E8+K7 -> 7750 | L8: =+K8/J8 -> 0.23267849 | M8: 11
A9: =+A8+1 -> 46271 | B9: 6 | C9: SUN | D9: 11801.484 | E9: 0 | F9: =E9/D9 -> 0 | G9: =D9/250 -> 47.205936 | H9: 0 | I9: =H9/G9 -> 0 | J9: =+D9+J8 -> 45109.247 | K9: =+E9+K8 -> 7750 | L9: =+K9/J9 -> 0.17180513 | M9: 0
A10: =+A9+1 -> 46272 | B10: 7 | C10: MON | D10: 4504.142 | E10: 750 | F10: =E10/D10 -> 0.1665134 | G10: =D10/250 -> 18.016568 | H10: 3 | I10: =H10/G10 -> 0.1665134 | J10: =+D10+J9 -> 49613.389 | K10: =+E10+K9 -> 8500 | L10: =+K10/J10 -> 0.17132472 | M10: 3
A11: =+A10+1 -> 46273 | B11: 8 | C11: TUE | D11: 4713.2701 | E11: 500 | F11: =E11/D11 -> 0.10608346 | G11: =D11/250 -> 18.85308 | H11: 2 | I11: =H11/G11 -> 0.10608346 | J11: =+D11+J10 -> 54326.659 | K11: =+E11+K10 -> 9000 | L11: =+K11/J11 -> 0.16566452 | M11: 2
A12: =+A11+1 -> 46274 | B12: 9 | C12: WED | D12: 4730.4354 | E12: 250 | F12: =E12/D12 -> 0.052849258 | G12: =D12/250 -> 18.921741 | H12: 1 | I12: =H12/G12 -> 0.052849258 | J12: =+D12+J11 -> 59057.095 | K12: =+E12+K11 -> 9250 | L12: =+K12/J12 -> 0.15662809 | M12: 1
A13: =+A12+1 -> 46275 | B13: 10 | C13: THU | D13: 5265.6039 | E13: 1750 | F13: =E13/D13 -> 0.33234555 | G13: =D13/250 -> 21.062416 | H13: 4 | I13: =H13/G13 -> 0.18991174 | J13: =+D13+J12 -> 64322.699 | K13: =+E13+K12 -> 11000 | L13: =+K13/J13 -> 0.17101273 | M13: 7
A14: =+A13+1 -> 46276 | B14: 11 | C14: FRI | D14: 6387.6675 | E14: 1850 | F14: =E14/D14 -> 0.28962059 | G14: =D14/250 -> 25.55067 | H14: 7 | I14: =H14/G14 -> 0.27396542 | J14: =+D14+J13 -> 70710.366 | K14: =+E14+K13 -> 12850 | L14: =+K14/J14 -> 0.18172724 | M14: 8
A15: =+A14+1 -> 46277 | B15: 12 | C15: SAT | D15: 11555.449 | E15: 7500 | F15: =E15/D15 -> 0.64904444 | G15: =D15/250 -> 46.221796 | H15: 22 | I15: =H15/G15 -> 0.47596592 | J15: =+D15+J14 -> 82265.815 | K15: =+E15+K14 -> 20350 | L15: =+K15/J15 -> 0.24736885 | M15: 30
A16: =+A15+1 -> 46278 | B16: 13 | C16: SUN | D16: 11783.432 | E16: 5250 | F16: =E16/D16 -> 0.44554082 | G16: =D16/250 -> 47.133728 | H16: 17 | I16: =H16/G16 -> 0.36067591 | J16: =+D16+J15 -> 94049.247 | K16: =+E16+K15 -> 25600 | L16: =+K16/J16 -> 0.27219782 | M16: 21
A17: =+A16+1 -> 46279 | B17: 14 | C17: MON | D17: 5196.8316 | E17: 1000 | F17: =E17/D17 -> 0.19242494 | G17: =D17/250 -> 20.787326 | H17: 4 | I17: =H17/G17 -> 0.19242494 | J17: =+D17+J16 -> 99246.079 | K17: =+E17+K16 -> 26600 | L17: =+K17/J17 -> 0.26802066 | M17: 4
... A28: =+A27+1 -> 46290 | B28: 25 | C28: FRI | D28: 6239.3847 | E28: 750 | F28: =E28/D28 -> 0.12020416 | G28: =D28/250 -> 24.957539 | H28: 3 | I28: =H28/G28 -> 0.12020416 | J28: =+D28+J27 -> 169804.17 | K28: =+E28+K27 -> 47200 | L28: =+K28/J28 -> 0.27796727 | M28: 3
A29: =+A28+1 -> 46291 | B29: 26 | C29: SAT | D29: 11996.078 | F29: =E29/D29 -> 0 | G29: =D29/250 -> 47.984312 | I29: =H29/G29 -> 0 | J29: =+D29+J28 -> 181800.24 | K29: =+E29+K28 -> 47200 | L29: =+K29/J29 -> 0.25962562
A30: =+A29+1 -> 46292 | B30: 27 | C30: SUN | D30: 11530.929 | F30: =E30/D30 -> 0 | G30: =D30/250 -> 46.123716 | I30: =H30/G30 -> 0 | J30: =+D30+J29 -> 193331.17 | K30: =+E30+K29 -> 47200 | L30: =+K30/J30 -> 0.24414066
A31: =+A30+1 -> 46293 | B31: 28 | C31: MON | D31: 4504.142 | F31: =E31/D31 -> 0 | G31: =D31/250 -> 18.016568 | I31: =H31/G31 -> 0 | J31: =+D31+J30 -> 197835.31 | K31: =+E31+K30 -> 47200 | L31: =+K31/J31 -> 0.23858228
A32: =+A31+1 -> 46294 | B32: 29 | C32: TUE | D32: 4713.2701 | F32: =E32/D32 -> 0 | G32: =D32/250 -> 18.85308 | I32: =H32/G32 -> 0 | J32: =+D32+J31 -> 202548.58 | K32: =+E32+K31 -> 47200 | L32: =+K32/J32 -> 0.23303051
A33: =+A32+1 -> 46295 | B33: 30 | C33: WED | D33: 4802.5022 | F33: =E33/D33 -> 0 | G33: =D33/250 -> 19.210009 | I33: =H33/G33 -> 0 | J33: =+D33+J32 -> 207351.09 | K33: =+E33+K32 -> 47200 | L33: =+K33/J33 -> 0.22763324
A34: =+A33+1 -> 46296 | B34: 31 | C34: THU | F34: =E34/D34 -> #DIV/0! | G34: =D34/250 -> 0 | I34: =H34/G34 -> #DIV/0! | J34: =+D34+J33 -> 207351.09 | K34: =+E34+K33 -> 47200 | L34: =+K34/J34 -> 0.22763324
A35: Total | D35: =SUM(D4:D34) -> 207351.09 | E35: =SUM(E4:E34) -> 47200 | F35: =E35/D35 -> 0.22763324 | G35: =+SUM(G4:G34) -> 829.40435 | H35: =SUM(H4:H34) -> 154 | I35: =H35/G35 -> 0.18567542 | J35: =J34 -> 207351.09 | K35: =K34 -> 47200 | L35: =+K35/J35 -> 0.22763324 | M35: =SUM(M4:M34) -> 190
W36: =37/40 -> 0.925
A37: Last
A38: Week1
A39: Week2
A40: Week3
A41: Week4
A42: Week5
A43: Week6
V61: d

Sheet DSR
A1: DAILY NET SALES (Gross Of Vat; Net Of Discount) | S1: Hamleys India
E2: YTD | F2: =17179447+E54 -> 19583633 | J2: achieved till date | K2: =#REF!/#REF! -> #REF! | S2: Hamleys Store: | U2: Vegas | AW2: =8095+7733 -> 15828
S3: Store Area: | U3: 4500
D4: Daily Net Sales | K4: Month to Date Net Sales | Q4: Key Performance Indicators
E5: ACTUAL | F5: Discount Given | G5: Disc % | I5: ACTUAL | J5: ACTUAL | K5: MONTH | L5: MONTH | M5: MONTH | N5: ACTUAL | O5: ACTUAL | Q5: Units Sold | R5: Number of Transact | S5: Number of visitors | T5: Batteries Sold | U5: ATV Drivers Sold | V5: Loyalty | W5: Red Card | X5: Bubble Stick | AC5: Battery Attachment% | AD5: ATV Attachment% | AE5: Red Card% | AF5: Loyalty% | AG5: Bubble Stick% | AH5: ATV Drivers Value | AI5: ATV CONTRI % | AJ5: BAttery Value | AK5: BATTERY CONTRI % | AL5: Core Value | AN5: CORE CONTRI % | AO5: SELF VALUE | AQ5: SELF CONTRI % | AR5: HOTSPOT VALUE | AT5: HOTSPOT CONTRI % | AU5: MII Sale | AW5: MII Contri% | AX5: MULTI BILLS | AY5: MULTI BILLS CONTRI % | AZ5: TELECALLING TGT | BA5: TELECALLING CALLS | BB5: TELECALLING BILLS | BC5: TELECALLING SALE | BD5: TELECALLING CONRI% | BE5: Liquidation | BF5: Liquidation% | BG5: Tote Bag | BH5: Tote Bag%
A6: Week | B6: Weekdy | C6: Day | D6: TARGET | H6: LY | I6: vs | J6: vs | K6: to date | L6: to date | M6: to date | N6: vs | O6: vs | Y6: AUV | Z6: ATV | AA6: UPT | AB6: Conv%
I7: TARGET | J7: LY | K7: TARGET | L7: ACTUAL | M7: LY | N7: TARGET | O7: LY
AL8: Qty | AM8: Sale | AO8: Qty | AP8: Sale | AR8: Qty | AS8: Sale | AU8: Qty | AV8: Sale
A9: WEEK 1 | B9: Sat | C9: 46263 | G9: =IF(ISERROR(F9/E9),"",F9/E9) | I9: =IF(ISERROR(E9/D9),"",E9/D9) | J9: =IF(ISERROR(E9/H9),"",(E9/H9))-1 -> #VALUE! | K9: =IF(ISERROR(K8+D9),0,K8+D9) -> 0 | L9: =IF(ISERROR(L8+E9),0,L8+E9) -> 0 | M9: =IF(ISERROR(M8+H9),0,M8+H9) -> 0 | N9: =IF(ISERROR(L9/K9),"",L9/K9) | O9: =IF(ISERROR(L9/M9),"",L9/M9)-100% -> #VALUE! | Y9: =IF(ISERROR(E9/Q9),"",E9/Q9) | Z9: =IF(ISERROR(E9/R9),"",E9/R9) | AA9: =IF(ISERROR(Q9/R9),"",Q9/R9) | AB9: =IF(ISERROR(R9/S9),"",R9/S9) | AC9: =IF(ISERROR(T9/R9),"",T9/R9) | AD9: =IF(ISERROR(U9/R9),"",U9/R9) | AE9: =IF(ISERROR(W9/R9),"",W9/R9) | AF9: =+V9/R9 -> #DIV/0! | AG9: =+X9/R9 -> #DIV/0! | AI9: =AH9/E9 -> #DIV/0! | AK9: =+AJ9/E9 -> #DIV/0! | AN9: =AM9/E9 -> #DIV/0! | AQ9: =AP9/E9 -> #DIV/0! | AT9: =AS9/E9 -> #DIV/0! | AW9: =AV9/E9 -> #DIV/0! | AY9: =AX9/R9 -> #DIV/0! | BD9: =+BC9/E9 -> #DIV/0! | BF9: =BE9/R9 -> #DIV/0! | BH9: =BG9/R9 -> #DIV/0!
B10: Sun | C10: =C9+1 -> 46264 | G10: =IF(ISERROR(F10/E10),"",F10/E10) | I10: =IF(ISERROR(E10/D10),"",E10/D10) | J10: =IF(ISERROR(E10/H10),"",(E10/H10))-1 -> #VALUE! | K10: =IF(ISERROR(K9+D10),0,K9+D10) -> 0 | L10: =IF(ISERROR(L9+E10),0,L9+E10) -> 0 | M10: =IF(ISERROR(M9+H10),0,M9+H10) -> 0 | N10: =IF(ISERROR(L10/K10),"",L10/K10) | O10: =IF(ISERROR(L10/M10),"",L10/M10)-100% -> #VALUE! | Y10: =IF(ISERROR(E10/Q10),"",E10/Q10) | Z10: =IF(ISERROR(E10/R10),"",E10/R10) | AA10: =IF(ISERROR(Q10/R10),"",Q10/R10) | AB10: =IF(ISERROR(R10/S10),"",R10/S10) | AC10: =IF(ISERROR(T10/R10),"",T10/R10) | AD10: =IF(ISERROR(U10/R10),"",U10/R10) | AE10: =IF(ISERROR(W10/R10),"",W10/R10) | AF10: =+V10/R10 -> #DIV/0! | AG10: =+X10/R10 -> #DIV/0! | AI10: =AH10/E10 -> #DIV/0! | AK10: =+AJ10/E10 -> #DIV/0! | AN10: =AM10/E10 -> #DIV/0! | AQ10: =AP10/E10 -> #DIV/0! | AT10: =AS10/E10 -> #DIV/0! | AW10: =AV10/E10 -> #DIV/0! | AY10: =AX10/R10 -> #DIV/0! | BD10: =+BC10/E10 -> #DIV/0! | BF10: =BE10/R10 -> #DIV/0! | BH10: =BG10/R10 -> #DIV/0!
B11: Total | D11: =SUM(D9:D10) -> 0 | E11: =SUM(E9:E10) -> 0 | F11: =SUM(F9:F10) -> 0 | G11: =IF(ISERROR(F11/E11),"",F11/E11) | H11: =SUM(H9:H10) -> 0 | I11: =IF(ISERROR(E11/D11),"",E11/D11) | J11: =IF(ISERROR(E11/H11),"",(E11/H11))-1 -> #VALUE! | Q11: =SUM(Q9:Q10) -> 0 | R11: =SUM(R9:R10) -> 0 | S11: =SUM(S9:S10) -> 0 | T11: =SUM(T9:T10) -> 0 | U11: =SUM(U9:U10) -> 0 | V11: =SUM(V9:V10) -> 0 | W11: =SUM(W9:W10) -> 0 | X11: =SUM(X9:X10) -> 0 | Y11: =IF(ISERROR(E11/Q11),"",E11/Q11) | Z11: =IF(ISERROR(E11/R11),"",E11/R11) | AA11: =IF(ISERROR(Q11/R11),"",Q11/R11) | AB11: =IF(ISERROR(R11/S11),"",R11/S11) | AC11: =IF(ISERROR(T11/R11),"",T11/R11) | AD11: =IF(ISERROR(U11/R11),"",U11/R11) | AE11: =IF(ISERROR(W11/R11),"",W11/R11) | AF11: =+V11/R11 -> #DIV/0! | AG11: =+X11/R11 -> #DIV/0! | AH11: =SUM(AH9:AH10) -> 0 | AI11: =AH11/E11 -> #DIV/0! | AJ11: =SUM(AJ9:AJ10) -> 0 | AK11: =+AJ11/E11 -> #DIV/0! | AL11: =SUM(AL9:AL10) -> 0 | AM11: =SUM(AM9:AM10) -> 0 | AN11: =AM11/E11 -> #DIV/0! | AO11: =+SUM(AO9:AO10) -> 0 | AP11: =+SUM(AP9:AP10) -> 0 | AQ11: =AP11/E11 -> #DIV/0! | AR11: =+SUM(AR9:AR10) -> 0 | AS11: =+SUM(AS9:AS10) -> 0 | AT11: =AS11/E11 -> #DIV/0! | AU11: =+SUM(AU9:AU10) -> 0 | AV11: =+SUM(AV9:AV10) -> 0 | AW11: =AV11/E11 -> #DIV/0! | AX11: =SUM(AX9:AX10) -> 0 | AY11: =AX11/R11 -> #DIV/0! | AZ11: =SUM(AZ9:AZ10) -> 0 | BA11: =SUM(BA9:BA10) -> 0 | BB11: =SUM(BB9:BB10) -> 0 | BC11: =SUM(BC9:BC10) -> 0 | BD11: =+BC11/E11 -> #DIV/0! | BE11: =SUM(BE9:BE10) -> 0 | BF11: =BE11/R11 -> #DIV/0! | BG11: =SUM(BG9:BG10) -> 0 | BH11: =BG11/R11 -> #DIV/0!
A12: WEEK 1 | B12: Mon | C12: =C10+1 -> 46265 | G12: =IF(ISERROR(F12/E12),"",F12/E12) | I12: =IF(ISERROR(E12/D12),"",E12/D12) | J12: =IF(ISERROR(E12/H12),"",(E12/H12))-1 -> #VALUE! | K12: =IF(ISERROR(K10+D12),0,K10+D12) -> 0 | L12: =IF(ISERROR(L10+E12),0,L10+E12) -> 0 | M12: =IF(ISERROR(M10+H12),0,M10+H12) -> 0 | N12: =IF(ISERROR(L12/K12),"",L12/K12) | O12: =IF(ISERROR(L12/M12),"",L12/M12)-100% -> #VALUE! | Y12: =IF(ISERROR(E12/Q12),"",E12/Q12) | Z12: =IF(ISERROR(E12/R12),"",E12/R12) | AA12: =IF(ISERROR(Q12/R12),"",Q12/R12) | AB12: =IF(ISERROR(R12/S12),"",R12/S12) | AC12: =IF(ISERROR(T12/R12),"",T12/R12) | AD12: =IF(ISERROR(U12/R12),"",U12/R12) | AE12: =IF(ISERROR(W12/R12),"",W12/R12) | AF12: =+V12/R12 -> #DIV/0! | AG12: =+X12/R12 -> #DIV/0! | AI12: =AH12/E12 -> #DIV/0! | AK12: =+AJ12/E12 -> #DIV/0! | AN12: =AM12/E12 -> #DIV/0! | AQ12: =AP12/E12 -> #DIV/0! | AT12: =AS12/E12 -> #DIV/0! | AW12: =AV12/E12 -> #DIV/0! | AY12: =AX12/R12 -> #DIV/0! | BD12: =+BC12/E12 -> #DIV/0! | BF12: =BE12/R12 -> #DIV/0! | BH12: =BG12/R12 -> #DIV/0!
B13: Tues | C13: =C12+1 -> 46266 | D13: 73656.886 | E13: 64929 | G13: =IF(ISERROR(F13/E13),"",F13/E13) -> 0 | H13: 65771 | I13: =IF(ISERROR(E13/D13),"",E13/D13) -> 0.88150618 | J13: =IF(ISERROR(E13/H13),"",(E13/H13))-1 -> -0.012801995 | K13: =IF(ISERROR(K12+D13),0,K12+D13) -> 73656.886 | L13: =IF(ISERROR(L12+E13),0,L12+E13) -> 64929 | M13: =IF(ISERROR(M12+H13),0,M12+H13) -> 65771 | N13: =IF(ISERROR(L13/K13),"",L13/K13) -> 0.88150618 | O13: =IF(ISERROR(L13/M13),"",L13/M13)-100% -> -0.012801995 | Q13: 54 | R13: 27 | S13: 186 | T13: 4 | U13: 0 | V13: 4 | W13: 0 | X13: 0 | Y13: =IF(ISERROR(E13/Q13),"",E13/Q13) -> 1202.3889 | Z13: =IF(ISERROR(E13/R13),"",E13/R13) -> 2404.7778 | AA13: =IF(ISERROR(Q13/R13),"",Q13/R13) -> 2 | AB13: =IF(ISERROR(R13/S13),"",R13/S13) -> 0.14516129 | AC13: =IF(ISERROR(T13/R13),"",T13/R13) -> 0.14814815 | AD13: =IF(ISERROR(U13/R13),"",U13/R13) -> 0 | AE13: =IF(ISERROR(W13/R13),"",W13/R13) -> 0 | AF13: =+V13/R13 -> 0.14814815 | AG13: =+X13/R13 -> 0 | AH13: 0 | AI13: =AH13/E13 -> 0 | AJ13: 440 | AK13: =+AJ13/E13 -> 0.0067766329 | AL13: 0 | AM13: 0 | AN13: =AM13/E13 -> 0 | AO13: 3 | AP13: 3573 | AQ13: =AP13/E13 -> 0.05502934 | AR13: 1 | AS13: 1699 | AT13: =AS13/E13 -> 0.026167044 | AU13: 4 | AV13: 7172 | AW13: =AV13/E13 -> 0.11045912 | AX13: 13 | AY13: =AX13/R13 -> 0.48148148 | AZ13: 100 | BA13: 80 | BB13: 0 | BC13: 0 | BD13: =+BC13/E13 -> 0 | BE13: 0 | BF13: =BE13/R13 -> 0 | BG13: 0 | BH13: =BG13/R13 -> 0
B14: Wed | C14: =C13+1 -> 46267 | D14: 76859.359 | E14: 119760 | G14: =IF(ISERROR(F14/E14),"",F14/E14) -> 0 | H14: 66849 | I14: =IF(ISERROR(E14/D14),"",E14/D14) -> 1.5581707 | J14: =IF(ISERROR(E14/H14),"",(E14/H14))-1 -> 0.79150025 | K14: =IF(ISERROR(K13+D14),0,K13+D14) -> 150516.25 | L14: =IF(ISERROR(L13+E14),0,L13+E14) -> 184689 | M14: =IF(ISERROR(M13+H14),0,M13+H14) -> 132620 | N14: =IF(ISERROR(L14/K14),"",L14/K14) -> 1.227037 | O14: =IF(ISERROR(L14/M14),"",L14/M14)-100% -> 0.39261801 | Q14: 58 | R14: 29 | S14: 206 | T14: 7 | U14: 0 | V14: 1 | W14: 0 | X14: 0 | Y14: =IF(ISERROR(E14/Q14),"",E14/Q14) -> 2064.8276 | Z14: =IF(ISERROR(E14/R14),"",E14/R14) -> 4129.6552 | AA14: =IF(ISERROR(Q14/R14),"",Q14/R14) -> 2 | AB14: =IF(ISERROR(R14/S14),"",R14/S14) -> 0.1407767 | AC14: =IF(ISERROR(T14/R14),"",T14/R14) -> 0.24137931 | AD14: =IF(ISERROR(U14/R14),"",U14/R14) -> 0 | AE14: =IF(ISERROR(W14/R14),"",W14/R14) -> 0 | AF14: =+V14/R14 -> 0.034482759 | AG14: =+X14/R14 -> 0 | AH14: 2499 | AI14: =AH14/E14 -> 0.020866733 | AJ14: 760 | AK14: =+AJ14/E14 -> 0.0063460254 | AL14: 1 | AM14: 32997 | AN14: =AM14/E14 -> 0.27552605 | AO14: 0 | AP14: 0 | AQ14: =AP14/E14 -> 0 | AR14: 1 | AS14: 32997 | AT14: =AS14/E14 -> 0.27552605 | AU14: 4 | AV14: 7071 | AW14: =AV14/E14 -> 0.059043086 | AX14: 15 | AY14: =AX14/R14 -> 0.51724138 | AZ14: 100 | BA14: 100 | BB14: 0 | BC14: 0 | BD14: =+BC14/E14 -> 0 | BE14: 0 | BF14: =BE14/R14 -> 0 | BG14: 0 | BH14: =BG14/R14 -> 0
B15: Thurs | C15: =C14+1 -> 46268 | D15: 89669.252 | E15: 70583 | G15: =IF(ISERROR(F15/E15),"",F15/E15) -> 0 | H15: 69939 | I15: =IF(ISERROR(E15/D15),"",E15/D15) -> 0.7871483 | J15: =IF(ISERROR(E15/H15),"",(E15/H15))-1 -> 0.0092080241 | K15: =IF(ISERROR(K14+D15),0,K14+D15) -> 240185.5 | L15: =IF(ISERROR(L14+E15),0,L14+E15) -> 255272 | M15: =IF(ISERROR(M14+H15),0,M14+H15) -> 202559 | N15: =IF(ISERROR(L15/K15),"",L15/K15) -> 1.0628119 | O15: =IF(ISERROR(L15/M15),"",L15/M15)-100% -> 0.26023529 | Q15: 75 | R15: 37 | S15: 231 | T15: 6 | U15: 0 | V15: 4 | W15: 0 | X15: 0 | Y15: =IF(ISERROR(E15/Q15),"",E15/Q15) -> 941.10667 | Z15: =IF(ISERROR(E15/R15),"",E15/R15) -> 1907.6486 | AA15: =IF(ISERROR(Q15/R15),"",Q15/R15) -> 2.027027 | AB15: =IF(ISERROR(R15/S15),"",R15/S15) -> 0.16017316 | AC15: =IF(ISERROR(T15/R15),"",T15/R15) -> 0.16216216 | AD15: =IF(ISERROR(U15/R15),"",U15/R15) -> 0 | AE15: =IF(ISERROR(W15/R15),"",W15/R15) -> 0 | AF15: =+V15/R15 -> 0.10810811 | AG15: =+X15/R15 -> 0 | AH15: 0 | AI15: =AH15/E15 -> 0 | AJ15: 630 | AK15: =+AJ15/E15 -> 0.008925662 | AL15: 0 | AM15: 0 | AN15: =AM15/E15 -> 0 | AO15: 1 | AP15: 1299 | AQ15: =AP15/E15 -> 0.018403865 | AR15: 0 | AS15: 0 | AT15: =AS15/E15 -> 0 | AU15: 2 | AV15: 648 | AW15: =AV15/E15 -> 0.0091806809 | AX15: 20 | AY15: =AX15/R15 -> 0.54054054 | AZ15: 100 | BA15: 110 | BB15: 1 | BC15: 7794 | BD15: =+BC15/E15 -> 0.11042319 | BE15: 0 | BF15: =BE15/R15 -> 0 | BG15: 0 | BH15: =BG15/R15 -> 0
B16: Fri | C16: =C15+1 -> 46269 | D16: 128098.93 | E16: 51966 | G16: =IF(ISERROR(F16/E16),"",F16/E16) -> 0 | H16: 81017 | I16: =IF(ISERROR(E16/D16),"",E16/D16) -> 0.40567083 | J16: =IF(ISERROR(E16/H16),"",(E16/H16))-1 -> -0.35857906 | K16: =IF(ISERROR(K15+D16),0,K15+D16) -> 368284.43 | L16: =IF(ISERROR(L15+E16),0,L15+E16) -> 307238 | M16: =IF(ISERROR(M15+H16),0,M15+H16) -> 283576 | N16: =IF(ISERROR(L16/K16),"",L16/K16) -> 0.83424108 | O16: =IF(ISERROR(L16/M16),"",L16/M16)-100% -> 0.083441476 | Q16: 75 | R16: 34 | S16: 233 | T16: 3 | U16: 1 | V16: 3 | W16: 0 | X16: 1 | Y16: =IF(ISERROR(E16/Q16),"",E16/Q16) -> 692.88 | Z16: =IF(ISERROR(E16/R16),"",E16/R16) -> 1528.4118 | AA16: =IF(ISERROR(Q16/R16),"",Q16/R16) -> 2.2058824 | AB16: =IF(ISERROR(R16/S16),"",R16/S16) -> 0.14592275 | AC16: =IF(ISERROR(T16/R16),"",T16/R16) -> 0.088235294 | AD16: =IF(ISERROR(U16/R16),"",U16/R16) -> 0.029411765 | AE16: =IF(ISERROR(W16/R16),"",W16/R16) -> 0 | AF16: =+V16/R16 -> 0.088235294 | AG16: =+X16/R16 -> 0.029411765 | AH16: 1499 | AI16: =AH16/E16 -> 0.028845784 | AJ16: 320 | AK16: =+AJ16/E16 -> 0.0061578725 | AL16: 1 | AM16: 954 | AN16: =AM16/E16 -> 0.018358157 | AO16: 4 | AP16: 5546 | AQ16: =AP16/E16 -> 0.10672363 | AR16: 2 | AS16: 2748 | AT16: =AS16/E16 -> 0.05288073 | AU16: 9 | AV16: 12702 | AW16: =AV16/E16 -> 0.24442905 | AX16: 17 | AY16: =AX16/R16 -> 0.5 | AZ16: 100 | BA16: 50 | BB16: 0 | BC16: 0 | BD16: =+BC16/E16 -> 0 | BE16: 0 | BF16: =BE16/R16 -> 0 | BG16: 0 | BH16: =BG16/R16 -> 0
B17: Sat | C17: =C16+1 -> 46270 | D17: 166528.61 | E17: 153776 | G17: =IF(ISERROR(F17/E17),"",F17/E17) -> 0 | H17: 190445 | I17: =IF(ISERROR(E17/D17),"",E17/D17) -> 0.9234209 | J17: =IF(ISERROR(E17/H17),"",(E17/H17))-1 -> -0.19254378 | K17: =IF(ISERROR(K16+D17),0,K16+D17) -> 534813.04 | L17: =IF(ISERROR(L16+E17),0,L16+E17) -> 461014 | M17: =IF(ISERROR(M16+H17),0,M16+H17) -> 474021 | N17: =IF(ISERROR(L17/K17),"",L17/K17) -> 0.86200964 | O17: =IF(ISERROR(L17/M17),"",L17/M17)-100% -> -0.027439713 | Q17: 178 | R17: 66 | S17: 437 | T17: 3 | U17: 1 | V17: 9 | W17: 0 | X17: 0 | Y17: =IF(ISERROR(E17/Q17),"",E17/Q17) -> 863.91011 | Z17: =IF(ISERROR(E17/R17),"",E17/R17) -> 2329.9394 | AA17: =IF(ISERROR(Q17/R17),"",Q17/R17) -> 2.6969697 | AB17: =IF(ISERROR(R17/S17),"",R17/S17) -> 0.15102975 | AC17: =IF(ISERROR(T17/R17),"",T17/R17) -> 0.045454545 | AD17: =IF(ISERROR(U17/R17),"",U17/R17) -> 0.015151515 | AE17: =IF(ISERROR(W17/R17),"",W17/R17) -> 0 | AF17: =+V17/R17 -> 0.13636364 | AG17: =+X17/R17 -> 0 | AH17: 1199 | AI17: =AH17/E17 -> 0.0077970555 | AJ17: 288 | AK17: =+AJ17/E17 -> 0.001872854 | AL17: 1 | AM17: 799 | AN17: =AM17/E17 -> 0.0051958693 | AO17: 2 | AP17: 949 | AQ17: =AP17/E17 -> 0.0061713141 | AR17: 0 | AS17: 0 | AT17: =AS17/E17 -> 0 | AU17: 9 | AV17: 6043 | AW17: =AV17/E17 -> 0.03929742 | AX17: 31 | AY17: =AX17/R17 -> 0.46969697 | AZ17: 100 | BA17: 100 | BB17: 0 | BC17: 0 | BD17: =+BC17/E17 -> 0 | BE17: 0 | BF17: =BE17/R17 -> 0 | BG17: 0 | BH17: =BG17/R17 -> 0
B18: Sun | C18: =C17+1 -> 46271 | G18: =IF(ISERROR(F18/E18),"",F18/E18) | H18: 130963 | I18: =IF(ISERROR(E18/D18),"",E18/D18) | J18: =IF(ISERROR(E18/H18),"",(E18/H18))-1 -> -1 | K18: =IF(ISERROR(K17+D18),0,K17+D18) -> 534813.04 | L18: =IF(ISERROR(L17+E18),0,L17+E18) -> 461014 | M18: =IF(ISERROR(M17+H18),0,M17+H18) -> 604984 | N18: =IF(ISERROR(L18/K18),"",L18/K18) -> 0.86200964 | O18: =IF(ISERROR(L18/M18),"",L18/M18)-100% -> -0.23797324 | Y18: =IF(ISERROR(E18/Q18),"",E18/Q18) | Z18: =IF(ISERROR(E18/R18),"",E18/R18) | AA18: =IF(ISERROR(Q18/R18),"",Q18/R18) | AB18: =IF(ISERROR(R18/S18),"",R18/S18) | AC18: =IF(ISERROR(T18/R18),"",T18/R18) | AD18: =IF(ISERROR(U18/R18),"",U18/R18) | AE18: =IF(ISERROR(W18/R18),"",W18/R18) | AF18: =+V18/R18 -> #DIV/0! | AG18: =+X18/R18 -> #DIV/0! | AI18: =AH18/E18 -> #DIV/0! | AK18: =+AJ18/E18 -> #DIV/0! | AN18: =AM18/E18 -> #DIV/0! | AQ18: =AP18/E18 -> #DIV/0! | AT18: =AS18/E18 -> #DIV/0! | AW18: =AV18/E18 -> #DIV/0! | AY18: =AX18/R18 -> #DIV/0! | BD18: =+BC18/E18 -> #DIV/0! | BF18: =BE18/R18 -> #DIV/0! | BG18: 0 | BH18: =BG18/R18 -> #DIV/0!
B19: Total | D19: =SUM(D12:D18) -> 534813.04 | E19: =SUM(E12:E18) -> 461014 | F19: =SUM(F12:F18) -> 0 | G19: =IF(ISERROR(F19/E19),"",F19/E19) -> 0 | H19: =SUM(H12:H18) -> 604984 | I19: =IF(ISERROR(E19/D19),"",E19/D19) -> 0.86200964 | J19: =IF(ISERROR(E19/H19),"",(E19/H19))-1 -> -0.23797324 | Q19: =SUM(Q12:Q18) -> 440 | R19: =SUM(R12:R18) -> 193 | S19: =SUM(S12:S18) -> 1293 | T19: =SUM(T12:T18) -> 23 | U19: =SUM(U12:U18) -> 2 | V19: =SUM(V12:V18) -> 21 | W19: =SUM(W12:W18) -> 0 | X19: =SUM(X12:X18) -> 1 | Y19: =IF(ISERROR(E19/Q19),"",E19/Q19) -> 1047.7591 | Z19: =IF(ISERROR(E19/R19),"",E19/R19) -> 2388.6736 | AA19: =IF(ISERROR(Q19/R19),"",Q19/R19) -> 2.2797927 | AB19: =IF(ISERROR(R19/S19),"",R19/S19) -> 0.14926527 | AC19: =IF(ISERROR(T19/R19),"",T19/R19) -> 0.11917098 | AD19: =IF(ISERROR(U19/R19),"",U19/R19) -> 0.010362694 | AE19: =IF(ISERROR(W19/R19),"",W19/R19) -> 0 | AF19: =+V19/R19 -> 0.10880829 | AG19: =+X19/R19 -> 0.0051813472 | AH19: =SUM(AH12:AH18) -> 5197 | AI19: =AH19/E19 -> 0.011272977 | AJ19: =SUM(AJ12:AJ18) -> 2438 | AK19: =+AJ19/E19 -> 0.0052883427 | AL19: =SUM(AL12:AL18) -> 3 | AM19: =SUM(AM12:AM18) -> 34750 | AN19: =AM19/E19 -> 0.07537732 | AO19: =+SUM(AO12:AO18) -> 10 | AP19: =+SUM(AP12:AP18) -> 11367 | AQ19: =AP19/E19 -> 0.024656518 | AR19: =+SUM(AR12:AR18) -> 4 | AS19: =+SUM(AS12:AS18) -> 37444 | AT19: =AS19/E19 -> 0.081220961 | AU19: =+SUM(AU12:AU18) -> 28 | AV19: =+SUM(AV12:AV18) -> 33636 | AW19: =AV19/E19 -> 0.072960908 | AX19: =SUM(AX12:AX18) -> 96 | AY19: =AX19/R19 -> 0.49740933 | AZ19: =SUM(AZ12:AZ18) -> 500 | BA19: =SUM(BA12:BA18) -> 440 | BB19: =SUM(BB12:BB18) -> 1 | BC19: =SUM(BC12:BC18) -> 7794 | BD19: =+BC19/E19 -> 0.016906211 | BE19: =SUM(BE12:BE18) -> 0 | BF19: =BE19/R19 -> 0 | BG19: =SUM(BG12:BG18) -> 0 | BH19: =BG19/R19 -> 0
A20: WEEK 2 | B20: Mon | C20: =C18+1 -> 46272 | D20: 73656.886 | E20: 38921 | G20: =IF(ISERROR(F20/E20),"",F20/E20) -> 0 | H20: 166519 | I20: =IF(ISERROR(E20/D20),"",E20/D20) -> 0.52840952 | J20: =IF(ISERROR(E20/H20),"",(E20/H20))-1 -> -0.76626691 | K20: =IF(ISERROR(K18+D20),0,K18+D20) -> 608469.93 | L20: =IF(ISERROR(L18+E20),0,L18+E20) -> 499935 | M20: =IF(ISERROR(M18+H20),0,M18+H20) -> 771503 | N20: =IF(ISERROR(L20/K20),"",L20/K20) -> 0.82162647 | O20: =IF(ISERROR(L20/M20),"",L20/M20)-100% -> -0.35199863 | Q20: 35 | R20: 24 | S20: 140 | T20: 2 | U20: 0 | V20: 3 | W20: 0 | X20: 0 | Y20: =IF(ISERROR(E20/Q20),"",E20/Q20) -> 1112.0286 | Z20: =IF(ISERROR(E20/R20),"",E20/R20) -> 1621.7083 | AA20: =IF(ISERROR(Q20/R20),"",Q20/R20) -> 1.4583333 | AB20: =IF(ISERROR(R20/S20),"",R20/S20) -> 0.17142857 | AC20: =IF(ISERROR(T20/R20),"",T20/R20) -> 0.083333333 | AD20: =IF(ISERROR(U20/R20),"",U20/R20) -> 0 | AE20: =IF(ISERROR(V20/S20),"",V20/S20) -> 0.021428571 | AF20: =+V20/R20 -> 0.125 | AG20: =+X20/R20 -> 0 | AH20: 0 | AI20: =AH20/E20 -> 0 | AJ20: 300 | AK20: =+AJ20/E20 -> 0.0077079212 | AL20: 0 | AM20: 0 | AN20: =AM20/E20 -> 0 | AO20: 1 | AP20: 479 | AQ20: =AP20/E20 -> 0.012306981 | AR20: 0 | AS20: 0 | AT20: =AS20/E20 -> 0 | AU20: 3 | AV20: 1318 | AW20: =AV20/E20 -> 0.033863467 | AX20: 9 | AY20: =AX20/R20 -> 0.375 | AZ20: 100 | BA20: 50 | BB20: 0 | BC20: 0 | BD20: =+BC20/E20 -> 0 | BE20: 0 | BF20: =BE20/R20 -> 0 | BG20: 0 | BH20: =BG20/R20 -> 0
B21: Tues | C21: =C20+1 -> 46273 | D21: 76859.359 | E21: 46337 | G21: =IF(ISERROR(F21/E21),"",F21/E21) -> 0 | H21: 47302 | I21: =IF(ISERROR(E21/D21),"",E21/D21) -> 0.60288038 | J21: =IF(ISERROR(E21/H21),"",(E21/H21))-1 -> -0.020400829 | K21: =IF(ISERROR(K20+D21),0,K20+D21) -> 685329.29 | L21: =IF(ISERROR(L20+E21),0,L20+E21) -> 546272 | M21: =IF(ISERROR(M20+H21),0,M20+H21) -> 818805 | N21: =IF(ISERROR(L21/K21),"",L21/K21) -> 0.7970942 | O21: =IF(ISERROR(L21/M21),"",L21/M21)-100% -> -0.33284237 | Q21: 36 | R21: 22 | S21: 142 | T21: 0 | U21: 1 | V21: 1 | W21: 0 | X21: 0 | Y21: =IF(ISERROR(E21/Q21),"",E21/Q21) -> 1287.1389 | Z21: =IF(ISERROR(E21/R21),"",E21/R21) -> 2106.2273 | AA21: =IF(ISERROR(Q21/R21),"",Q21/R21) -> 1.6363636 | AB21: =IF(ISERROR(R21/S21),"",R21/S21) -> 0.15492958 | AC21: =IF(ISERROR(T21/R21),"",T21/R21) -> 0 | AD21: =IF(ISERROR(U21/R21),"",U21/R21) -> 0.045454545 | AE21: =IF(ISERROR(V21/S21),"",V21/S21) -> 0.0070422535 | AF21: =+V21/R21 -> 0.045454545 | AG21: =+X21/R21 -> 0 | AH21: 2563 | AI21: =AH21/E21 -> 0.05531217 | AJ21: 0 | AK21: =+AJ21/E21 -> 0 | AL21: 3 | AM21: =9999+3362 -> 13361 | AN21: =AM21/E21 -> 0.28834409 | AO21: 0 | AP21: 0 | AQ21: =AP21/E21 -> 0 | AR21: 0 | AS21: 0 | AT21: =AS21/E21 -> 0 | AU21: 3 | AV21: 2361 | AW21: =AV21/E21 -> 0.050952802 | AX21: 12 | AY21: =AX21/R21 -> 0.54545455 | AZ21: 100 | BA21: 100 | BB21: 0 | BC21: 0 | BD21: =+BC21/E21 -> 0 | BE21: 0 | BF21: =BE21/R21 -> 0 | BG21: 0 | BH21: =BG21/R21 -> 0
B22: Wed | C22: =C21+1 -> 46274 | D22: 76859.359 | E22: 86046 | G22: =IF(ISERROR(F22/E22),"",F22/E22) -> 0 | H22: 47469 | I22: =IF(ISERROR(E22/D22),"",E22/D22) -> 1.1195253 | J22: =IF(ISERROR(E22/H22),"",(E22/H22))-1 -> 0.81267775 | K22: =IF(ISERROR(K21+D22),0,K21+D22) -> 762188.65 | L22: =IF(ISERROR(L21+E22),0,L21+E22) -> 632318 | M22: =IF(ISERROR(M21+H22),0,M21+H22) -> 866274 | N22: =IF(ISERROR(L22/K22),"",L22/K22) -> 0.82960826 | O22: =IF(ISERROR(L22/M22),"",L22/M22)-100% -> -0.27007159 | Q22: 57 | R22: 29 | S22: 192 | T22: 1 | U22: 1 | V22: 3 | W22: 0 | X22: 0 | Y22: =IF(ISERROR(E22/Q22),"",E22/Q22) -> 1509.5789 | Z22: =IF(ISERROR(E22/R22),"",E22/R22) -> 2967.1034 | AA22: =IF(ISERROR(Q22/R22),"",Q22/R22) -> 1.9655172 | AB22: =IF(ISERROR(R22/S22),"",R22/S22) -> 0.15104167 | AC22: =IF(ISERROR(T22/R22),"",T22/R22) -> 0.034482759 | AD22: =IF(ISERROR(U22/R22),"",U22/R22) -> 0.034482759 | AE22: =IF(ISERROR(V22/S22),"",V22/S22) -> 0.015625 | AF22: =+V22/R22 -> 0.10344828 | AG22: =+X22/R22 -> 0 | AH22: 1499 | AI22: =AH22/E22 -> 0.017420914 | AJ22: 100 | AK22: =+AJ22/E22 -> 0.0011621691 | AL22: 2 | AM22: 21198 | AN22: =AM22/E22 -> 0.2463566 | AO22: 1 | AP22: 1799 | AQ22: =AP22/E22 -> 0.020907422 | AR22: 1 | AS22: 1799 | AT22: =AS22/E22 -> 0.020907422 | AU22: 13 | AV22: 15779 | AW22: =AV22/E22 -> 0.18337866 | AX22: 12 | AY22: =AX22/R22 -> 0.4137931 | AZ22: 100 | BA22: 100 | BB22: 1 | BC22: 32360 | BD22: =+BC22/E22 -> 0.37607791 | BE22: 0 | BF22: =BE22/R22 -> 0 | BG22: 0 | BH22: =BG22/R22 -> 0
B23: Thurs | C23: =C22+1 -> 46275 | D23: 86466.779 | E23: 47076 | G23: =IF(ISERROR(F23/E23),"",F23/E23) -> 0 | H23: 55947 | I23: =IF(ISERROR(E23/D23),"",E23/D23) -> 0.54444031 | J23: =IF(ISERROR(E23/H23),"",(E23/H23))-1 -> -0.15856078 | K23: =IF(ISERROR(K22+D23),0,K22+D23) -> 848655.43 | L23: =IF(ISERROR(L22+E23),0,L22+E23) -> 679394 | M23: =IF(ISERROR(M22+H23),0,M22+H23) -> 922221 | N23: =IF(ISERROR(L23/K23),"",L23/K23) -> 0.80055342 | O23: =IF(ISERROR(L23/M23),"",L23/M23)-100% -> -0.26330673 | Q23: 56 | R23: 37 | S23: 210 | T23: 0 | U23: 0 | V23: 2 | W23: 0 | X23: 0 | Y23: =IF(ISERROR(E23/Q23),"",E23/Q23) -> 840.64286 | Z23: =IF(ISERROR(E23/R23),"",E23/R23) -> 1272.3243 | AA23: =IF(ISERROR(Q23/R23),"",Q23/R23) -> 1.5135135 | AB23: =IF(ISERROR(R23/S23),"",R23/S23) -> 0.17619048 | AC23: =IF(ISERROR(T23/R23),"",T23/R23) -> 0 | AD23: =IF(ISERROR(U23/R23),"",U23/R23) -> 0 | AE23: =IF(ISERROR(V23/S23),"",V23/S23) -> 0.0095238095 | AF23: =+V23/R23 -> 0.054054054 | AG23: =+X23/R23 -> 0 | AH23: 0 | AI23: =AH23/E23 -> 0 | AJ23: 0 | AK23: =+AJ23/E23 -> 0 | AL23: 0 | AM23: 0 | AN23: =AM23/E23 -> 0 | AO23: 1 | AP23: 1799 | AQ23: =AP23/E23 -> 0.038214802 | AR23: 1 | AS23: 1799 | AT23: =AS23/E23 -> 0.038214802 | AU23: 3 | AV23: 458 | AW23: =AV23/E23 -> 0.0097289489 | AX23: 20 | AY23: =AX23/R23 -> 0.54054054 | AZ23: 100 | BA23: 50 | BB23: 0 | BC23: 0 | BD23: =+BC23/E23 -> 0 | BE23: 2 | BF23: =BE23/R23 -> 0.054054054 | BG23: 0 | BH23: =BG23/R23 -> 0
B24: Fri | C24: =C23+1 -> 46276 | D24: 96074.199 | E24: 109677 | G24: =IF(ISERROR(F24/E24),"",F24/E24) -> 0 | H24: 74095 | I24: =IF(ISERROR(E24/D24),"",E24/D24) -> 1.1415864 | J24: =IF(ISERROR(E24/H24),"",(E24/H24))-1 -> 0.48022134 | K24: =IF(ISERROR(K23+D24),0,K23+D24) -> 944729.62 | L24: =IF(ISERROR(L23+E24),0,L23+E24) -> 789071 | M24: =IF(ISERROR(M23+H24),0,M23+H24) -> 996316 | N24: =IF(ISERROR(L24/K24),"",L24/K24) -> 0.83523474 | O24: =IF(ISERROR(L24/M24),"",L24/M24)-100% -> -0.20801131 | Q24: 105 | R24: 47 | S24: 253 | T24: 6 | U24: 0 | V24: 7 | W24: 0 | X24: 0 | Y24: =IF(ISERROR(E24/Q24),"",E24/Q24) -> 1044.5429 | Z24: =IF(ISERROR(E24/R24),"",E24/R24) -> 2333.5532 | AA24: =IF(ISERROR(Q24/R24),"",Q24/R24) -> 2.2340426 | AB24: =IF(ISERROR(R24/S24),"",R24/S24) -> 0.18577075 | AC24: =IF(ISERROR(T24/R24),"",T24/R24) -> 0.12765957 | AD24: =IF(ISERROR(U24/R24),"",U24/R24) -> 0 | AE24: =IF(ISERROR(V24/S24),"",V24/S24) -> 0.027667984 | AF24: =+V24/R24 -> 0.14893617 | AG24: =+X24/R24 -> 0 | AH24: 0 | AI24: =AH24/E24 -> 0 | AJ24: 780 | AK24: =+AJ24/E24 -> 0.0071117919 | AL24: 0 | AM24: 0 | AN24: =AM24/E24 -> 0 | AO24: 1 | AP24: 1799 | AQ24: =AP24/E24 -> 0.01640271 | AR24: 2 | AS24: 2798 | AT24: =AS24/E24 -> 0.025511274 | AU24: 7 | AV24: 6354 | AW24: =AV24/E24 -> 0.057933751 | AX24: 24 | AY24: =AX24/R24 -> 0.5106383 | AZ24: 100 | BA24: 100 | BB24: 1 | BC24: 2341 | BD24: =+BC24/E24 -> 0.021344493 | BE24: 1 | BF24: =BE24/R24 -> 0.021276596 | BG24: 0 | BH24: =BG24/R24 -> 0
B25: Sat | C25: =C24+1 -> 46277 | D25: 169731.09 | E25: 229487 | G25: =IF(ISERROR(F25/E25),"",F25/E25) -> 0 | H25: 89983 | I25: =IF(ISERROR(E25/D25),"",E25/D25) -> 1.3520623 | J25: =IF(ISERROR(E25/H25),"",(E25/H25))-1 -> 1.5503373 | K25: =IF(ISERROR(K24+D25),0,K24+D25) -> 1114460.7 | L25: =IF(ISERROR(L24+E25),0,L24+E25) -> 1018558 | M25: =IF(ISERROR(M24+H25),0,M24+H25) -> 1086299 | N25: =IF(ISERROR(L25/K25),"",L25/K25) -> 0.91394698 | O25: =IF(ISERROR(L25/M25),"",L25/M25)-100% -> -0.062359442 | Q25: 220 | R25: 82 | S25: 512 | T25: 4 | U25: 1 | V25: 10 | W25: 0 | X25: 0 | Y25: =IF(ISERROR(E25/Q25),"",E25/Q25) -> 1043.1227 | Z25: =IF(ISERROR(E25/R25),"",E25/R25) -> 2798.622 | AA25: =IF(ISERROR(Q25/R25),"",Q25/R25) -> 2.6829268 | AB25: =IF(ISERROR(R25/S25),"",R25/S25) -> 0.16015625 | AC25: =IF(ISERROR(T25/R25),"",T25/R25) -> 0.048780488 | AD25: =IF(ISERROR(U25/R25),"",U25/R25) -> 0.012195122 | AE25: =IF(ISERROR(V25/S25),"",V25/S25) -> 0.01953125 | AF25: =+V25/R25 -> 0.12195122 | AG25: =+X25/R25 -> 0 | AH25: 2466 | AI25: =AH25/E25 -> 0.010745707 | AJ25: 510 | AK25: =+AJ25/E25 -> 0.0022223481 | AL25: 3 | AM25: 4989 | AN25: =AM25/E25 -> 0.021739794 | AO25: 3 | AP25: 2337 | AQ25: =AP25/E25 -> 0.010183583 | AR25: 1 | AS25: 325 | AT25: =AS25/E25 -> 0.0014162022 | AU25: 11 | AV25: 12617 | AW25: =AV25/E25 -> 0.054979149 | AX25: 41 | AY25: =AX25/R25 -> 0.5 | AZ25: 100 | BA25: 100 | BB25: 1 | BC25: 2143 | BD25: =+BC25/E25 -> 0.0093382196 | BE25: 0 | BF25: =BE25/R25 -> 0 | BG25: 0 | BH25: =BG25/R25 -> 0
B26: Sun | C26: =C25+1 -> 46278 | D26: 169731.09 | E26: 183475 | G26: =IF(ISERROR(F26/E26),"",F26/E26) -> 0 | H26: 139375 | I26: =IF(ISERROR(E26/D26),"",E26/D26) -> 1.0809746 | J26: =IF(ISERROR(E26/H26),"",(E26/H26))-1 -> 0.31641256 | K26: =IF(ISERROR(K25+D26),0,K25+D26) -> 1284191.8 | L26: =IF(ISERROR(L25+E26),0,L25+E26) -> 1202033 | M26: =IF(ISERROR(M25+H26),0,M25+H26) -> 1225674 | N26: =IF(ISERROR(L26/K26),"",L26/K26) -> 0.93602296 | O26: =IF(ISERROR(L26/M26),"",L26/M26)-100% -> -0.019288163 | Q26: 187 | R26: 75 | S26: 500 | T26: 17 | U26: 0 | V26: 7 | W26: 0 | X26: 0 | Y26: =IF(ISERROR(E26/Q26),"",E26/Q26) -> 981.14973 | Z26: =IF(ISERROR(E26/R26),"",E26/R26) -> 2446.3333 | AA26: =IF(ISERROR(Q26/R26),"",Q26/R26) -> 2.4933333 | AB26: =IF(ISERROR(R26/S26),"",R26/S26) -> 0.15 | AC26: =IF(ISERROR(T26/R26),"",T26/R26) -> 0.22666667 | AD26: =IF(ISERROR(U26/R26),"",U26/R26) -> 0 | AE26: =IF(ISERROR(V26/S26),"",V26/S26) -> 0.014 | AF26: =+V26/R26 -> 0.093333333 | AG26: =+X26/R26 -> 0 | AH26: 0 | AI26: =AH26/E26 -> 0 | AJ26: 1924 | AK26: =+AJ26/E26 -> 0.010486442 | AL26: 1 | AM26: 2124 | AN26: =AM26/E26 -> 0.011576509 | AO26: 2 | AP26: 2814 | AQ26: =AP26/E26 -> 0.015337239 | AR26: 1 | AS26: 2124 | AT26: =AS26/E26 -> 0.011576509 | AU26: 7 | AV26: 7924 | AW26: =AV26/E26 -> 0.043188445 | AX26: 35 | AY26: =AX26/R26 -> 0.46666667 | AZ26: 100 | BA26: 50 | BB26: 0 | BC26: 0 | BD26: =+BC26/E26 -> 0 | BE26: 0 | BF26: =BE26/R26 -> 0 | BG26: 0 | BH26: =BG26/R26 -> 0
B27: Total | D27: =SUM(D20:D26) -> 749378.75 | E27: =SUM(E20:E26) -> 741019 | F27: =SUM(F20:F26) -> 0 | G27: =IF(ISERROR(F27/E27),"",F27/E27) -> 0 | H27: =SUM(H20:H26) -> 620690 | I27: =IF(ISERROR(E27/D27),"",E27/D27) -> 0.98884442 | J27: =IF(ISERROR(E27/H27),"",(E27/H27))-1 -> 0.19386328 | Q27: =SUM(Q20:Q26) -> 696 | R27: =SUM(R20:R26) -> 316 | S27: =SUM(S20:S26) -> 1949 | T27: =SUM(T20:T26) -> 30 | U27: =+SUM(U26,U25,U24,U23,U22,U21,U20) -> 3 | V27: =+SUM(V26,V25,V24,V23,V22,V21,V20) -> 33 | W27: =+SUM(W26,W25,W24,W23,W22,W21,W20) -> 0 | X27: =+SUM(X26,X25,X24,X23,X22,X21,X20) -> 0 | Y27: =IF(ISERROR(E27/Q27),"",E27/Q27) -> 1064.6825 | Z27: =IF(ISERROR(E27/R27),"",E27/R27) -> 2344.9968 | AA27: =IF(ISERROR(Q27/R27),"",Q27/R27) -> 2.2025316 | AB27: =IF(ISERROR(R27/S27),"",R27/S27) -> 0.16213443 | AC27: =IF(ISERROR(T27/R27),"",T27/R27) -> 0.094936709 | AD27: =IF(ISERROR(U27/R27),"",U27/R27) -> 0.0094936709 | AE27: =IF(ISERROR(V27/S27),"",V27/S27) -> 0.01693176 | AF27: =+V27/R27 -> 0.10443038 | AG27: =+X27/R27 -> 0 | AH27: =SUM(AH20:AH26) -> 6528 | AI27: =AH27/E27 -> 0.0088094907 | AJ27: =SUM(AJ20:AJ26) -> 3614 | AK27: =+AJ27/E27 -> 0.0048770679 | AL27: =SUM(AL20:AL26) -> 9 | AM27: =SUM(AM20:AM26) -> 41672 | AN27: =AM27/E27 -> 0.056236075 | AO27: =SUM(AO20:AO26) -> 9 | AP27: =SUM(AP20:AP26) -> 11027 | AQ27: =AP27/E27 -> 0.01488086 | AR27: =SUM(AR20:AR26) -> 6 | AS27: =SUM(AS20:AS26) -> 8845 | AT27: =AS27/E27 -> 0.011936266 | AU27: =+SUM(AU20:AU26) -> 47 | AV27: =+SUM(AV20:AV26) -> 46811 | AW27: =AV27/E27 -> 0.06317112 | AX27: =SUM(AX20:AX26) -> 153 | AY27: =AX27/R27 -> 0.48417722 | AZ27: =SUM(AZ20:AZ26) -> 700 | BA27: =SUM(BA20:BA26) -> 550 | BB27: =SUM(BB20:BB26) -> 3 | BC27: =SUM(BC20:BC26) -> 36844 | BD27: =+BC27/E27 -> 0.049720722 | BE27: =SUM(BE20:BE26) -> 3 | BF27: =BE27/R27 -> 0.0094936709 | BG27: =SUM(BG20:BG26) -> 0 | BH27: =BG27/R27 -> 0
A28: WEEK 3 | B28: Mon | C28: =C26+1 -> 46279 | D28: 73656.886 | E28: 63336 | G28: =IF(ISERROR(F28/E28),"",F28/E28) -> 0 | H28: 153549 | I28: =IF(ISERROR(E28/D28),"",E28/D28) -> 0.85987887 | J28: =IF(ISERROR(E28/H28),"",(E28/H28))-1 -> -0.58751929 | K28: =IF(ISERROR(K26+D28),0,K26+D28) -> 1357848.7 | L28: =IF(ISERROR(L26+E28),0,L26+E28) -> 1265369 | M28: =IF(ISERROR(M26+H28),0,M26+H28) -> 1379223 | N28: =IF(ISERROR(L28/K28),"",L28/K28) -> 0.9318925 | O28: =IF(ISERROR(L28/M28),"",L28/M28)-100% -> -0.082549377 | Q28: 63 | R28: 21 | S28: 149 | T28: 2 | U28: 0 | V28: 2 | W28: 0 | X28: 0 | Y28: =IF(ISERROR(E28/Q28),"",E28/Q28) -> 1005.3333 | Z28: =IF(ISERROR(E28/R28),"",E28/R28) -> 3016 | AA28: =IF(ISERROR(Q28/R28),"",Q28/R28) -> 3 | AB28: =IF(ISERROR(R28/S28),"",R28/S28) -> 0.1409396 | AC28: =IF(ISERROR(T28/R28),"",T28/R28) -> 0.095238095 | AD28: =IF(ISERROR(U28/R28),"",U28/R28) -> 0 | AE28: =IF(ISERROR(W28/R28),"",W28/R28) -> 0 | AF28: =+V28/R28 -> 0.095238095 | AG28: =+X28/R28 -> 0 | AH28: 0 | AI28: =AH28/E28 -> 0 | AJ28: 220 | AK28: =+AJ28/E28 -> 0.003473538 | AL28: 0 | AM28: 0 | AN28: =AM28/E28 -> 0 | AO28: 3 | AP28: 4080 | AQ28: =AP28/E28 -> 0.06441834 | AR28: 2 | AS28: 4687 | AT28: =AS28/E28 -> 0.074002147 | AU28: 7 | AV28: 9843 | AW28: =AV28/E28 -> 0.15540925 | AX28: 12 | AY28: =AX28/R28 -> 0.57142857 | AZ28: 100 | BA28: 50 | BB28: 0 | BC28: 0 | BD28: =+BC28/E28 -> 0 | BE28: 0 | BF28: =BE28/R28 -> 0 | BG28: 0 | BH28: =BG28/R28 -> 0
B29: Tues | C29: =C28+1 -> 46280 | D29: 76859.359 | E29: 60616 | G29: =IF(ISERROR(F29/E29),"",F29/E29) -> 0 | H29: 55073 | I29: =IF(ISERROR(E29/D29),"",E29/D29) -> 0.78866127 | J29: =IF(ISERROR(E29/H29),"",(E29/H29))-1 -> 0.10064823 | K29: =IF(ISERROR(K28+D29),0,K28+D29) -> 1434708 | L29: =IF(ISERROR(L28+E29),0,L28+E29) -> 1325985 | M29: =IF(ISERROR(M28+H29),0,M28+H29) -> 1434296 | N29: =IF(ISERROR(L29/K29),"",L29/K29) -> 0.9242194 | O29: =IF(ISERROR(L29/M29),"",L29/M29)-100% -> -0.075515096 | Q29: 47 | R29: 20 | S29: 159 | T29: 5 | U29: 0 | V29: 3 | W29: 0 | X29: 0 | Y29: =IF(ISERROR(E29/Q29),"",E29/Q29) -> 1289.7021 | Z29: =IF(ISERROR(E29/R29),"",E29/R29) -> 3030.8 | AA29: =IF(ISERROR(Q29/R29),"",Q29/R29) -> 2.35 | AB29: =IF(ISERROR(R29/S29),"",R29/S29) -> 0.12578616 | AC29: =IF(ISERROR(T29/R29),"",T29/R29) -> 0.25 | AD29: =IF(ISERROR(U29/R29),"",U29/R29) -> 0 | AE29: =IF(ISERROR(W29/R29),"",W29/R29) -> 0 | AF29: =+V29/R29 -> 0.15 | AG29: =+X29/R29 -> 0 | AH29: 0 | AI29: =AH29/E29 -> 0 | AJ29: 552 | AK29: =+AJ29/E29 -> 0.0091065065 | AL29: 0 | AM29: 0 | AN29: =AM29/E29 -> 0 | AO29: 2 | AP29: 6898 | AQ29: =AP29/E29 -> 0.11379834 | AR29: 1 | AS29: 3059 | AT29: =AS29/E29 -> 0.050465224 | AU29: 4 | AV29: 10437 | AW29: =AV29/E29 -> 0.17218226 | AX29: 15 | AY29: =AX29/R29 -> 0.75 | AZ29: 100 | BA29: 50 | BB29: 0 | BC29: 0 | BD29: =+BC29/E29 -> 0 | BE29: 0 | BF29: =BE29/R29 -> 0 | BG29: 0 | BH29: =BG29/R29 -> 0
B30: Wed | C30: =C29+1 -> 46281 | D30: 76859.359 | E30: 45330 | G30: =IF(ISERROR(F30/E30),"",F30/E30) -> 0 | H30: 55540 | I30: =IF(ISERROR(E30/D30),"",E30/D30) -> 0.58977853 | J30: =IF(ISERROR(E30/H30),"",(E30/H30))-1 -> -0.18383147 | K30: =IF(ISERROR(K29+D30),0,K29+D30) -> 1511567.4 | L30: =IF(ISERROR(L29+E30),0,L29+E30) -> 1371315 | M30: =IF(ISERROR(M29+H30),0,M29+H30) -> 1489836 | N30: =IF(ISERROR(L30/K30),"",L30/K30) -> 0.90721393 | O30: =IF(ISERROR(L30/M30),"",L30/M30)-100% -> -0.079553051 | Q30: 47 | R30: 20 | S30: 151 | T30: 2 | U30: 0 | V30: 5 | W30: 0 | X30: 3 | Y30: =IF(ISERROR(E30/Q30),"",E30/Q30) -> 964.46809 | Z30: =IF(ISERROR(E30/R30),"",E30/R30) -> 2266.5 | AA30: =IF(ISERROR(Q30/R30),"",Q30/R30) -> 2.35 | AB30: =IF(ISERROR(R30/S30),"",R30/S30) -> 0.13245033 | AC30: =IF(ISERROR(T30/R30),"",T30/R30) -> 0.1 | AD30: =IF(ISERROR(U30/R30),"",U30/R30) -> 0 | AE30: =IF(ISERROR(W30/R30),"",W30/R30) -> 0 | AF30: =+V30/R30 -> 0.25 | AG30: =+X30/R30 -> 0.15 | AH30: 0 | AI30: =AH30/E30 -> 0 | AJ30: 220 | AK30: =+AJ30/E30 -> 0.004853298 | AL30: 0 | AM30: 0 | AN30: =AM30/E30 -> 0 | AO30: 1 | AP30: 2804 | AQ30: =AP30/E30 -> 0.06185749 | AR30: 0 | AS30: 0 | AT30: =AS30/E30 -> 0 | AU30: 1 | AV30: 2804 | AW30: =AV30/E30 -> 0.06185749 | AX30: 10 | AY30: =AX30/R30 -> 0.5 | AZ30: 100 | BA30: 50 | BB30: 0 | BC30: 0 | BD30: =+BC30/E30 -> 0 | BE30: 0 | BF30: =BE30/R30 -> 0 | BG30: 0 | BH30: =BG30/R30 -> 0
B31: Thurs | C31: =C30+1 -> 46282 | D31: 89669.252 | E31: 43767 | G31: =IF(ISERROR(F31/E31),"",F31/E31) -> 0 | H31: 46315 | I31: =IF(ISERROR(E31/D31),"",E31/D31) -> 0.48809373 | J31: =IF(ISERROR(E31/H31),"",(E31/H31))-1 -> -0.055014574 | K31: =IF(ISERROR(K30+D31),0,K30+D31) -> 1601236.7 | L31: =IF(ISERROR(L30+E31),0,L30+E31) -> 1415082 | M31: =IF(ISERROR(M30+H31),0,M30+H31) -> 1536151 | N31: =IF(ISERROR(L31/K31),"",L31/K31) -> 0.8837432 | O31: =IF(ISERROR(L31/M31),"",L31/M31)-100% -> -0.078813216 | Q31: 52 | R31: 25 | S31: 169 | T31: 7 | U31: 0 | V31: 2 | W31: 1 | X31: 3 | Y31: =IF(ISERROR(E31/Q31),"",E31/Q31) -> 841.67308 | Z31: =IF(ISERROR(E31/R31),"",E31/R31) -> 1750.68 | AA31: =IF(ISERROR(Q31/R31),"",Q31/R31) -> 2.08 | AB31: =IF(ISERROR(R31/S31),"",R31/S31) -> 0.14792899 | AC31: =IF(ISERROR(T31/R31),"",T31/R31) -> 0.28 | AD31: =IF(ISERROR(U31/R31),"",U31/R31) -> 0 | AE31: =IF(ISERROR(W31/R31),"",W31/R31) -> 0.04 | AF31: =+V31/R31 -> 0.08 | AG31: =+X31/R31 -> 0.12 | AH31: 0 | AI31: =AH31/E31 -> 0 | AJ31: 848 | AK31: =+AJ31/E31 -> 0.019375328 | AL31: 0 | AM31: 0 | AN31: =AM31/E31 -> 0 | AO31: 1 | AP31: 1359 | AQ31: =AP31/E31 -> 0.031050792 | AR31: 1 | AS31: 1359 | AT31: =AS31/E31 -> 0.031050792 | AU31: 6 | AV31: 6645 | AW31: =AV31/E31 -> 0.15182672 | AX31: 15 | AY31: =AX31/R31 -> 0.6 | AZ31: 100 | BA31: 50 | BB31: 0 | BC31: 0 | BD31: =+BC31/E31 -> 0 | BE31: 0 | BF31: =BE31/R31 -> 0 | BG31: 0 | BH31: =BG31/R31 -> 0
B32: Fri | C32: =C31+1 -> 46283 | D32: 96074.199 | E32: 103358 | G32: =IF(ISERROR(F32/E32),"",F32/E32) -> 0 | H32: 76551 | I32: =IF(ISERROR(E32/D32),"",E32/D32) -> 1.0758143 | J32: =IF(ISERROR(E32/H32),"",(E32/H32))-1 -> 0.35018484 | K32: =IF(ISERROR(K31+D32),0,K31+D32) -> 1697310.9 | L32: =IF(ISERROR(L31+E32),0,L31+E32) -> 1518440 | M32: =IF(ISERROR(M31+H32),0,M31+H32) -> 1612702 | N32: =IF(ISERROR(L32/K32),"",L32/K32) -> 0.89461515 | O32: =IF(ISERROR(L32/M32),"",L32/M32)-100% -> -0.058449732 | Q32: 94 | R32: 42 | S32: 247 | T32: 1 | U32: 0 | V32: 5 | W32: 0 | X32: 1 | Y32: =IF(ISERROR(E32/Q32),"",E32/Q32) -> 1099.5532 | Z32: =IF(ISERROR(E32/R32),"",E32/R32) -> 2460.9048 | AA32: =IF(ISERROR(Q32/R32),"",Q32/R32) -> 2.2380952 | AB32: =IF(ISERROR(R32/S32),"",R32/S32) -> 0.17004049 | AC32: =IF(ISERROR(T32/R32),"",T32/R32) -> 0.023809524 | AD32: =IF(ISERROR(U32/R32),"",U32/R32) -> 0 | AE32: =IF(ISERROR(W32/R32),"",W32/R32) -> 0 | AF32: =+V32/R32 -> 0.11904762 | AG32: =+X32/R32 -> 0.023809524 | AH32: 0 | AI32: =AH32/E32 -> 0 | AJ32: 110 | AK32: =+AJ32/E32 -> 0.0010642621 | AL32: 1 | AM32: 1199 | AN32: =AM32/E32 -> 0.011600457 | AO32: 3 | AP32: 8797 | AQ32: =AP32/E32 -> 0.085111941 | AR32: 0 | AS32: 0 | AT32: =AS32/E32 -> 0 | AU32: 7 | AV32: 12343 | AW32: =AV32/E32 -> 0.11941988 | AX32: 27 | AY32: =AX32/R32 -> 0.64285714 | AZ32: 100 | BA32: 60 | BB32: 2 | BC32: 2196 | BD32: =+BC32/E32 -> 0.021246541 | BE32: 0 | BF32: =BE32/R32 -> 0 | BG32: 0 | BH32: =BG32/R32 -> 0
B33: Sat | C33: =C32+1 -> 46284 | D33: 169731.09 | E33: 192912 | G33: =IF(ISERROR(F33/E33),"",F33/E33) -> 0 | H33: 89503 | I33: =IF(ISERROR(E33/D33),"",E33/D33) -> 1.1365744 | J33: =IF(ISERROR(E33/H33),"",(E33/H33))-1 -> 1.1553691 | K33: =IF(ISERROR(K32+D33),0,K32+D33) -> 1867041.9 | L33: =IF(ISERROR(L32+E33),0,L32+E33) -> 1711352 | M33: =IF(ISERROR(M32+H33),0,M32+H33) -> 1702205 | N33: =IF(ISERROR(L33/K33),"",L33/K33) -> 0.91661144 | O33: =IF(ISERROR(L33/M33),"",L33/M33)-100% -> 0.0053736183 | Q33: 180 | R33: 81 | S33: 500 | T33: 6 | U33: 1 | V33: 15 | W33: 0 | X33: 0 | Y33: =IF(ISERROR(E33/Q33),"",E33/Q33) -> 1071.7333 | Z33: =IF(ISERROR(E33/R33),"",E33/R33) -> 2381.6296 | AA33: =IF(ISERROR(Q33/R33),"",Q33/R33) -> 2.2222222 | AB33: =IF(ISERROR(R33/S33),"",R33/S33) -> 0.162 | AC33: =IF(ISERROR(T33/R33),"",T33/R33) -> 0.074074074 | AD33: =IF(ISERROR(U33/R33),"",U33/R33) -> 0.012345679 | AE33: =IF(ISERROR(W33/R33),"",W33/R33) -> 0 | AF33: =+V33/R33 -> 0.18518519 | AG33: =+X33/R33 -> 0 | AH33: 1099 | AI33: =AH33/E33 -> 0.0056968981 | AJ33: 680 | AK33: =+AJ33/E33 -> 0.0035249233 | AL33: 4 | AM33: 9721 | AN33: =AM33/E33 -> 0.050390852 | AO33: 5 | AP33: 5495 | AQ33: =AP33/E33 -> 0.02848449 | AR33: 3 | AS33: 11082 | AT33: =AS33/E33 -> 0.057445882 | AU33: 14 | AV33: 18722 | AW33: =AV33/E33 -> 0.097049432 | AX33: 45 | AY33: =AX33/R33 -> 0.55555556 | AZ33: 100 | BA33: 50 | BB33: 0 | BC33: 0 | BD33: =+BC33/E33 -> 0 | BE33: 0 | BF33: =BE33/R33 -> 0 | BG33: 0 | BH33: =BG33/R33 -> 0
B34: Sun | C34: =C33+1 -> 46285 | D34: 169731.09 | E34: 239136 | G34: =IF(ISERROR(F34/E34),"",F34/E34) -> 0 | H34: 122958 | I34: =IF(ISERROR(E34/D34),"",E34/D34) -> 1.408911 | J34: =IF(ISERROR(E34/H34),"",(E34/H34))-1 -> 0.94485922 | K34: =IF(ISERROR(K33+D34),0,K33+D34) -> 2036773 | L34: =IF(ISERROR(L33+E34),0,L33+E34) -> 1950488 | M34: =IF(ISERROR(M33+H34),0,M33+H34) -> 1825163 | N34: =IF(ISERROR(L34/K34),"",L34/K34) -> 0.95763641 | O34: =IF(ISERROR(L34/M34),"",L34/M34)-100% -> 0.0686651 | Q34: 221 | R34: 84 | S34: 538 | T34: 11 | U34: 1 | V34: 17 | W34: 0 | X34: 6 | Y34: =IF(ISERROR(E34/Q34),"",E34/Q34) -> 1082.0633 | Z34: =IF(ISERROR(E34/R34),"",E34/R34) -> 2846.8571 | AA34: =IF(ISERROR(Q34/R34),"",Q34/R34) -> 2.6309524 | AB34: =IF(ISERROR(R34/S34),"",R34/S34) -> 0.15613383 | AC34: =IF(ISERROR(T34/R34),"",T34/R34) -> 0.13095238 | AD34: =IF(ISERROR(U34/R34),"",U34/R34) -> 0.011904762 | AE34: =IF(ISERROR(W34/R34),"",W34/R34) -> 0 | AF34: =+V34/R34 -> 0.20238095 | AG34: =+X34/R34 -> 0.071428571 | AH34: 1440 | AI34: =AH34/E34 -> 0.006021678 | AJ34: 1266 | AK34: =+AJ34/E34 -> 0.0052940586 | AL34: 5 | AM34: 5195 | AN34: =AM34/E34 -> 0.02172404 | AO34: 5 | AP34: 8357 | AQ34: =AP34/E34 -> 0.034946641 | AR34: 6 | AS34: 13464 | AT34: =AS34/E34 -> 0.05630269 | AU34: 20 | AV34: 26548 | AW34: =AV34/E34 -> 0.11101633 | AX34: 48 | AY34: =AX34/R34 -> 0.57142857 | AZ34: 100 | BA34: 50 | BB34: 0 | BC34: 0 | BD34: =+BC34/E34 -> 0 | BE34: 0 | BF34: =BE34/R34 -> 0 | BG34: 0 | BH34: =BG34/R34 -> 0
B35: Total | D35: =SUM(D28:D34) -> 752581.23 | E35: =SUM(E28:E34) -> 748455 | F35: =SUM(F28:F34) -> 0 | G35: =IF(ISERROR(F35/E35),"",F35/E35) -> 0 | H35: =SUM(H28:H34) -> 599489 | I35: =IF(ISERROR(E35/D35),"",E35/D35) -> 0.99451723 | J35: =IF(ISERROR(E35/H35),"",(E35/H35))-1 -> 0.2484883 | Q35: =SUM(Q28:Q34) -> 704 | R35: =SUM(R28:R34) -> 293 | S35: =SUM(S28:S34) -> 1913 | T35: =SUM(T28:T34) -> 34 | U35: =SUM(U28:U34) -> 2 | V35: =SUM(V28:V34) -> 49 | W35: =SUM(W28:W34) -> 1 | X35: =SUM(X28:X34) -> 13 | Y35: =IF(ISERROR(E35/Q35),"",E35/Q35) -> 1063.1463 | Z35: =IF(ISERROR(E35/R35),"",E35/R35) -> 2554.4539 | AA35: =IF(ISERROR(Q35/R35),"",Q35/R35) -> 2.4027304 | AB35: =IF(ISERROR(R35/S35),"",R35/S35) -> 0.15316257 | AC35: =IF(ISERROR(T35/R35),"",T35/R35) -> 0.11604096 | AD35: =IF(ISERROR(U35/R35),"",U35/R35) -> 0.0068259386 | AE35: =IF(ISERROR(W35/R35),"",W35/R35) -> 0.0034129693 | AF35: =+V35/R35 -> 0.16723549 | AG35: =+X35/R35 -> 0.044368601 | AH35: =SUM(AH28:AH34) -> 2539 | AI35: =AH35/E35 -> 0.0033923215 | AJ35: =SUM(AJ28:AJ34) -> 3896 | AK35: =SUM(AK28:AK34) -> 0.046691915 | AL35: =SUM(AL28:AL34) -> 10 | AM35: =SUM(AM28:AM34) -> 16115 | AN35: =AM35/E35 -> 0.021531021 | AO35: =SUM(AO28:AO34) -> 20 | AP35: =SUM(AP28:AP34) -> 37790 | AQ35: =AP35/E35 -> 0.050490677 | AR35: =SUM(AR28:AR34) -> 13 | AS35: =SUM(AS28:AS34) -> 33651 | AT35: =AS35/E35 -> 0.044960619 | AU35: =+SUM(AU28:AU34) -> 59 | AV35: =+SUM(AV28:AV34) -> 87342 | AW35: =AV35/E35 -> 0.11669639 | AX35: =SUM(AX28:AX34) -> 172 | AY35: =SUM(AY28:AY34) -> 4.1912698 | AZ35: =SUM(AZ28:AZ34) -> 700 | BA35: =SUM(BA28:BA34) -> 360 | BB35: =SUM(BB28:BB34) -> 2 | BC35: =SUM(BC28:BC34) -> 2196 | BD35: =+BC35/E35 -> 0.0029340441 | BE35: =SUM(BE28:BE34) -> 0 | BF35: =BE35/R35 -> 0 | BG35: =SUM(BG28:BG34) -> 0 | BH35: =BG35/R35 -> 0
A36: WEEK 4 | B36: Mon | C36: =C34+1 -> 46286 | D36: 73656.886 | E36: 61212 | G36: =IF(ISERROR(F36/E36),"",F36/E36) -> 0 | H36: 151580 | I36: =IF(ISERROR(E36/D36),"",E36/D36) -> 0.83104246 | J36: =IF(ISERROR(E36/H36),"",(E36/H36))-1 -> -0.59617364 | K36: =IF($C36="","",IF(ISERROR(K34+D36),0,K34+D36)) -> 2110429.9 | L36: =IF(ISERROR(L34+E36),0,L34+E36) -> 2011700 | M36: =IF(ISERROR(M34+H36),0,M34+H36) -> 1976743 | N36: =IF(ISERROR(L36/K36),"",L36/K36) -> 0.95321811 | O36: =IF(ISERROR(L36/M36),"",L36/M36)-100% -> 0.01768414 | Q36: 54 | R36: 30 | S36: 216 | T36: 4 | U36: 0 | V36: 1 | W36: 0 | X36: 0 | Y36: =IF(ISERROR(E36/Q36),"",E36/Q36) -> 1133.5556 | Z36: =IF(ISERROR(E36/R36),"",E36/R36) -> 2040.4 | AA36: =IF(ISERROR(Q36/R36),"",Q36/R36) -> 1.8 | AB36: =IF(ISERROR(R36/S36),"",R36/S36) -> 0.13888889 | AC36: =IF(ISERROR(T36/R36),"",T36/R36) -> 0.13333333 | AD36: =IF(ISERROR(U36/R36),"",U36/R36) -> 0 | AE36: =IF(ISERROR(W36/R36),"",W36/R36) -> 0 | AF36: =+V36/R36 -> 0.033333333 | AG36: =+X36/R36 -> 0 | AH36: 0 | AI36: =AH36/E36 -> 0 | AJ36: 440 | AK36: =+AJ36/E36 -> 0.007188133 | AL36: 1 | AM36: 1099 | AN36: =AM36/E36 -> 0.017953996 | AO36: 1 | AP36: 999 | AQ36: =AP36/E36 -> 0.016320329 | AR36: 0 | AS36: 0 | AT36: =AS36/E36 -> 0 | AU36: 3 | AV36: 1947 | AW36: =AV36/E36 -> 0.031807489 | AX36: 14 | AY36: =AX36/R36 -> 0.46666667 | AZ36: 100 | BA36: 50 | BB36: 0 | BC36: 0 | BD36: =+BC36/E36 -> 0 | BE36: 0 | BF36: =BE36/R36 -> 0 | BG36: 0 | BH36: =BG36/R36 -> 0
B37: Tue | C37: =C36+1 -> 46287 | D37: 76859.359 | E37: 110446 | G37: =IF(ISERROR(F37/E37),"",F37/E37) -> 0 | H37: 64149 | I37: =IF(ISERROR(E37/D37),"",E37/D37) -> 1.4369883 | J37: =IF(ISERROR(E37/H37),"",(E37/H37))-1 -> 0.72171039 | K37: =IF(C37="","",IF(ISERROR(K36+D37),0,K36+D37)) -> 2187289.3 | L37: =IF(ISERROR(L36+E37),0,L36+E37) -> 2122146 | M37: =IF(ISERROR(M36+H37),0,M36+H37) -> 2040892 | N37: =IF(ISERROR(L37/K37),"",L37/K37) -> 0.97021735 | O37: =IF(ISERROR(L37/M37),"",L37/M37)-100% -> 0.039812984 | Q37: 102 | R37: 42 | S37: 281 | T37: 16 | U37: 1 | V37: 2 | W37: 0 | X37: 0 | Y37: =IF(ISERROR(E37/Q37),"",E37/Q37) -> 1082.8039 | Z37: =IF(ISERROR(E37/R37),"",E37/R37) -> 2629.6667 | AA37: =IF(ISERROR(Q37/R37),"",Q37/R37) -> 2.4285714 | AB37: =IF(ISERROR(R37/S37),"",R37/S37) -> 0.14946619 | AC37: =IF(ISERROR(T37/R37),"",T37/R37) -> 0.38095238 | AD37: =IF(ISERROR(U37/R37),"",U37/R37) -> 0.023809524 | AE37: =IF(ISERROR(W37/R37),"",W37/R37) -> 0 | AF37: =+V37/R37 -> 0.047619048 | AG37: =+X37/R37 -> 0 | AH37: 1499 | AI37: =AH37/E37 -> 0.013572243 | AJ37: 1880 | AK37: =+AJ37/E37 -> 0.017021893 | AL37: 2 | AM37: 2398 | AN37: =AM37/E37 -> 0.021711968 | AO37: 2 | AP37: 5208 | AQ37: =AP37/E37 -> 0.047154265 | AR37: 0 | AS37: 0 | AT37: =AS37/E37 -> 0 | AU37: 7 | AV37: 11789 | AW37: =AV37/E37 -> 0.10673995 | AX37: 26 | AY37: =AX37/R37 -> 0.61904762 | AZ37: 100 | BA37: 0 | BB37: 0 | BC37: 0 | BD37: =+BC37/E37 -> 0 | BE37: 0 | BF37: =BE37/R37 -> 0 | BG37: 0 | BH37: =BG37/R37 -> 0
B38: Wed | C38: =C37+1 -> 46288 | D38: 76859.359 | E38: 74250 | G38: =IF(ISERROR(F38/E38),"",F38/E38) -> 0 | H38: 155133 | I38: =IF(ISERROR(E38/D38),"",E38/D38) -> 0.96605021 | J38: =IF(ISERROR(E38/H38),"",(E38/H38))-1 -> -0.52137843 | K38: =IF(C38="","",IF(ISERROR(K37+D38),0,K37+D38)) -> 2264148.6 | L38: =IF($C38="","",IF(ISERROR(L37+E38),0,L37+E38)) -> 2196396 | M38: =IF($C38="","",IF(ISERROR(M37+H38),0,M37+H38)) -> 2196025 | N38: =IF(ISERROR(L38/K38),"",L38/K38) -> 0.97007589 | O38: =IF(ISERROR(L38/M38),"",L38/M38)-100% -> 0.00016894161 | Q38: 69 | R38: 39 | S38: 214 | T38: 1 | U38: 0 | V38: 5 | W38: 0 | X38: 2 | Y38: =IF(ISERROR(E38/Q38),"",E38/Q38) -> 1076.087 | Z38: =IF(ISERROR(E38/R38),"",E38/R38) -> 1903.8462 | AA38: =IF(ISERROR(Q38/R38),"",Q38/R38) -> 1.7692308 | AB38: =IF(ISERROR(R38/S38),"",R38/S38) -> 0.18224299 | AC38: =IF(ISERROR(T38/R38),"",T38/R38) -> 0.025641026 | AD38: =IF(ISERROR(U38/R38),"",U38/R38) -> 0 | AE38: =IF(ISERROR(W38/R38),"",W38/R38) -> 0 | AF38: =+V38/R38 -> 0.12820513 | AG38: =+X38/R38 -> 0.051282051 | AH38: 0 | AI38: =AH38/E38 -> 0 | AJ38: 120 | AK38: =+AJ38/E38 -> 0.0016161616 | AL38: 0 | AM38: 0 | AN38: =AM38/E38 -> 0 | AO38: 4 | AP38: 11468 | AQ38: =AP38/E38 -> 0.15445118 | AR38: 1 | AS38: 5099 | AT38: =AS38/E38 -> 0.068673401 | AU38: 9 | AV38: 15178 | AW38: =AV38/E38 -> 0.20441751 | AX38: 20 | AY38: =AX38/R38 -> 0.51282051 | AZ38: 100 | BA38: 0 | BB38: 0 | BC38: 0 | BD38: =+BC38/E38 -> 0 | BE38: 0 | BF38: =BE38/R38 -> 0 | BG38: 0 | BH38: =BG38/R38 -> 0
B39: Thu | C39: =C38+1 -> 46289 | D39: 89669.252 | E39: 111052 | G39: =IF(ISERROR(F39/E39),"",F39/E39) -> 0 | H39: 68405 | I39: =IF(ISERROR(E39/D39),"",E39/D39) -> 1.2384624 | J39: =IF(ISERROR(E39/H39),"",(E39/H39))-1 -> 0.62344858 | K39: =IF(C39="","",IF(ISERROR(K38+D39),0,K38+D39)) -> 2353817.9 | L39: =IF($C39="","",IF(ISERROR(L38+E39),0,L38+E39)) -> 2307448 | M39: =IF($C39="","",IF(ISERROR(M38+H39),0,M38+H39)) -> 2264430 | N39: =IF(ISERROR(L39/K39),"",L39/K39) -> 0.98030014 | O39: =IF(ISERROR(L39/M39),"",L39/M39)-100% -> 0.018997275 | Q39: 127 | R39: 60 | S39: 287 | T39: 7 | U39: 0 | V39: 5 | W39: 0 | X39: 5 | Y39: =IF(ISERROR(E39/Q39),"",E39/Q39) -> 874.4252 | Z39: =IF(ISERROR(E39/R39),"",E39/R39) -> 1850.8667 | AA39: =IF(ISERROR(Q39/R39),"",Q39/R39) -> 2.1166667 | AB39: =IF(ISERROR(R39/S39),"",R39/S39) -> 0.20905923 | AC39: =IF(ISERROR(T39/R39),"",T39/R39) -> 0.11666667 | AD39: =IF(ISERROR(U39/R39),"",U39/R39) -> 0 | AE39: =IF(ISERROR(W39/R39),"",W39/R39) -> 0 | AF39: =+V39/R39 -> 0.083333333 | AG39: =+X39/R39 -> 0.083333333 | AH39: 0 | AI39: =AH39/E39 -> 0 | AJ39: 698 | AK39: =+AJ39/E39 -> 0.0062853438 | AL39: 3 | AM39: 4623 | AN39: =AM39/E39 -> 0.041629147 | AO39: 2 | AP39: 4139 | AQ39: =AP39/E39 -> 0.037270828 | AR39: 5 | AS39: 10936 | AT39: =AS39/E39 -> 0.098476389 | AU39: 8 | AV39: 13930 | AW39: =AV39/E39 -> 0.12543673 | AX39: 30 | AY39: =AX39/R39 -> 0.5 | AZ39: 100 | BA39: 50 | BB39: 0 | BC39: 0 | BD39: =+BC39/E39 -> 0 | BE39: 2 | BF39: =BE39/R39 -> 0.033333333 | BG39: 0 | BH39: =BG39/R39 -> 0
B40: Fri | C40: =C39+1 -> 46290 | D40: 96074.199 | E40: 96738 | G40: =IF(ISERROR(F40/E40),"",F40/E40) -> 0 | H40: 89900 | I40: =IF(ISERROR(E40/D40),"",E40/D40) -> 1.0069093 | J40: =IF(ISERROR(E40/H40),"",(E40/H40))-1 -> 0.076062291 | K40: =IF(C40="","",IF(ISERROR(K39+D40),0,K39+D40)) -> 2449892.1 | L40: =IF($C40="","",IF(ISERROR(L39+E40),0,L39+E40)) -> 2404186 | M40: =IF($C40="","",IF(ISERROR(M39+H40),0,M39+H40)) -> 2354330 | N40: =IF(ISERROR(L40/K40),"",L40/K40) -> 0.98134364 | O40: =IF(ISERROR(L40/M40),"",L40/M40)-100% -> 0.021176301 | Q40: 100 | R40: 48 | S40: 265 | T40: 11 | U40: 0 | V40: 5 | W40: 0 | X40: 0 | Y40: =IF(ISERROR(E40/Q40),"",E40/Q40) -> 967.38 | Z40: =IF(ISERROR(E40/R40),"",E40/R40) -> 2015.375 | AA40: =IF(ISERROR(Q40/R40),"",Q40/R40) -> 2.0833333 | AB40: =IF(ISERROR(R40/S40),"",R40/S40) -> 0.18113208 | AC40: =IF(ISERROR(T40/R40),"",T40/R40) -> 0.22916667 | AD40: =IF(ISERROR(U40/R40),"",U40/R40) -> 0 | AE40: =IF(ISERROR(W40/R40),"",W40/R40) -> 0 | AF40: =+V40/R40 -> 0.10416667 | AG40: =+X40/R40 -> 0 | AH40: 0 | AI40: =AH40/E40 -> 0 | AJ40: 1142 | AK40: =+AJ40/E40 -> 0.011805082 | AL40: 2 | AM40: 1860 | AN40: =AM40/E40 -> 0.019227191 | AO40: 4 | AP40: 5309 | AQ40: =AP40/E40 -> 0.054880192 | AR40: 1 | AS40: 1799 | AT40: =AS40/E40 -> 0.018596622 | AU40: 7 | AV40: 8581 | AW40: =AV40/E40 -> 0.088703508 | AX40: 31 | AY40: =AX40/R40 -> 0.64583333 | AZ40: 100 | BA40: 50 | BB40: 0 | BC40: 0 | BD40: =+BC40/E40 -> 0 | BE40: 0 | BF40: =BE40/R40 -> 0 | BG40: 0 | BH40: =BG40/R40 -> 0
...

Sheet MSG 
A1: Store | B1: VEGAS | I1: Date | J1: Retail | K1: Retail Accum Tgt | L1: Net Play | M1: Net play Accum Tgt
A2: Date- | B2: =TODAY()-0 -> 46291 | C2: =B2+1 -> 46292 | I2: 46266 | J2: 73656.886 | K2: =J2 -> 73656.886 | L2: 4597.4185 | M2: =L2 -> 4597.4185
A3: MONTH TRGT - | B3: =DSR!D54 -> 3029539.7 | I3: =I2+1 -> 46267 | J3: 76859.359 | K3: =K2+J3 -> 150516.25 | L3: 4760.6694 | M3: =M2+L3 -> 9358.0879
A4: TARGET- | B4: =VLOOKUP(B2,DSR!C8:D52,2,0) -> 176136.03 | I4: =I3+1 -> 46268 | J4: 89669.252 | K4: =K3+J4 -> 240185.5 | L4: 5336.5905 | M4: =M3+L4 -> 14694.678
A5: SALE- | B5: =IFERROR(VLOOKUP(B2,DSR!C9:E54,3,0),0) -> 0 | I5: =I4+1 -> 46269 | J5: 128098.93 | K5: =K4+J5 -> 368284.43 | L5: 8061.591 | M5: =M4+L5 -> 22756.269
A6: FF- | B6: =VLOOKUP(B2,DSR!C8:S52,17,0) -> 0 | I6: =I5+1 -> 46270 | J6: 166528.61 | K6: =K5+J6 -> 534813.04 | L6: 10551.494 | M6: =M5+L6 -> 33307.763
A7: BILL- | B7: =VLOOKUP(B2,DSR!C8:R52,16,0) -> 0 | I7: =I6+1 -> 46271 | J7: 166528.61 | K7: =K6+J7 -> 701341.65 | L7: 11801.484 | M7: =M6+L7 -> 45109.247
A8: UNIT- | B8: =IFERROR(VLOOKUP(B2,DSR!C9:Q54,15,0),0) -> 0 | I8: =I7+1 -> 46272 | J8: 73656.886 | K8: =K7+J8 -> 774998.54 | L8: 4504.142 | M8: =M7+L8 -> 49613.389
A9: UPT- | B9: =VLOOKUP(B2,DSR!C9:AA52,25,0) | I9: =I8+1 -> 46273 | J9: 76859.359 | K9: =K8+J9 -> 851857.9 | L9: 4713.2701 | M9: =M8+L9 -> 54326.659
A10: ATV- | B10: =VLOOKUP(B2,DSR!C9:Z52,24,0) | I10: =I9+1 -> 46274 | J10: 76859.359 | K10: =K9+J10 -> 928717.26 | L10: 4730.4354 | M10: =M9+L10 -> 59057.095
A11: AUV- | B11: =VLOOKUP(B2,DSR!C9:Y52,23,0) | I11: =I10+1 -> 46275 | J11: 86466.779 | K11: =K10+J11 -> 1015184 | L11: 5265.6039 | M11: =M10+L11 -> 64322.699
A12: CONV%- | B12: =VLOOKUP('MSG '!B2,DSR!C9:AB52,26,0) | I12: =I11+1 -> 46276 | J12: 96074.199 | K12: =K11+J12 -> 1111258.2 | L12: 6387.6675 | M12: =M11+L12 -> 70710.366
I13: =I12+1 -> 46277 | J13: 169731.09 | K13: =K12+J13 -> 1280989.3 | L13: 11555.449 | M13: =M12+L13 -> 82265.815
A14: MTD TGT- | B14: =VLOOKUP(B2,DSR!C9:K52,9,0) -> 2626028.1 | I14: =I13+1 -> 46278 | J14: 169731.09 | K14: =K13+J14 -> 1450720.4 | L14: 11783.432 | M14: =M13+L14 -> 94049.247
A15: MTD SALE- | B15: =DSR!E54 -> 2404186 | I15: =I14+1 -> 46279 | J15: 73656.886 | K15: =K14+J15 -> 1524377.3 | L15: 5196.8316 | M15: =M14+L15 -> 99246.079
A16: MTD SALE%- | B16: =B15/B14 -> 0.91552181 | I16: =I15+1 -> 46280 | J16: 76859.359 | K16: =K15+J16 -> 1601236.7 | L16: 4642.688 | M16: =M15+L16 -> 103888.77
A17: MTD FF- | B17: =DSR!S54 -> 6418 | I17: =I16+1 -> 46281 | J17: 76859.359 | K17: =K16+J17 -> 1678096 | L17: 4779.251 | M17: =M16+L17 -> 108668.02
A18: MTD BILL- | B18: =DSR!R54 -> 1021 | I18: =I17+1 -> 46282 | J18: 89669.252 | K18: =K17+J18 -> 1767765.3 | L18: 5428.7639 | M18: =M17+L18 -> 114096.78
A19: MTD QTY- | B19: =DSR!Q54 -> 2292 | I19: =I18+1 -> 46283 | J19: 96074.199 | K19: =K18+J19 -> 1863839.5 | L19: 6239.3847 | M19: =M18+L19 -> 120336.17
A20: MTD UPT- | B20: =DSR!AA54 -> 2.244858 | I20: =I19+1 -> 46284 | J20: 169731.09 | K20: =K19+J20 -> 2033570.5 | L20: 12016.311 | M20: =M19+L20 -> 132352.48
A21: MTD ATV- | B21: =DSR!Z54 -> 2354.7365 | I21: =I20+1 -> 46285 | J21: 169731.09 | K21: =K20+J21 -> 2203301.6 | L21: 11786.877 | M21: =M20+L21 -> 144139.35
A22: MTD AUV- | B22: =DSR!Y54 -> 1048.9468 | I22: =I21+1 -> 46286 | J22: 73656.886 | K22: =K21+J22 -> 2276958.5 | L22: 4504.142 | M22: =M21+L22 -> 148643.5
A23: MTD CONV%- | B23: =DSR!AB54 -> 0.15908383 | I23: =I22+1 -> 46287 | J23: 76859.359 | K23: =K22+J23 -> 2353817.9 | L23: 4713.2701 | M23: =M22+L23 -> 153356.77
I24: =I23+1 -> 46288 | J24: 76859.359 | K24: =K23+J24 -> 2430677.2 | L24: 4779.251 | M24: =M23+L24 -> 158136.02
A25: ATVD SALE- | B25: =VLOOKUP(B2,DSR!C9:AH52,32,0) -> 0 | I25: =I24+1 -> 46289 | J25: 89669.252 | K25: =K24+J25 -> 2520346.5 | L25: 5428.7639 | M25: =M24+L25 -> 163564.78
A26: ATVD QTY- | B26: =VLOOKUP(B2,DSR!C9:U52,19,0) -> 0 | I26: =I25+1 -> 46290 | J26: 96074.199 | K26: =K25+J26 -> 2616420.7 | L26: 6239.3847 | M26: =M25+L26 -> 169804.17
A27: ATVD CONTRI%- | B27: =VLOOKUP(B2,DSR!C9:AI52,33,0) -> #DIV/0! | I27: =I26+1 -> 46291 | J27: 176136.03 | K27: =K26+J27 -> 2792556.7 | L27: 11996.078 | M27: =M26+L27 -> 181800.24
A28: MTD ATVD CONTRI%- | B28: =DSR!AI54 -> 0.0065564811 | I28: =I27+1 -> 46292 | J28: 176136.03 | K28: =K27+J28 -> 2968692.8 | L28: 11530.929 | M28: =M27+L28 -> 193331.17
I29: =I28+1 -> 46293 | J29: 73656.886 | K29: =K28+J29 -> 3042349.6 | L29: 4504.142 | M29: =M28+L29 -> 197835.31
A30: HOT SPOT SALE- | B30: =VLOOKUP(B2,DSR!C9:AS52,43,0) -> 0 | I30: =I29+1 -> 46294 | J30: 76859.359 | K30: =K29+J30 -> 3119209 | L30: 4713.2701 | M30: =M29+L30 -> 202548.58
A31: HOT SPOT %- | B31: =VLOOKUP(B2,DSR!C9:AT52,44,0) -> #DIV/0! | I31: =I30+1 -> 46295 | J31: 76859.359 | K31: =K30+J31 -> 3196068.4 | L31: 4802.5022 | M31: =M30+L31 -> 207351.09
A32: MTD HOTSPOT %- | B32: =DSR!AT54 -> 0.040668234 | I32: =I31+1 -> 46296 | K32: =K31+J32 -> 3196068.4 | M32: =M31+L32 -> 207351.09
J33: =SUM(J2:J32) -> 3196068.4 | L33: =SUM(L2:L32) -> 207351.09
A34: SELF DEMO SALE- | B34: =VLOOKUP(B2,DSR!C9:AP52,40,0) -> 0 | J34: =+J33-J7 -> 3029539.7
A35: SELF DEMO %- | B35: =VLOOKUP(B2,DSR!C9:AQ52,41,0) -> #DIV/0! | J35: =+J34-B15 -> 625353.74
A36: MTD SELF DEMO %- | B36: =DSR!AQ54 -> 0.036314578
A38: CORE- | B38: =VLOOKUP(B2,DSR!C9:AM52,37,0) -> 0
A39: CORE %- | B39: =VLOOKUP(B2,DSR!C9:AN52,38,0) -> #DIV/0!
A40: MTD CORE SALE- | B40: =DSR!AM54 -> 102517
A41: MTD CORE DEMO%- | B41: =DSR!AN54 -> 0.042641044
...

Sheet Format
D1: Qty | E1: FOOTFALL | F1: Bills
A2: Sale
A3: KPI | B3: Qty | C3: SALE VALUE
A4: BUBBLE ST | B4: =SUMIF($A$17:$A$23001,"BUBBLE ST",$E$17:$E$23001) -> 0 | C4: =SUMIF($A$17:$A$23001,"BUBBLE ST",$F$17:$F$23001) -> 0 | D4: =+C4/$D$3 -> #DIV/0! | H4: =C4/B4 -> #DIV/0!
